Workbook

Sheet 承台
C7: 编号 | D7: 规格 | E7: 单根长 | F7: 根数 | G7: 总长 | H7: 单位重 | I7: 总重 | J7: 全桥合计(共4个)
D8: mm | E8: cm | G8: m | H8: kg/m | I8: kg | J8: kg
C9: 1 | D9: 28 | E9: =(527+1334.2)/2+32.8*2 -> 996.2 | F9: =3*64 -> 192 | G9: =F9*E9/100 -> 1912.704 | H9: 4.83 | I9: =G9*H9 -> 9238.3603 | J9: =SUM(I9:I13)*4 -> 91471.892
C10: 1a | D10: 28 | E10: =724.2+32.8*2 -> 789.8 | F10: =3*49 -> 147 | G10: =F10*E10/100 -> 1161.006 | H10: 4.83 | I10: =G10*H10 -> 5607.659
C11: 1b | D11: 28 | E11: =(70+772.4)/2+32.8*2 -> 486.8 | F11: =3*62 -> 186 | G11: =F11*E11/100 -> 905.448 | H11: 4.83 | I11: =G11*H11 -> 4373.3138
C12: 1c | D12: 28 | E12: =(85.5+8.7)/2+337.6+448.4 -> 833.1 | F12: 60 | G12: =F12*E12/100 -> 499.86 | H12: 4.83 | I12: =G12*H12 -> 2414.3238
C13: 4 | D13: 28 | E13: =224.8+32.8*2 -> 290.4 | F13: 88 | G13: =F13*E13/100 -> 255.552 | H13: 4.83 | I13: =G13*H13 -> 1234.3162
C14: 2 | D14: 20 | E14: =224.8 -> 224.8 | F14: 276 | G14: =F14*E14/100 -> 620.448 | H14: 2.47 | I14: =G14*H14 -> 1532.5066 | J14: =I14*4 -> 6130.0262
C15: 3 | D15: 16 | E15: =(734.8+1300)/2+18.7*2 -> 1054.8 | F15: 16 | G15: =F15*E15/100 -> 168.768 | H15: 1.58 | I15: =G15*H15 -> 266.65344 | J15: =SUM(I15:I18)*4 -> 5624.1427
C16: 3a | D16: 16 | E16: =774.2+18.7*2 -> 811.6 | F16: 12 | G16: =F16*E16/100 -> 97.392 | H16: 1.58 | I16: =G16*H16 -> 153.87936
C17: 3b | D17: 16 | E17: =(148.5+735.4)/2+18.7*2 -> 479.35 | F17: 16 | G17: =F17*E17/100 -> 76.696 | H17: 1.58 | I17: =G17*H17 -> 121.17968
C18: 5 | D18: 16 | E18: =192+400+(53.3+448.4)*2+114.1 -> 1709.5 | F18: 32 | G18: =F18*E18/100 -> 547.04 | H18: 1.58 | I18: =G18*H18 -> 864.3232
C19: 合计（kg） | I19: =SUM(I9:I18) -> 25806.515 | J19: =I19*4 -> 103226.06
C20: 12冷轧带肋钢筋网（kg） | I20: =80.5048*17.75 -> 1428.9602 | J20: =I20*4 -> 5715.8408
C21: C35混凝土（m ） | I21: =80.5048*2.5 -> 201.262 | J21: =I21*4 -> 805.048
C22: C25封底混凝土（m ） | I22: =80.5048*0.75 -> 60.3786 | J22: =I22*4 -> 241.5144
C23: 28钢筋连接器 | I23: =41*3 -> 123 | J23: =I23*4 -> 492
C32: 编号 | D32: 规格 | E32: 单根长 | F32: 根数 | G32: 总长 | H32: 单位重 | I32: 总重 | J32: 合计（4）
D33: mm | E33: cm | G33: m | H33: kg/m | I33: kg | J33: kg
C34: 上层冷却管 | D34: φ42.3×3.25 | E34: =7349.6+12.5*2 -> 7374.6 | F34: 1 | G34: =F34*E34/100 -> 73.746 | H34: 3.13 | I34: =G34*H34 -> 230.82498 | J34: =(I34+I35)*4 -> 1807.7002
C35: 下层冷却管 | D35: φ42.3×3.25 | E35: =7018.9+22.5*2 -> 7063.9 | F35: 1 | G35: =F35*E35/100 -> 70.639 | H35: 3.13 | I35: =G35*H35 -> 221.10007

Sheet 支座+垫石
A1: 位置 | C1: 支座型号 | D1: 抗剪承载能力(KN) | E1: 支座高度(cm) | F1: 摩擦系数 | G1: 垫石尺寸cm | J1: 支座+垫石+底板控制高度cm | K1: 底板厚cm | L1: 高差 | M1: 垫石高度cm | N1: 支座个数 | O1: 纵坡距离 | P1: 坡度
A2: 引桥支座 | B2: 7z | C2: 20000单向 | D2: =20000*0.15 -> 3000 | E2: 25 | F2: 0.03 | G2: 129*123 | H2: 取值143*143 | J2: 60 | L2: -1.3443 | M2: =J2-E2+L2 -> 33.6557 | N2: 1
B3: 7y | C3: 20000双向 | D3: =20000*0.15 -> 3000 | E3: 25 | F3: 0.03 | G3: 123*123 | J3: 60 | L3: -1.3443 | M3: =J3-E3+L3 -> 33.6557 | N3: 1
B4: 8z | C4: 27500单向 | D4: =27500*0.15 -> 4125 | E4: 29.5 | F4: 0.03 | G4: 143*138 | J4: 60 | L4: -2.89 | M4: =J4-E4+L4 -> 27.61 | N4: 1
B5: 8y | C5: 27500双向 | D5: =27500*0.15 -> 4125 | E5: 29.5 | F5: 0.03 | G5: 138*138 | J5: 60 | L5: -2.89 | M5: =J5-E5+L5 -> 27.61 | N5: 1
A9: 位置 | C9: 支座型号 | D9: 抗剪承载能力(KN) | E9: 支座高度(cm) | F9: 摩擦系数 | G9: 垫石尺寸cm | J9: 支座+垫石+底板控制高度cm | K9: 底板厚cm | M9: 垫石高度cm | N9: 支座个数
A10: 主桥支座 | B10: 7z | C10: 22500单向 | D10: =22500*0.15 -> 3375 | E10: 26.5 | F10: 0.03 | G10: 145*137 | H10: 取值150*150 | J10: 60 | K10: =3.6+4 -> 7.6 | L10: 0.634 | M10: =J10-E10-K10+L10 -> 26.534 | N10: 1
B11: 7y | C11: 22500双向 | D11: =22500*0.15 -> 3375 | E11: 26.5 | F11: 0.03 | G11: 137*137 | J11: 60 | K11: =3.6+4 -> 7.6 | L11: 0.634 | M11: =J11-E11-K11+L11 -> 26.534 | N11: 1
B12: 8z | C12: 22500固定 | D12: =22500*0.15 -> 3375 | E12: 26.5 | F12: 0.03 | G12: 147*137 | J12: 60 | K12: =3.6+4 -> 7.6 | L12: 1.386 | M12: =J12-E12-K12+L12 -> 27.286 | N12: 1
B13: 8y | C13: 22500单向 | D13: =22500*0.15 -> 3375 | E13: 26.5 | F13: 0.03 | G13: 145*137 | J13: 60 | K13: =3.6+4 -> 7.6 | L13: 1.386 | M13: =J13-E13-K13+L13 -> 27.286 | N13: 1
A17: 副拱支座 | D17: 450 | E17: 29 | F17: 0.03 | G17: 90*90 | M17: =58.9-E17 -> 29.9 | N17: 4
A22: 主桥 | B22: 参数 | D22: 编号 | E22: 规格 | F22: 单根长 | G22: 根数 | H22: 总长 | I22: 单位重 | J22: 总重 | K22: 2 | L22: 合计
B23: cm | E23: mm | F23: cm | H23: m | I23: kg/m | J23: kg | K23: kg
B24: H | C24: 26.53 | D24: 1 | E24: 16 | F24: =2*C24+301.8 -> 354.86 | G24: 28 | H24: =G24*F24/100 -> 99.3608 | I24: 1.58 | J24: =H24*I24 -> 156.99006 | K24: =J24*K22 -> 313.98013 | L24: 16 | M24: =K24+K32+K41+K49+K62 -> 1389.7794
B25: a | C25: =C24-5.7-5-15 -> 0.83 | D25: 2 | E25: 12 | F25: =138.6+14.1*2 -> 166.8 | G25: 84 | H25: =G25*F25/100 -> 140.112 | I25: 0.888 | J25: =H25*I25 -> 124.41946 | K25: =SUM(J25:J27)*K22 -> 371.82283 | L25: 12 | M25: =K25+K33+K42+K50+K58 -> 1787.3469
B26: 适用范围 | D26: 3 | E26: 12 | F26: =C24+78.4 -> 104.93 | G26: 49 | H26: =G26*F26/100 -> 51.4157 | I26: 0.888 | J26: =H26*I26 -> 45.657142 | L26: c40 | M26: =K28+K45+K53+K64+K36 -> 5.8964805
B27: 7#墩主桥侧 | D27: 4 | E27: 12 | F27: =138.6*4+40 -> 594.4 | G27: 3 | H27: =G27*F27/100 -> 17.832 | I27: 0.888 | J27: =H27*I27 -> 15.834816
D28: C40混凝土（m ） | J28: =1.5^2*(C24/100) -> 0.596925 | K28: =J28*K22 -> 1.19385
B30: 参数 | D30: 编号 | E30: 规格 | F30: 单根长 | G30: 根数 | H30: 总长 | I30: 单位重 | J30: 总重 | K30: 2
B31: cm | E31: mm | F31: cm | H31: m | I31: kg/m | J31: kg | K31: kg
B32: H | C32: 27.29 | D32: 1 | E32: 16 | F32: =2*C32+301.8 -> 356.38 | G32: 28 | H32: =G32*F32/100 -> 99.7864 | I32: 1.58 | J32: =H32*I32 -> 157.66251 | K32: =J32*K30 -> 315.32502
B33: a | C33: =C32-5.7-5-15 -> 1.59 | D33: 2 | E33: 12 | F33: =138.6+14.1*2 -> 166.8 | G33: 84 | H33: =G33*F33/100 -> 140.112 | I33: 0.888 | J33: =H33*I33 -> 124.41946 | K33: =SUM(J33:J35)*K30 -> 372.48421
B34: 适用范围 | D34: 3 | E34: 12 | F34: =C32+78.4 -> 105.69 | G34: 49 | H34: =G34*F34/100 -> 51.7881 | I34: 0.888 | J34: =H34*I34 -> 45.987833
B35: 8#墩主桥侧 | D35: 4 | E35: 12 | F35: =138.6*4+40 -> 594.4 | G35: 3 | H35: =G35*F35/100 -> 17.832 | I35: 0.888 | J35: =H35*I35 -> 15.834816
D36: C40混凝土（m ） | J36: =1.5^2*(C32/100) -> 0.614025 | K36: =J36*K30 -> 1.22805
A39: 引桥 | B39: 参数 | D39: 编号 | E39: 规格 | F39: 单根长 | G39: 根数 | H39: 总长 | I39: 单位重 | J39: 总重 | K39: 2
B40: cm | E40: mm | F40: cm | H40: m | I40: kg/m | J40: kg | K40: kg
B41: H | C41: 33.66 | D41: 1 | E41: 16 | F41: =2*C41+285.6 -> 352.92 | G41: 26 | H41: =G41*F41/100 -> 91.7592 | I41: 1.58 | J41: =H41*I41 -> 144.97954 | K41: =J41*K39 -> 289.95907
B42: a | C42: =C41-5.7-5-16 -> 6.96 | D42: 2 | E42: 12 | F42: 159.8 | G42: =26*3 -> 78 | H42: =G42*F42/100 -> 124.644 | I42: 0.888 | J42: =H42*I42 -> 110.68387 | K42: =SUM(J42:J44)*K39 -> 323.19222
B43: 适用范围 | D43: 3 | E43: 12 | F43: =C41+78.4 -> 112.06 | G43: 36 | H43: =G43*F43/100 -> 40.3416 | I43: 0.888 | J43: =H43*I43 -> 35.823341
B44: 7#墩引桥侧 | D44: 4 | E44: 12 | F44: 566.4 | G44: 3 | H44: =G44*F44/100 -> 16.992 | I44: 0.888 | J44: =H44*I44 -> 15.088896
D45: C40混凝土（m ） | J45: =1.43^2*(C41/100) -> 0.68831334 | K45: =J45*K39 -> 1.3766267
B47: 参数 | D47: 编号 | E47: 规格 | F47: 单根长 | G47: 根数 | H47: 总长 | I47: 单位重 | J47: 总重 | K47: 2
B48: cm | E48: mm | F48: cm | H48: m | I48: kg/m | J48: kg | K48: kg
B49: H | C49: 27.61 | D49: 1 | E49: 16 | F49: =2*C49+285.6 -> 340.82 | G49: 26 | H49: =G49*F49/100 -> 88.6132 | I49: 1.58 | J49: =H49*I49 -> 140.00886 | K49: =J49*K47 -> 280.01771
B50: a | C50: =C49-5.7-5-16 -> 0.91 | D50: 2 | E50: 12 | F50: 159.8 | G50: =26*3 -> 78 | H50: =G50*F50/100 -> 124.644 | I50: 0.888 | J50: =H50*I50 -> 110.68387 | K50: =SUM(J50:J52)*K47 -> 319.32409
B51: 适用范围 | D51: 3 | E51: 12 | F51: =C49+78.4 -> 106.01 | G51: 36 | H51: =G51*F51/100 -> 38.1636 | I51: 0.888 | J51: =H51*I51 -> 33.889277
B52: 8#墩引桥侧 | D52: 4 | E52: 12 | F52: 566.4 | G52: 3 | H52: =G52*F52/100 -> 16.992 | I52: 0.888 | J52: =H52*I52 -> 15.088896
D53: C40混凝土（m ） | J53: =1.43^2*(C49/100) -> 0.56459689 | K53: =J53*K47 -> 1.1291938
A56: 装饰拱肋 | B56: 参数 | D56: 编号 | E56: 规格 | F56: 单根长 | G56: 数量 | H56: 总长 | I56: 单位重 | J56: 总重 | K56: 4
...

Sheet 防雷+墩顶装饰
C8: 编号 | D8: 规格 | E8: 单根长 | F8: 根数 | G8: 总长 | H8: 单位重 | I8: 总重
D9: mm | E9: mm | G9: m | H9: kg/m | I9: kg
C10: h1 | D10: 16 | E10: 550 | F10: 10 | G10: =F10*E10/1000 -> 5.5 | H10: 1.58 | I10: =G10*H10 -> 8.69
C11: h2 | D11: 16 | E11: 700 | F11: 14 | G11: =F11*E11/1000 -> 9.8 | H11: 1.58 | I11: =G11*H11 -> 15.484
C12: h3 | D12: 10 | E12: =938.5*2+140 -> 2017 | F12: 4 | G12: =F12*E12/1000 -> 8.068 | H12: 0.617 | I12: =G12*H12 -> 4.977956
C18: 编号 | D18: 规格/牌号 | E18: 单件重 | F18: 数量 | G18: 合计
D19: mm | E19: kg
C20: A1 | D20: □200×5×200 | E20: =0.2*0.2*0.005*7850 -> 1.57 | F20: 8 | G20: =E20*F20 -> 12.56
C21: A2 | D21: □100×5×100 | E21: =0.1*0.1*0.005*7850 -> 0.3925 | F21: 8 | G21: =E21*F21 -> 3.14
C22: M16螺栓 | D22: GB/T 5782-2000 | E22: - | F22: =F20 -> 8 | G22: -
C23: 铜带 | D23: 4×50×1000(暂估) | E23: - | F23: 4 | G23: -
C29: 材料种类 | D29: 牌号 | E29: 规格 | F29: 单位 | G29: 全桥数量
C30: 钢筋 | D30: HRB400 | E30: 16 | F30: kg | G30: =(I10+I11)*4 -> 96.696
D31: HPB300 | E31: 10 | G31: =I12*4 -> 19.911824
C32: 钢材 | D32: 1Cr18Ni12 | E32: t=5mm | F32: kg | G32: =(G20+G21)*4 -> 62.8
C33: 螺栓 | D33: (GB/T 5782-2000) | E33: M16 | F33: 个 | G33: =F22*4 -> 32
C34: 铜带 | E34: 4×50×1000(暂估) | F34: m | G34: =F23*1*4 -> 16
C41: 编号 | D41: 规格 | E41: 单件重 | F41: 数量 | G41: 总重 | H41: 全桥合计(4) | I41: 牌号 | J41: 12 | K41: =G48*4 -> 978.5496
D42: mm | E42: kg | G42: kg | H42: kg | J42: 8 | K42: =SUM(G43:G47)*4 -> 7587.5069 | M42: 涂装
C43: HG1 | D43: □1650×8×6593 | E43: =6.57188731*0.008*7850 -> 412.71452 | F43: 2 | G43: =E43*F43 -> 825.42905 | H43: =SUM(G43:G50)*4 -> 37559.063 | I43: Q235C | J43: 4 | K43: =G50*4 -> 28807.319 | M43: =G43/7850/0.008*2*F43 -> 52.575098
C44: HG2 | D44: □1502×8×2918 | E44: =2.99882077*0.008*7850 -> 188.32594 | F44: 4 | G44: =E44*F44 -> 753.30378 | J44: 涂装 | K44: =SUM(M43:M50) -> 651.30648 | M44: =G44/7850/0.008*2*F44 -> 95.962265
C45: HG3 | D45: □1145×8×1613 | E45: =1.28326789*0.008*7850 -> 80.589223 | F45: 2 | G45: =E45*F45 -> 161.17845 | M45: =G45/7850/0.008*2*F45 -> 10.266143
C46: 预埋钢板N1 | D46: □150×8×15425 | E46: =14.463*0.15*0.008*7850 -> 136.24146 | F46: 1 | G46: =E46*F46 -> 136.24146 | M46: =G46/7850/0.008*2*F46 -> 4.3389
C47: 预埋钢板N2 | D47: □150×8×1100 | E47: =1.1*0.15*0.008*7850 -> 10.362 | F47: =F43 -> 2 | G47: =E47*F47 -> 20.724 | M47: =G47/7850/0.008*2*F47 -> 1.32
C48: N3 | D48: □350×12×3710(平均) | E48: =3.71*0.35*0.012*7850 -> 122.3187 | F48: =F43 -> 2 | G48: =E48*F48 -> 244.6374 | M48: =G48/7850/0.012*2*F48 -> 10.388
C49: N4 | D49: □80×8×770(平均) | E49: =0.77*0.08*0.008*7850 -> 3.86848 | F49: 12 | G49: =E49*F49 -> 46.42176 | M49: =G49/7850/0.008*2*F49 -> 17.7408
C50: W1 | D50: □5395×4×42513(平均) | E50: =42.513*0.004*5.395*7850 -> 7201.8297 | F50: 1 | G50: =E50*F50 -> 7201.8297 | M50: =G50/7850/0.004*2*F50 -> 458.71527
C51: 预埋钢筋 | D51: 12 | E51: =0.892*0.888 -> 0.792096 | F51: =75 -> 75 | G51: =E51*F51 -> 59.4072 | H51: =G51*4 -> 237.6288 | I51: HRB400
C52: 爬梯钢筋 | D52: 32 | E52: =3.514*6.31 -> 22.17334 | F52: 3 | G52: =E52*F52 -> 66.52002 | H52: =G52*4 -> 266.08008
C53: 涂装面积（m2） | G53: =SUM(M43:M50) -> 651.30648 | H53: =G53*4 -> 2605.2259

Sheet 主桥下部数量表
A4: 材料名称 | B4: 规格 | E4: 单位 | F4: 墩身 | G4: 承台 | H4: 桩基 | I4: 支座及垫石 | J4: 墩顶装饰 | K4: 防雷设施 | L4: 合计
A5: 混凝土 | B5: C40 | E5: m3 | F5: 467.5 | I5: ='支座+垫石'!M26 -> 5.8964805 | L5: =SUM(F5:K5) -> 473.39648
B6: C35 | E6: m3 | G6: =承台!J21 -> 805.048 | L6: =SUM(F6:K6) -> 805.048
B7: C35水下 | E7: m3 | H7: 3513.1 | L7: =SUM(F7:K7) -> 3513.1
B8: C25封底混凝土 | E8: m3 | G8: =承台!J22 -> 241.5144 | L8: =SUM(F8:K8) -> 241.5144
A9: 钢材 | B9: 1Cr18Ni12 | D9: t=5 | E9: kg | K9: ='防雷+墩顶装饰'!G32 -> 62.8 | L9: =SUM(F9:K9) -> 62.8
B10: Q235C | D10: t=12 | E10: kg | J10: ='防雷+墩顶装饰'!K41 -> 978.5496 | L10: =SUM(F10:K10) -> 978.5496
D11: t=8 | E11: kg | J11: ='防雷+墩顶装饰'!K42 -> 7587.5069 | L11: =SUM(F11:K11) -> 7587.5069
D12: t=4 | E12: kg | J12: ='防雷+墩顶装饰'!K43 -> 28807.319 | L12: =SUM(F12:K12) -> 28807.319
B13: 小计 | E13: kg | J13: =SUM(J9:J12) -> 37373.375 | K13: =SUM(K9:K12) -> 62.8 | L13: =SUM(F13:K13) -> 37436.175
A14: 钢筋 | B14: HRB400 | D14: 32 | E14: kg | F14: 31730.3 | J14: ='防雷+墩顶装饰'!H52 -> 266.08008 | L14: =SUM(F14:K14) -> 31996.38
D15: 28 | E15: kg | G15: =承台!J9 -> 91471.892 | L15: =SUM(F15:K15) -> 91471.892
D16: 25 | E16: kg | F16: 12993.1 | H16: 185934.6 | L16: =SUM(F16:K16) -> 198927.7
D17: 20 | E17: kg | G17: =承台!J14 -> 6130.0262 | L17: =SUM(F17:K17) -> 6130.0262
D18: 16 | E18: kg | F18: 32112 | G18: =承台!J15 -> 5624.1427 | I18: ='支座+垫石'!M24 -> 1389.7794 | K18: ='防雷+墩顶装饰'!G30 -> 96.696 | L18: =SUM(F18:K18) -> 39222.618
D19: 12 | E19: kg | I19: ='支座+垫石'!M25 -> 1787.3469 | J19: ='防雷+墩顶装饰'!H51 -> 237.6288 | L19: =SUM(F19:K19) -> 2024.9757
B20: HPB300 | D20: 10 | E20: kg | H20: 45546.8 | K20: ='防雷+墩顶装饰'!G31 -> 19.911824 | L20: =SUM(F20:K20) -> 45566.712
B21: 小计 | E21: kg | F21: =SUM(F14:F20) -> 76835.4 | G21: =SUM(G14:G20) -> 103226.06 | H21: =SUM(H14:H20) -> 231481.4 | I21: =SUM(I14:I20) -> 3177.1262 | J21: =SUM(J14:J20) -> 503.70888 | K21: =SUM(K14:K20) -> 116.60782 | L21: =SUM(F21:K21) -> 415340.3
A22: 12冷轧带肋钢筋网 | E22: kg | G22: =承台!J20 -> 5715.8408 | L22: =SUM(F22:K22) -> 5715.8408
A23: 钢筋连接器 | B23: 25 | E23: 个 | H23: 4256 | L23: =SUM(F23:K23) -> 4256
B24: 28 | E24: 个 | G24: =承台!J23 -> 492 | L24: =SUM(F24:K24) -> 492
B25: 32 | E25: 个 | F25: 544 | L25: =SUM(F25:K25) -> 544
A26: 螺栓 | B26: GB/T 5782-2000 | D26: M16 | E26: 个 | K26: ='防雷+墩顶装饰'!G33 -> 32 | L26: =SUM(F26:K26) -> 32
A27: 声测管 | B27: Q235B | C27: φ57×3(mm) | E27: kg | H27: 24162.8 | L27: =SUM(F27:K27) -> 24162.8
A28: 涂装 | B28: 外表面涂装 | E28: m2 | F28: 448.7 | J28: ='防雷+墩顶装饰'!K44 -> 651.30648 | L28: =SUM(F28:K28) -> 1100.0065
A29: 铜带 | B29: 4×50mm | E29: m | K29: ='防雷+墩顶装饰'!G34 -> 16 | L29: =SUM(F29:K29) -> 16
A30: C35混凝土定位块 | E30: 个 | H30: 3976 | L30: =SUM(F30:K30) -> 3976
A31: 冷却管 | B31: φ42.3×3.25 | E31: kg | G31: =承台!J34 -> 1807.7002 | L31: =SUM(F31:K31) -> 1807.7002
A32: 支座 | B32: 20000单向 | E32: 个 | I32: 1 | L32: =SUM(F32:K32) -> 1
B33: 20000双向 | E33: 个 | I33: 1 | L33: =SUM(F33:K33) -> 1
B34: 27500单向 | E34: 个 | I34: 1 | L34: =SUM(F34:K34) -> 1
B35: 27500双向 | E35: 个 | I35: 1 | L35: =SUM(F35:K35) -> 1
B36: 22500固定 | E36: 个 | I36: 1 | L36: =SUM(F36:K36) -> 1
B37: 22500单向 | E37: 个 | I37: 2 | L37: =SUM(F37:K37) -> 2
B38: 22500双向 | E38: 个 | I38: 1 | L38: =SUM(F38:K38) -> 1
B39: 3000单向(副拱,位于引桥) | E39: 个 | I39: 4 | L39: =SUM(F39:K39) -> 4
