Workbook

Sheet 梁段划分
A1: 梁段编号 | B1: C1 | C1: B1 | D1: A | E1: A | F1: A | G1: A | H1: A | I1: A | J1: A | K1: B2 | L1: C2
A2: 顶板厚(mm) | B2: 16 | C2: 16 | D2: 16 | K2: 16 | L2: 16
A3: 顶板加劲尺寸(mm) | B3: U 300×8、12×140 | C3: U 300×8、12×140 | D3: U 300×8、12×140 | K3: U 300×8、12×140 | L3: U 300×8、12×140
A4: 底板厚(mm) | B4: 24 | C4: 32 | D4: 28 | K4: 32 | L4: 24
A5: 底板加劲尺寸(mm) | B5: 12×140 | C5: 12×140 | D5: 12×140 | K5: 12×140 | L5: 12×140
A6: 腹板厚(mm) | B6: 14 | C6: 14 | D6: 14 | K6: 14 | L6: 14
A7: 腹板加劲尺寸(mm) | B7: 12×140 | C7: 12×140 | D7: 12×140 | K7: 12×140 | L7: 12×140
A19: 吊索编号 | B19: 1 | C19: 2 | D19: 3 | E19: 4 | F19: 5 | G19: 6 | H19: 7 | I19: 8 | J19: 9 | K19: 10 | L19: 11 | M19: 12 | N19: 13 | O19: 14 | P19: 15 | Q19: 16 | R19: 17 | S19: 18 | T19: 19
A20: 吊索型号 | B20: PES7-85 | D20: PES7-73 | S20: PES7-85
A21: 吊索倾角α(°) | B21: 91.136097 | C21: 86.573859 | D21: 84.670368 | E21: 83.650438 | F21: 83.033914 | G21: 82.638479 | H21: 82.380767 | I21: 82.218362 | J21: 82.12873 | K21: 82.100517 | L21: 82.145937 | M21: 82.25337 | N21: 82.434737 | O21: 82.713153 | P21: 83.131484 | Q21: 83.772742 | R21: 84.815013 | S21: 86.713527 | T21: 91.055335
A22: 单根吊索长L(m) | B22: 9.0522364 | C22: 13.796947 | D22: 18.029097 | E22: 21.719208 | F22: 24.860683 | G22: 27.451481 | H22: 29.491056 | I22: 30.979505 | J22: 31.917277 | K22: 32.305036 | L22: 31.984504 | M22: 31.113992 | N22: 29.692866 | O22: 27.720728 | P22: 25.197544 | Q22: 22.12397 | R22: 18.502226 | S22: 14.339593 | T22: 9.6677192
A23: 单根吊索钢丝重(kg) | B23: =B22*25.6 -> 231.73725 | C23: =C22*25.6 -> 353.20183 | D23: =D22*22 -> 396.64014 | E23: =E22*22 -> 477.82257 | F23: =F22*22 -> 546.93503 | G23: =G22*22 -> 603.93259 | H23: =H22*22 -> 648.80322 | I23: =I22*22 -> 681.54912 | J23: =J22*22 -> 702.1801 | K23: =K22*22 -> 710.71079 | ... R23: =R22*22 -> 407.04897 | S23: =S22*25.6 -> 367.09358 | T23: =T22*25.6 -> 247.49361
A24: 全桥根数 | B24: 2 | C24: 2 | D24: 2 | E24: 2 | F24: 2 | G24: 2 | H24: 2 | I24: 2 | J24: 2 | K24: 2 | L24: 2 | M24: 2 | N24: 2 | O24: 2 | P24: 2 | Q24: 2 | R24: 2 | S24: 2 | T24: 2
A25: 全桥吊索钢丝重(kg) | B25: =B24*B23 -> 463.47451 | C25: =C24*C23 -> 706.40367 | D25: =D24*D23 -> 793.28027 | E25: =E24*E23 -> 955.64515 | F25: =F24*F23 -> 1093.8701 | G25: =G24*G23 -> 1207.8652 | H25: =H24*H23 -> 1297.6064 | I25: =I24*I23 -> 1363.0982 | ... T25: =T24*T23 -> 494.98723
C30: 单位 | D30: 吊索
A31: 吊索 | B31: PES7-73 | C31: kg | D31: =SUM(C25:S25) -> 19176.514
B32: PES7-85 | C32: kg | D32: =B25+T25 -> 958.46173
A33: 合计 | C33: kg | D33: =D31+D32 -> 20134.976

Sheet A类梁段
B2: 参数 | C2: L | D2: L1 | E2: L2 | F2: L3 | G2: L5 | H2: L6 | I2: α
C3: mm | D3: mm | E3: mm | F3: mm | G3: mm | H3: mm | I3: 度(°) | N3: sin角度 | O3: 斜边 | P3: cos角度 | Q3: 临边
B4: 吊索4 | C4: 1063.3828 | D4: 1163.6172 | E4: 1052.6172 | F4: 804.38278 | G4: 269.12767 | H4: 2573.8723 | I4: 83.650438 | N4: =SIN(I4*PI()/180) -> 0.99386566 | O4: =100/N4 -> 100.61722 | P4: =COS(I4*PI()/180) -> 0.11059407 | Q4: =P4*O4 -> 11.127668
B5: 吊索5 | C5: 1064.2563 | D5: 1170.7437 | E5: 1048.7437 | F5: 803.25632 | G5: 245.21838 | H5: 2596.7816 | I5: 83.033914 | N5: =SIN(I5*PI()/180) -> 0.99261811 | O5: =100/N5 -> 100.74368 | P5: =COS(I5*PI()/180) -> 0.12128182 | Q5: =P5*O5 -> 12.218376
B6: 吊索6 | C6: 1065.1689 | D6: 1175.8311 | E6: 1045.8311 | F6: 803.16889 | G6: 229.91945 | H6: 2611.0806 | I6: 82.638479 | N6: =SIN(I6*PI()/180) -> 0.99175744 | O6: =100/N6 -> 100.83111 | P6: =COS(I6*PI()/180) -> 0.12812958 | Q6: =P6*O6 -> 12.919447
B7: 吊索7 | C7: 1066.1092 | D7: 1178.8908 | E7: 1043.8908 | F7: 803.10924 | G7: 220.37702 | H7: 2619.623 | I7: 82.380767 | N7: =SIN(I7*PI()/180) -> 0.99117109 | O7: =100/N7 -> 100.89076 | P7: =COS(I7*PI()/180) -> 0.13258911 | Q7: =P7*O7 -> 13.377016
B8: 吊索8 | C8: 1066.0706 | D8: 1179.9294 | E8: 1043.9294 | F8: 803.07057 | G8: 213.66565 | H8: 2626.3344 | I8: 82.218362 | N8: =SIN(I8*PI()/180) -> 0.99079128 | O8: =100/N8 -> 100.92943 | P8: =COS(I8*PI()/180) -> 0.13539805 | Q8: =P8*O8 -> 13.665648
B9: 吊索9 | C9: 1067.0489 | D9: 1181.9511 | E9: 1042.9511 | F9: 803.04886 | G9: 210.82504 | H9: 2629.175 | I9: 82.12873 | N9: =SIN(I9*PI()/180) -> 0.99057826 | O9: =100/N9 -> 100.95114 | P9: =COS(I9*PI()/180) -> 0.13694785 | Q9: =P9*O9 -> 13.825041
B10: 吊索10 | C10: 1067.042 | D10: 1181.958 | E10: 1042.958 | F10: 803.04198 | G10: 209.87523 | H10: 2630.1248 | I10: 82.100517 | N10: =SIN(I10*PI()/180) -> 0.9905107 | O10: =100/N10 -> 100.95802 | P10: =COS(I10*PI()/180) -> 0.13743561 | Q10: =P10*O10 -> 13.875227
B11: 吊索11 | C11: 1067.0531 | D11: 1180.9469 | E11: 1042.9469 | F11: 803.05305 | G11: 210.79444 | H11: 2628.2056 | I11: 82.145937 | N11: =SIN(I11*PI()/180) -> 0.99061934 | O11: =100/N11 -> 100.94695 | P11: =COS(I11*PI()/180) -> 0.13665036 | Q11: =P11*O11 -> 13.794437
B12: 吊索12 | C12: 1066.079 | D12: 1179.921 | E12: 1043.921 | F12: 803.07898 | G12: 215.60341 | H12: 2624.3966 | I12: 82.25337 | N12: =SIN(I12*PI()/180) -> 0.99087383 | O12: =100/N12 -> 100.92102 | P12: =COS(I12*PI()/180) -> 0.13479264 | Q12: =P12*O12 -> 13.603412
B13: 吊索13 | C13: 1066.1219 | D13: 1177.8781 | E13: 1044.8781 | F13: 803.12191 | G13: 222.28115 | H13: 2617.7189 | I13: 82.434737 | N13: =SIN(I13*PI()/180) -> 0.99129554 | O13: =100/N13 -> 100.87809 | P13: =COS(I13*PI()/180) -> 0.13165541 | Q13: =P13*O13 -> 13.281146
B14: 吊索14 | C14: 1065.1858 | D14: 1174.8142 | E14: 1046.8142 | F14: 802.18578 | G14: 232.78696 | H14: 2608.213 | I14: 82.713153 | N14: =SIN(I14*PI()/180) -> 0.99192359 | O14: =100/N14 -> 100.81422 | P14: =COS(I14*PI()/180) -> 0.1268369 | Q14: =P14*O14 -> 12.786963
B15: 吊索15 | C15: 1064.2771 | D15: 1169.7229 | E15: 1048.7229 | F15: 803.27713 | G15: 249.04558 | H15: 2592.9544 | I15: 83.131484 | N15: =SIN(I15*PI()/180) -> 0.99282321 | O15: =100/N15 -> 100.72287 | P15: =COS(I15*PI()/180) -> 0.1195913 | Q15: =P15*O15 -> 12.045578
... B17: 吊索17 | C17: 1061.5891 | D17: 1150.4109 | E17: 1060.4109 | F17: 805.58913 | G17: 313.07429 | H17: 2531.9257 | I17: 84.815013 | N17: =SIN(I17*PI()/180) -> 0.99590811 | O17: =100/N17 -> 100.41087 | P17: =COS(I17*PI()/180) -> 0.090371621 | Q17: =P17*O17 -> 9.0742931
B28: 编号 | C28: 规格(mm) | D28: 数量 | E28: 单件重(kg) | F28: 共重(kg) | I28: 长边 | J28: 厚度 | K28: 短边 | L28: 侧面S | M28: 涂装
B29: T1 | C29: =CONCATENATE("□",I29,"×",J29,"×",K29) -> □18000×16×40000 | D29: 1 | E29: =IF(L29>0,(L29*J29/1000000000*7850),(I29*J29*K29/1000000000*7850)) -> 90432 | F29: =D29*E29 -> 90432 | I29: 18000 | J29: 16 | K29: 40000 | M29: =IF(L29>0,(L29*2/1000000),(I29*K29*2/1000000)) -> 1440 | N29: =D29*M29 -> 1440
B30: TJ1 | C30: =CONCATENATE("□",I30,"×",J30,"×",K30) -> □460×24×18000 | D30: 2 | E30: =IF(L30>0,(L30*J30/1000000000*7850),(I30*J30*K30/1000000000*7850)) -> 1559.952 | F30: =D30*E30 -> 3119.904 | I30: 460 | J30: 24 | K30: 18000 | M30: =IF(L30>0,(L30*2/1000000),(I30*K30*2/1000000)) -> 16.56 | N30: =D30*M30 -> 33.12
B31: TJ2 | C31: =CONCATENATE("□",I31,"×",J31,"×",K31) -> □140×12×18000 | D31: =(9+9+1)*2 -> 38 | E31: =IF(L31>0,(L31*J31/1000000000*7850),(I31*J31*K31/1000000000*7850)) -> 237.384 | F31: =D31*E31 -> 9020.592 | I31: 140 | J31: 12 | K31: 18000 | M31: =IF(L31>0,(L31*2/1000000),(I31*K31*2/1000000)) -> 5.04 | N31: =D31*M31 -> 191.52
B32: TU1 | C32: =CONCATENATE("U",I32,"×",J32,"×",K32) -> U300×8×18000 | D32: 40 | E32: =L32*I32/1000000000*7850 -> 13.425314 | F32: =D32*E32 -> 537.01257 | I32: 300 | J32: 8 | K32: 18000 | L32: 5700.7704 | M32: =1441.6181*I32/1000000 -> 0.43248543 | N32: =D32*M32 -> 17.299417
B33: D1 | C33: =CONCATENATE("□",I33,"×",J33,"×",K33) -> □500×16×19518 | D33: 6 | E33: =IF(L33>0,(L33*J33/1000000000*7850),(I33*J33*K33/1000000000*7850)) -> 1225.7304 | F33: =D33*E33 -> 7354.3824 | I33: 500 | J33: 16 | K33: =9759*2 -> 19518 | M33: =IF(L33>0,(L33*2/1000000),(I33*K33*2/1000000)) -> 19.518 | N33: =D33*M33 -> 117.108
B34: D2 | C34: =CONCATENATE("□",I34,"×",J34,"×",K34) -> □3990×28×18000 | D34: 2 | E34: =IF(L34>0,(L34*J34/1000000000*7850),(I34*J34*K34/1000000000*7850)) -> 15786.036 | F34: =D34*E34 -> 31572.072 | I34: 3990 | J34: 28 | K34: 18000 | M34: =IF(L34>0,(L34*2/1000000),(I34*K34*2/1000000)) -> 143.64 | N34: =D34*M34 -> 287.28
B35: D3 | C35: =CONCATENATE("□",I35,"×",J35,"×",K35) -> □380×16×4828 | D35: 12 | E35: =IF(L35>0,(L35*J35/1000000000*7850),(I35*J35*K35/1000000000*7850)) -> 230.43078 | F35: =D35*E35 -> 2765.1694 | I35: 380 | J35: 16 | K35: 4828 | M35: =IF(L35>0,(L35*2/1000000),(I35*K35*2/1000000)) -> 3.66928 | N35: =D35*M35 -> 44.03136
B36: DJ1 | C36: =CONCATENATE("□",I36,"×",J36,"×",K36) -> □140×12×18000 | D36: 14 | E36: =IF(L36>0,(L36*J36/1000000000*7850),(I36*J36*K36/1000000000*7850)) -> 237.384 | F36: =D36*E36 -> 3323.376 | I36: 140 | J36: 12 | K36: 18000 | M36: =IF(L36>0,(L36*2/1000000),(I36*K36*2/1000000)) -> 5.04 | N36: =D36*M36 -> 70.56
B37: F1 | C37: =CONCATENATE("□",I37,"×",J37,"×",K37) -> □2991×14×18000 | D37: 2 | E37: =IF(L37>0,(L37*J37/1000000000*7850),(I37*J37*K37/1000000000*7850)) -> 5916.7962 | F37: =D37*E37 -> 11833.592 | I37: 2991 | J37: 14 | K37: 18000 | M37: =IF(L37>0,(L37*2/1000000),(I37*K37*2/1000000)) -> 107.676 | N37: =D37*M37 -> 215.352
B38: F2 | C38: =CONCATENATE("□",I38,"×",J38,"×",K38) -> □2283×14×18000 | D38: 2 | E38: =IF(L38>0,(L38*J38/1000000000*7850),(I38*J38*K38/1000000000*7850)) -> 4516.2306 | F38: =D38*E38 -> 9032.4612 | I38: 2283 | J38: 14 | K38: 18000 | M38: =IF(L38>0,(L38*2/1000000),(I38*K38*2/1000000)) -> 82.188 | N38: =D38*M38 -> 164.376
B39: FJ1 | C39: =CONCATENATE("□",I39,"×",J39,"×",K39) -> □140×12×18000 | D39: 18 | E39: =IF(L39>0,(L39*J39/1000000000*7850),(I39*J39*K39/1000000000*7850)) -> 237.384 | F39: =D39*E39 -> 4272.912 | I39: 140 | J39: 12 | K39: 18000 | M39: =IF(L39>0,(L39*2/1000000),(I39*K39*2/1000000)) -> 5.04 | N39: =D39*M39 -> 90.72
B40: FJ2 | C40: =CONCATENATE("□",I40,"×",J40,"×",K40) -> □234×16×450 | D40: 16 | E40: =IF(L40>0,(L40*J40/1000000000*7850),(I40*J40*K40/1000000000*7850)) -> 13.22568 | F40: =D40*E40 -> 211.61088 | I40: 234 | J40: 16 | K40: 450 | M40: =IF(L40>0,(L40*2/1000000),(I40*K40*2/1000000)) -> 0.2106 | N40: =D40*M40 -> 3.3696
B41: FJ3 | C41: =CONCATENATE("□",I41,"×",J41,"×",K41) -> □226×16×450 | D41: 8 | E41: =IF(L41>0,(L41*J41/1000000000*7850),(I41*J41*K41/1000000000*7850)) -> 12.77352 | F41: =D41*E41 -> 102.18816 | I41: 226 | J41: 16 | K41: 450 | M41: =IF(L41>0,(L41*2/1000000),(I41*K41*2/1000000)) -> 0.2034 | N41: =D41*M41 -> 1.6272
B42: HG1 | C42: =CONCATENATE("□",I42,"×",J42,"×",K42) -> □2384×12×19864 | D42: 6 | E42: =IF(L42>0,(L42*J42/1000000000*7850),(I42*J42*K42/1000000000*7850)) -> 4011.9568 | F42: =D42*E42 -> 24071.741 | I42: 2384 | J42: 12 | K42: 19864 | L42: =2*21294887.2264 -> 42589774 | M42: =IF(L42>0,(L42*2/1000000),(I42*K42*2/1000000)) -> 85.179549 | N42: =D42*M42 -> 511.07729
B43: HG2 | C43: =CONCATENATE("□",I43,"×",J43,"×",K43) -> □2241×12×6336 | D43: 8 | E43: =IF(L43>0,(L43*J43/1000000000*7850),(I43*J43*K43/1000000000*7850)) -> 912.42917 | F43: =D43*E43 -> 7299.4333 | I43: 2241 | J43: 12 | K43: 6336 | L43: 9686084.6 | M43: =IF(L43>0,(L43*2/1000000),(I43*K43*2/1000000)) -> 19.372169 | N43: =D43*M43 -> 154.97735
B44: HG3 | C44: =CONCATENATE("□",I44,"×",J44,"×",K44,"(平均)") -> □2283×28×3139(平均) | D44: 4 | E44: =IF(L44>0,(L44*J44/1000000000*7850),(I44*J44*K44/1000000000*7850)) -> 1321.0959 | F44: =D44*E44 -> 5284.3835 | I44: 2283 | J44: 28 | K44: 3139 | L44: 6010445.3 | M44: =IF(L44>0,(L44*2/1000000),(I44*K44*2/1000000)) -> 12.020891 | N44: =D44*M44 -> 48.083563
B45: HG4 | C45: =CONCATENATE("□",I45,"×",J45,"×",K45,"(平均)") -> □2189×28×2889(平均) | D45: 4 | E45: =IF(L45>0,(L45*J45/1000000000*7850),(I45*J45*K45/1000000000*7850)) -> 705.59954 | F45: =D45*E45 -> 2822.3982 | I45: 2189 | J45: 28 | K45: 2889 | L45: 3210189 | M45: =IF(L45>0,(L45*2/1000000),(I45*K45*2/1000000)) -> 6.420378 | N45: =D45*M45 -> 25.681512
B46: HG5 | C46: =CONCATENATE("□",I46,"×",J46,"×",K46) -> □789×12×4820 | D46: 12 | E46: =IF(L46>0,(L46*J46/1000000000*7850),(I46*J46*K46/1000000000*7850)) -> 230.03078 | F46: =D46*E46 -> 2760.3694 | I46: 789 | J46: 12 | K46: 4820 | L46: 2441940.4 | M46: =IF(L46>0,(L46*2/1000000),(I46*K46*2/1000000)) -> 4.8838807 | N46: =D46*M46 -> 58.606569
B47: HJ1 | C47: =CONCATENATE("□",I47,"×",J47,"×",K47) -> □140×12×19180 | D47: 12 | E47: =IF(L47>0,(L47*J47/1000000000*7850),(I47*J47*K47/1000000000*7850)) -> 252.94584 | F47: =D47*E47 -> 3035.3501 | I47: 140 | J47: 12 | K47: =9590*2 -> 19180 | M47: =IF(L47>0,(L47*2/1000000),(I47*K47*2/1000000)) -> 5.3704 | N47: =D47*M47 -> 64.4448
B48: HJ2 | C48: =CONCATENATE("□",I48,"×",J48,"×",K48) -> □180×12×1884 | D48: 24 | E48: =IF(L48>0,(L48*J48/1000000000*7850),(I48*J48*K48/1000000000*7850)) -> 31.945104 | F48: =D48*E48 -> 766.6825 | I48: 180 | J48: 12 | K48: 1884 | M48: =IF(L48>0,(L48*2/1000000),(I48*K48*2/1000000)) -> 0.67824 | N48: =D48*M48 -> 16.27776
B49: HJ3 | C49: =CONCATENATE("□",I49,"×",J49,"×",K49) -> □180×12×1857 | D49: 24 | E49: =IF(L49>0,(L49*J49/1000000000*7850),(I49*J49*K49/1000000000*7850)) -> 31.487292 | F49: =D49*E49 -> 755.69501 | I49: 180 | J49: 12 | K49: 1857 | M49: =IF(L49>0,(L49*2/1000000),(I49*K49*2/1000000)) -> 0.66852 | N49: =D49*M49 -> 16.04448
B50: HJ4 | C50: =CONCATENATE("□",I50,"×",J50,"×",K50) -> □180×12×1830 | D50: 24 | E50: =IF(L50>0,(L50*J50/1000000000*7850),(I50*J50*K50/1000000000*7850)) -> 31.02948 | F50: =D50*E50 -> 744.70752 | I50: 180 | J50: 12 | K50: 1830 | M50: =IF(L50>0,(L50*2/1000000),(I50*K50*2/1000000)) -> 0.6588 | N50: =D50*M50 -> 15.8112
B51: HJ5 | C51: =CONCATENATE("□",I51,"×",J51,"×",K51) -> □180×12×1803 | D51: 24 | E51: =IF(L51>0,(L51*J51/1000000000*7850),(I51*J51*K51/1000000000*7850)) -> 30.571668 | F51: =D51*E51 -> 733.72003 | I51: 180 | J51: 12 | K51: 1803 | M51: =IF(L51>0,(L51*2/1000000),(I51*K51*2/1000000)) -> 0.64908 | N51: =D51*M51 -> 15.57792
B52: HJ6 | C52: =CONCATENATE("□",I52,"×",J52,"×",K52) -> □180×12×1776 | D52: 24 | E52: =IF(L52>0,(L52*J52/1000000000*7850),(I52*J52*K52/1000000000*7850)) -> 30.113856 | F52: =D52*E52 -> 722.73254 | I52: 180 | J52: 12 | K52: 1776 | M52: =IF(L52>0,(L52*2/1000000),(I52*K52*2/1000000)) -> 0.63936 | N52: =D52*M52 -> 15.34464
...

Sheet B1类梁段
B2: 参数 | C2: L1 | D2: L2 | E2: L3 | F2: L4
C3: mm | D3: mm | E3: mm | F3: mm
B4: HG2 | C4: 4820 | D4: 4073 | E4: 1073 | F4: =1558-500 -> 1058
B5: HG3 | C5: 4820 | D5: 4073 | E5: 1073
B6: HG4 | C6: 4581 | D6: 3853 | E6: 1045.8311
B7: HG5 | C7: 4342 | D7: 3633 | E7: 1029 | F7: =1560-500 -> 1060
B8: HG6 | C8: 4157 | D8: 3463 | E8: 999
B9: HG7 | C9: 3864 | D9: 3193 | E9: 967
B10: HG8 | C10: 3625 | D10: 2973 | E10: 940 | F10: =1562-500 -> 1062
A21: 位置 | B21: 编号 | C21: 规格(mm) | D21: 数量 | E21: 单件重(kg) | F21: 共重(kg) | I21: 长边 | J21: 厚度 | K21: 短边 | L21: 侧面S | M21: 涂装
A22: 顶板 | B22: T1 | C22: =CONCATENATE("□",I22,"×",J22,"×",K22) -> □19600×16×43398 | D22: 1 | E22: =IF(L22>0,(L22*J22/1000000000*7850),(I22*J22*K22/1000000000*7850)) -> 101730.84 | F22: =D22*E22 -> 101730.84 | I22: 19600 | J22: 16 | K22: 43398 | L22: =404979457.4716*2 -> 8.0995891e+08 | M22: =IF(L22>0,(L22*2/1000000),(I22*K22*2/1000000)) -> 1619.9178 | N22: =D22*M22 -> 1619.9178
B23: TJ1 | C23: =CONCATENATE("□",I23,"×",J23,"×",K23) -> □460×24×19682 | D23: 2 | E23: =IF(L23>0,(L23*J23/1000000000*7850),(I23*J23*K23/1000000000*7850)) -> 1705.7208 | F23: =D23*E23 -> 3411.4417 | I23: 460 | J23: 24 | K23: 19682 | M23: =IF(L23>0,(L23*2/1000000),(I23*K23*2/1000000)) -> 18.10744 | N23: =D23*M23 -> 36.21488
B24: TJ2 | C24: =CONCATENATE("□",I24,"×",J24,"×",K24,"(总长)") -> □140×12×793814(总长) | D24: 1 | E24: =IF(L24>0,(L24*J24/1000000000*7850),(I24*J24*K24/1000000000*7850)) -> 10468.819 | F24: =D24*E24 -> 10468.819 | I24: 140 | J24: 12 | K24: =396907*2 -> 793814 | M24: =IF(L24>0,(L24*2/1000000),(I24*K24*2/1000000)) -> 222.26792 | N24: =D24*M24 -> 222.26792
B25: TU1 | C25: =CONCATENATE("U",I25,"×",J25,"×",K25) -> U300×8×19600 | D25: 40 | E25: =L25*I25/1000000000*7850 -> 13.425314 | F25: =D25*E25 -> 537.01257 | I25: 300 | J25: 8 | K25: 19600 | L25: 5700.7704 | M25: =IF(L25>0,(L25*2/1000000),(I25*K25*2/1000000)) -> 0.011401541 | N25: =D25*M25 -> 0.45606163
A26: 底板 | B26: D1 | C26: =CONCATENATE("□",I26,"×",J26,"×",K26) -> □500×16×19518 | D26: 7 | E26: =IF(L26>0,(L26*J26/1000000000*7850),(I26*J26*K26/1000000000*7850)) -> 1225.7304 | F26: =D26*E26 -> 8580.1128 | I26: 500 | J26: 16 | K26: =9759*2 -> 19518 | M26: =IF(L26>0,(L26*2/1000000),(I26*K26*2/1000000)) -> 19.518 | N26: =D26*M26 -> 136.626
B27: D2 | C27: =CONCATENATE("□",I27,"×",J27,"×",K27) -> □6898×32×19600 | D27: 2 | E27: =IF(L27>0,(L27*J27/1000000000*7850),(I27*J27*K27/1000000000*7850)) -> 25224.284 | F27: =D27*E27 -> 50448.568 | I27: 6898 | J27: 32 | K27: 19600 | L27: 1.0041514e+08 | M27: =IF(L27>0,(L27*2/1000000),(I27*K27*2/1000000)) -> 200.83029 | N27: =D27*M27 -> 401.66058
B28: D3 | C28: =CONCATENATE("□",I28,"×",J28,"×",K28,"(平均)") -> □380×16×4239(平均) | D28: 14 | E28: =IF(L28>0,(L28*J28/1000000000*7850),(I28*J28*K28/1000000000*7850)) -> 202.31899 | F28: =D28*E28 -> 2832.4659 | I28: 380 | J28: 16 | K28: =(4836+3642)/2 -> 4239 | M28: =IF(L28>0,(L28*2/1000000),(I28*K28*2/1000000)) -> 3.22164 | N28: =D28*M28 -> 45.10296
B29: DJ1 | C29: =CONCATENATE("□",I29,"×",J29,"×",K29,"(总长)") -> □140×12×380836(总长) | D29: 1 | E29: =IF(L29>0,(L29*J29/1000000000*7850),(I29*J29*K29/1000000000*7850)) -> 5022.4652 | F29: =D29*E29 -> 5022.4652 | I29: 140 | J29: 12 | K29: =190418*2 -> 380836 | M29: =IF(L29>0,(L29*2/1000000),(I29*K29*2/1000000)) -> 106.63408 | N29: =D29*M29 -> 106.63408
A30: 腹板 | B30: F1 | C30: =CONCATENATE("□",I30,"×",J30,"×",K30) -> □3031×14×19600 | D30: 2 | E30: =IF(L30>0,(L30*J30/1000000000*7850),(I30*J30*K30/1000000000*7850)) -> 6528.8952 | F30: =D30*E30 -> 13057.79 | I30: 3031 | J30: 14 | K30: 19600 | M30: =IF(L30>0,(L30*2/1000000),(I30*K30*2/1000000)) -> 118.8152 | N30: =D30*M30 -> 237.6304
B31: F2 | C31: =CONCATENATE("□",I31,"×",J31,"×",K31) -> □2283×14×19600 | D31: 2 | E31: =IF(L31>0,(L31*J31/1000000000*7850),(I31*J31*K31/1000000000*7850)) -> 4917.6733 | F31: =D31*E31 -> 9835.3466 | I31: 2283 | J31: 14 | K31: 19600 | M31: =IF(L31>0,(L31*2/1000000),(I31*K31*2/1000000)) -> 89.4936 | N31: =D31*M31 -> 178.9872
B32: F3 | C32: =CONCATENATE("□",I32,"×",J32,"×",K32) -> □2179×20×8771 | D32: 2 | E32: =IF(L32>0,(L32*J32/1000000000*7850),(I32*J32*K32/1000000000*7850)) -> 2824.5273 | F32: =D32*E32 -> 5649.0545 | I32: 2179 | J32: 20 | K32: 8771 | L32: 17990620 | M32: =IF(L32>0,(L32*2/1000000),(I32*K32*2/1000000)) -> 35.981239 | N32: =D32*M32 -> 71.962478
B33: FJ1 | C33: =CONCATENATE("□",I33,"×",J33,"×",K33,"(总长)") -> □140×12×420800(总长) | D33: 1 | E33: =IF(L33>0,(L33*J33/1000000000*7850),(I33*J33*K33/1000000000*7850)) -> 5549.5104 | F33: =D33*E33 -> 5549.5104 | I33: 140 | J33: 12 | K33: =19600*9*2+8500*8 -> 420800 | M33: =IF(L33>0,(L33*2/1000000),(I33*K33*2/1000000)) -> 117.824 | N33: =D33*M33 -> 117.824
B34: FJ2 | C34: =CONCATENATE("□",I34,"×",J34,"×",K34) -> □184×16×450 | D34: 16 | E34: =IF(L34>0,(L34*J34/1000000000*7850),(I34*J34*K34/1000000000*7850)) -> 10.39968 | F34: =D34*E34 -> 166.39488 | I34: 184 | J34: 16 | K34: 450 | M34: =IF(L34>0,(L34*2/1000000),(I34*K34*2/1000000)) -> 0.1656 | N34: =D34*M34 -> 2.6496
B35: FJ3 | C35: =CONCATENATE("□",I35,"×",J35,"×",K35) -> □176×16×450 | D35: 12 | E35: =IF(L35>0,(L35*J35/1000000000*7850),(I35*J35*K35/1000000000*7850)) -> 9.94752 | F35: =D35*E35 -> 119.37024 | I35: 176 | J35: 16 | K35: 450 | M35: =IF(L35>0,(L35*2/1000000),(I35*K35*2/1000000)) -> 0.1584 | N35: =D35*M35 -> 1.9008
A36: 横隔板 | B36: HG1 | C36: =CONCATENATE("□",I36,"×",J36,"×",K36) -> □2384×12×19864 | D36: 7 | E36: =IF(L36>0,(L36*J36/1000000000*7850),(I36*J36*K36/1000000000*7850)) -> 4011.9568 | F36: =D36*E36 -> 28083.697 | I36: 2384 | J36: 12 | K36: 19864 | L36: =2*21294887.2264 -> 42589774 | M36: =IF(L36>0,(L36*2/1000000),(I36*K36*2/1000000)) -> 85.179549 | N36: =D36*M36 -> 596.25684
B37: HG2 | C37: =CONCATENATE("□",I37,"×",J37,"×",K37) -> □2241×28×3138 | D37: 2 | E37: =IF(L37>0,(L37*J37/1000000000*7850),(I37*J37*K37/1000000000*7850)) -> 1315.3228 | F37: =D37*E37 -> 2630.6456 | I37: 2241 | J37: 28 | K37: 3138 | L37: 5984180.1 | M37: =IF(L37>0,(L37*2/1000000),(I37*K37*2/1000000)) -> 11.96836 | N37: =D37*M37 -> 23.93672
B38: HG2a | C38: =CONCATENATE("□",I38,"×",J38,"×",K38) -> □2190×28×2889 | D38: 2 | E38: =IF(L38>0,(L38*J38/1000000000*7850),(I38*J38*K38/1000000000*7850)) -> 709.24329 | F38: =D38*E38 -> 1418.4866 | I38: 2190 | J38: 28 | K38: 2889 | L38: 3226766.6 | M38: =IF(L38>0,(L38*2/1000000),(I38*K38*2/1000000)) -> 6.4535331 | N38: =D38*M38 -> 12.907066
B39: HG3 | C39: =CONCATENATE("□",I39,"×",J39,"×",K39) -> □2241×12×6335 | D39: 2 | E39: =IF(L39>0,(L39*J39/1000000000*7850),(I39*J39*K39/1000000000*7850)) -> 961.93587 | F39: =D39*E39 -> 1923.8717 | I39: 2241 | J39: 12 | K39: 6335 | L39: =11217890.0408-1006256.5949 -> 10211633 | M39: =IF(L39>0,(L39*2/1000000),(I39*K39*2/1000000)) -> 20.423267 | N39: =D39*M39 -> 40.846534
B40: HG4 | C40: =CONCATENATE("□",I40,"×",J40,"×",K40) -> □2241×12×6860 | D40: 2 | E40: =IF(L40>0,(L40*J40/1000000000*7850),(I40*J40*K40/1000000000*7850)) -> 1018.3017 | F40: =D40*E40 -> 2036.6034 | I40: 2241 | J40: 12 | K40: 6860 | L40: 10809997 | M40: =IF(L40>0,(L40*2/1000000),(I40*K40*2/1000000)) -> 21.619993 | N40: =D40*M40 -> 43.239987
B41: HG5 | C41: =CONCATENATE("□",I41,"×",J41,"×",K41) -> □2241×28×3139 | D41: 2 | E41: =IF(L41>0,(L41*J41/1000000000*7850),(I41*J41*K41/1000000000*7850)) -> 1313.3798 | F41: =D41*E41 -> 2626.7597 | I41: 2241 | J41: 28 | K41: 3139 | L41: 5975340.4 | M41: =IF(L41>0,(L41*2/1000000),(I41*K41*2/1000000)) -> 11.950681 | N41: =D41*M41 -> 23.901362
B42: HG5a | C42: =CONCATENATE("□",I42,"×",J42,"×",K42) -> □2190×28×3937 | D42: 2 | E42: =IF(L42>0,(L42*J42/1000000000*7850),(I42*J42*K42/1000000000*7850)) -> 1197.1311 | F42: =D42*E42 -> 2394.2621 | I42: 2190 | J42: 28 | K42: 3937 | L42: 5446456.2 | M42: =IF(L42>0,(L42*2/1000000),(I42*K42*2/1000000)) -> 10.892912 | N42: =D42*M42 -> 21.785825
B43: HG6 | C43: =CONCATENATE("□",I43,"×",J43,"×",K43) -> □2179×12×4207 | D43: 2 | E43: =IF(L43>0,(L43*J43/1000000000*7850),(I43*J43*K43/1000000000*7850)) -> 692.57593 | F43: =D43*E43 -> 1385.1519 | I43: 2179 | J43: 12 | K43: 4207 | L43: =8358442.7236-1006256.5949 -> 7352186.1 | M43: =IF(L43>0,(L43*2/1000000),(I43*K43*2/1000000)) -> 14.704372 | N43: =D43*M43 -> 29.408745
B44: HG6a | C44: =CONCATENATE("□",I44,"×",J44,"×",K44) -> □2179×12×3681 | D44: 2 | E44: =IF(L44>0,(L44*J44/1000000000*7850),(I44*J44*K44/1000000000*7850)) -> 468.19878 | F44: =D44*E44 -> 936.39755 | I44: 2179 | J44: 12 | K44: 3681 | L44: =5618168.7453-647905.7293 -> 4970263 | M44: =IF(L44>0,(L44*2/1000000),(I44*K44*2/1000000)) -> 9.940526 | N44: =D44*M44 -> 19.881052
B45: HG7 | C45: =CONCATENATE("□",I45,"×",J45,"×",K45) -> □2179×12×4207 | D45: 2 | E45: =IF(L45>0,(L45*J45/1000000000*7850),(I45*J45*K45/1000000000*7850)) -> 692.57593 | F45: =D45*E45 -> 1385.1519 | I45: 2179 | J45: 12 | K45: 4207 | L45: =8358442.7236-1006256.5949 -> 7352186.1 | M45: =IF(L45>0,(L45*2/1000000),(I45*K45*2/1000000)) -> 14.704372 | N45: =D45*M45 -> 29.408745
B46: HG7a | C46: =CONCATENATE("□",I46,"×",J46,"×",K46) -> □2179×12×4206 | D46: 2 | E46: =IF(L46>0,(L46*J46/1000000000*7850),(I46*J46*K46/1000000000*7850)) -> 574.88865 | F46: =D46*E46 -> 1149.7773 | I46: 2179 | J46: 12 | K46: 4206 | L46: =6750757.6587-647905.7293 -> 6102851.9 | M46: =IF(L46>0,(L46*2/1000000),(I46*K46*2/1000000)) -> 12.205704 | N46: =D46*M46 -> 24.411408
B47: HG8 | C47: =CONCATENATE("□",I47,"×",J47,"×",K47) -> □2241×28×3139 | D47: 2 | E47: =IF(L47>0,(L47*J47/1000000000*7850),(I47*J47*K47/1000000000*7850)) -> 1313.1684 | F47: =D47*E47 -> 2626.3367 | I47: 2241 | J47: 28 | K47: 3139 | L47: 5974378.4 | M47: =IF(L47>0,(L47*2/1000000),(I47*K47*2/1000000)) -> 11.948757 | N47: =D47*M47 -> 23.897514
B48: HG8a | C48: =CONCATENATE("□",I48,"×",J48,"×",K48) -> □760×28×2179 | D48: 2 | E48: =IF(L48>0,(L48*J48/1000000000*7850),(I48*J48*K48/1000000000*7850)) -> 185.09473 | F48: =D48*E48 -> 370.18947 | I48: 760 | J48: 28 | K48: 2179 | L48: 842105.25 | M48: =IF(L48>0,(L48*2/1000000),(I48*K48*2/1000000)) -> 1.6842105 | N48: =D48*M48 -> 3.368421
B49: HG8b | C49: =CONCATENATE("□",I49,"×",J49,"×",K49) -> □2179×28×4730 | D49: 2 | E49: =IF(L49>0,(L49*J49/1000000000*7850),(I49*J49*K49/1000000000*7850)) -> 1606.0279 | F49: =D49*E49 -> 3212.0557 | I49: 2179 | J49: 28 | K49: 4730 | L49: 7306769.2 | M49: =IF(L49>0,(L49*2/1000000),(I49*K49*2/1000000)) -> 14.613538 | N49: =D49*M49 -> 29.227077
B50: HG9 | C50: =CONCATENATE("□",I50,"×",J50,"×",K50,"(平均)") -> □4316×12×1018(平均) | D50: 14 | E50: =IF(L50>0,(L50*J50/1000000000*7850),(I50*J50*K50/1000000000*7850)) -> 194.68071 | F50: =D50*E50 -> 2725.5299 | I50: 4316 | J50: 12 | K50: 1018 | L50: =(2530150.5372+1603197.7906)/2 -> 2066674.2 | M50: =IF(L50>0,(L50*2/1000000),(I50*K50*2/1000000)) -> 4.1333483 | N50: =D50*M50 -> 57.866877
A51: 横隔板加劲 | B51: HJ1 | C51: =CONCATENATE("□",I51,"×",J51,"×",K51) -> □140×12×19180 | D51: 14 | E51: =IF(L51>0,(L51*J51/1000000000*7850),(I51*J51*K51/1000000000*7850)) -> 252.94584 | F51: =D51*E51 -> 3541.2418 | I51: 140 | J51: 12 | K51: =9590*2 -> 19180 | M51: =IF(L51>0,(L51*2/1000000),(I51*K51*2/1000000)) -> 5.3704 | N51: =D51*M51 -> 75.1856
...

Sheet B2类梁段
B2: 参数 | C2: L1 | D2: L2 | E2: L3 | F2: L4
C3: mm | D3: mm | E3: mm | F3: mm
B4: HG2 | C4: 4820 | D4: 4073 | E4: 1085
B5: HG3 | C5: 4589 | D5: 3861 | E5: 1047
B6: HG4 | C6: 4358 | D6: 3649 | E6: 1022 | F6: 1059
B7: HG5 | C7: 4128 | D7: 3436 | E7: 996
B8: HG6 | C8: 3896 | D8: 3224 | E8: 970
B9: HG7 | C9: 3666 | D9: 3011 | E9: 945 | F9: 1058
A20: 位置 | B20: 编号 | C20: 规格(mm) | D20: 数量 | E20: 单件重(kg) | F20: 共重(kg) | I20: 长边 | J20: 厚度 | K20: 短边 | L20: 侧面S | M20: 涂装
A21: 顶板 | B21: T1 | C21: =CONCATENATE("□",I21,"×",J21,"×",K21) -> □19400×16×43348 | D21: 1 | E21: =IF(L21>0,(L21*J21/1000000000*7850),(I21*J21*K21/1000000000*7850)) -> 100999.33 | F21: =D21*E21 -> 100999.33 | I21: 19400 | J21: 16 | K21: =21674*2 -> 43348 | L21: 8.0413478e+08 | M21: =IF(L21>0,(L21*2/1000000),(I21*K21*2/1000000)) -> 1608.2696 | N21: =D21*M21 -> 1608.2696
B22: TJ1 | C22: =CONCATENATE("□",I22,"×",J22,"×",K22) -> □460×24×19480 | D22: 2 | E22: =IF(L22>0,(L22*J22/1000000000*7850),(I22*J22*K22/1000000000*7850)) -> 1688.2147 | F22: =D22*E22 -> 3376.4294 | I22: 460 | J22: 24 | K22: 19480 | M22: =IF(L22>0,(L22*2/1000000),(I22*K22*2/1000000)) -> 17.9216 | N22: =D22*M22 -> 35.8432
B23: TJ2 | C23: =CONCATENATE("□",I23,"×",J23,"×",K23,"(总长)") -> □140×12×46834(总长) | D23: 1 | E23: =IF(L23>0,(L23*J23/1000000000*7850),(I23*J23*K23/1000000000*7850)) -> 617.64679 | F23: =D23*E23 -> 617.64679 | I23: 140 | J23: 12 | K23: =23417*2 -> 46834 | M23: =IF(L23>0,(L23*2/1000000),(I23*K23*2/1000000)) -> 13.11352 | N23: =D23*M23 -> 13.11352
B24: TU1 | C24: =CONCATENATE("U",I24,"×",J24,"×",K24) -> U300×8×19400 | D24: 40 | E24: =L24*I24/1000000000*7850 -> 13.425314 | F24: =D24*E24 -> 537.01257 | I24: 300 | J24: 8 | K24: 19400 | L24: 5700.7704 | M24: =IF(L24>0,(L24*2/1000000),(I24*K24*2/1000000)) -> 0.011401541 | N24: =D24*M24 -> 0.45606163
A25: 底板 | B25: D1 | C25: =CONCATENATE("□",I25,"×",J25,"×",K25) -> □500×16×19518 | D25: 6 | E25: =IF(L25>0,(L25*J25/1000000000*7850),(I25*J25*K25/1000000000*7850)) -> 1225.7304 | F25: =D25*E25 -> 7354.3824 | I25: 500 | J25: 16 | K25: =9759*2 -> 19518 | M25: =IF(L25>0,(L25*2/1000000),(I25*K25*2/1000000)) -> 19.518 | N25: =D25*M25 -> 117.108
B26: D2 | C26: =CONCATENATE("□",I26,"×",J26,"×",K26) -> □6889×32×19400 | D26: 2 | E26: =IF(L26>0,(L26*J26/1000000000*7850),(I26*J26*K26/1000000000*7850)) -> 25634.614 | F26: =D26*E26 -> 51269.229 | I26: 6889 | J26: 32 | K26: 19400 | L26: 1.0204862e+08 | M26: =IF(L26>0,(L26*2/1000000),(I26*K26*2/1000000)) -> 204.09725 | N26: =D26*M26 -> 408.1945
B27: D3 | C27: =CONCATENATE("□",I27,"×",J27,"×",K27,"(平均)") -> □380×16×4243(平均) | D27: 12 | E27: =IF(L27>0,(L27*J27/1000000000*7850),(I27*J27*K27/1000000000*7850)) -> 202.5099 | F27: =D27*E27 -> 2430.1188 | I27: 380 | J27: 16 | K27: =(4820+3666)/2 -> 4243 | M27: =IF(L27>0,(L27*2/1000000),(I27*K27*2/1000000)) -> 3.22468 | N27: =D27*M27 -> 38.69616
B28: DJ1 | C28: =CONCATENATE("□",I28,"×",J28,"×",K28,"(总长)") -> □140×12×374290(总长) | D28: 1 | E28: =IF(L28>0,(L28*J28/1000000000*7850),(I28*J28*K28/1000000000*7850)) -> 4936.1365 | F28: =D28*E28 -> 4936.1365 | I28: 140 | J28: 12 | K28: =187145*2 -> 374290 | M28: =IF(L28>0,(L28*2/1000000),(I28*K28*2/1000000)) -> 104.8012 | N28: =D28*M28 -> 104.8012
A29: 腹板 | B29: F1 | C29: =CONCATENATE("□",I29,"×",J29,"×",K29) -> □3031×14×19400 | D29: 2 | E29: =IF(L29>0,(L29*J29/1000000000*7850),(I29*J29*K29/1000000000*7850)) -> 6414.6285 | F29: =D29*E29 -> 12829.257 | I29: 3031 | J29: 14 | K29: 19400 | L29: 58367867 | M29: =IF(L29>0,(L29*2/1000000),(I29*K29*2/1000000)) -> 116.73573 | N29: =D29*M29 -> 233.47147
B30: F2 | C30: =CONCATENATE("□",I30,"×",J30,"×",K30) -> □2283×14×19600 | D30: 2 | E30: =IF(L30>0,(L30*J30/1000000000*7850),(I30*J30*K30/1000000000*7850)) -> 4917.6733 | F30: =D30*E30 -> 9835.3466 | I30: 2283 | J30: 14 | K30: 19600 | M30: =IF(L30>0,(L30*2/1000000),(I30*K30*2/1000000)) -> 89.4936 | N30: =D30*M30 -> 178.9872
B31: F3 | C31: =CONCATENATE("□",I31,"×",J31,"×",K31) -> □2179×20×7400 | D31: 2 | E31: =IF(L31>0,(L31*J31/1000000000*7850),(I31*J31*K31/1000000000*7850)) -> 2824.5273 | F31: =D31*E31 -> 5649.0545 | I31: 2179 | J31: 20 | K31: 7400 | L31: 17990620 | M31: =IF(L31>0,(L31*2/1000000),(I31*K31*2/1000000)) -> 35.981239 | N31: =D31*M31 -> 71.962478
B32: FJ1 | C32: =CONCATENATE("□",I32,"×",J32,"×",K32,"(总长)") -> □140×12×398000(总长) | D32: 1 | E32: =IF(L32>0,(L32*J32/1000000000*7850),(I32*J32*K32/1000000000*7850)) -> 5248.824 | F32: =D32*E32 -> 5248.824 | I32: 140 | J32: 12 | K32: =19400*9*2+6100*8 -> 398000 | M32: =IF(L32>0,(L32*2/1000000),(I32*K32*2/1000000)) -> 111.44 | N32: =D32*M32 -> 111.44
B33: FJ2 | C33: =CONCATENATE("□",I33,"×",J33,"×",K33) -> □184×16×450 | D33: =4*4 -> 16 | E33: =IF(L33>0,(L33*J33/1000000000*7850),(I33*J33*K33/1000000000*7850)) -> 10.39968 | F33: =D33*E33 -> 166.39488 | I33: 184 | J33: 16 | K33: 450 | M33: =IF(L33>0,(L33*2/1000000),(I33*K33*2/1000000)) -> 0.1656 | N33: =D33*M33 -> 2.6496
B34: FJ3 | C34: =CONCATENATE("□",I34,"×",J34,"×",K34) -> □176×16×450 | D34: =4*2 -> 8 | E34: =IF(L34>0,(L34*J34/1000000000*7850),(I34*J34*K34/1000000000*7850)) -> 9.94752 | F34: =D34*E34 -> 79.58016 | I34: 176 | J34: 16 | K34: 450 | M34: =IF(L34>0,(L34*2/1000000),(I34*K34*2/1000000)) -> 0.1584 | N34: =D34*M34 -> 1.2672
A35: 横隔板 | B35: HG1 | C35: =CONCATENATE("□",I35,"×",J35,"×",K35) -> □2384×12×19864 | D35: 6 | E35: =IF(L35>0,(L35*J35/1000000000*7850),(I35*J35*K35/1000000000*7850)) -> 4011.9568 | F35: =D35*E35 -> 24071.741 | I35: 2384 | J35: 12 | K35: 19864 | L35: =2*21294887.2264 -> 42589774 | M35: =IF(L35>0,(L35*2/1000000),(I35*K35*2/1000000)) -> 85.179549 | N35: =D35*M35 -> 511.07729
B36: HG2 | C36: =CONCATENATE("□",I36,"×",J36,"×",K36) -> □2241×12×6335 | D36: 2 | E36: =IF(L36>0,(L36*J36/1000000000*7850),(I36*J36*K36/1000000000*7850)) -> 961.93587 | F36: =D36*E36 -> 1923.8717 | I36: 2241 | J36: 12 | K36: 6335 | L36: =11217890.0408-1006256.5949 -> 10211633 | M36: =IF(L36>0,(L36*2/1000000),(I36*K36*2/1000000)) -> 20.423267 | N36: =D36*M36 -> 40.846534
B37: HG3 | C37: =CONCATENATE("□",I37,"×",J37,"×",K37) -> □2241×12×6840 | D37: 2 | E37: =IF(L37>0,(L37*J37/1000000000*7850),(I37*J37*K37/1000000000*7850)) -> 1015.158 | F37: =D37*E37 -> 2030.3159 | I37: 2241 | J37: 12 | K37: 6840 | L37: 10776624 | M37: =IF(L37>0,(L37*2/1000000),(I37*K37*2/1000000)) -> 21.553247 | N37: =D37*M37 -> 43.106495
B38: HG4 | C38: =CONCATENATE("□",I38,"×",J38,"×",K38) -> □2241×28×6335 | D38: 2 | E38: =IF(L38>0,(L38*J38/1000000000*7850),(I38*J38*K38/1000000000*7850)) -> 2244.517 | F38: =D38*E38 -> 4489.0341 | I38: 2241 | J38: 28 | K38: 6335 | L38: =11217890.0408-1006256.5949 -> 10211633 | M38: =IF(L38>0,(L38*2/1000000),(I38*K38*2/1000000)) -> 20.423267 | N38: =D38*M38 -> 40.846534
B39: HG4a | C39: =CONCATENATE("□",I39,"×",J39,"×",K39) -> □2241×28×6860 | D39: 2 | E39: =IF(L39>0,(L39*J39/1000000000*7850),(I39*J39*K39/1000000000*7850)) -> 2376.0373 | F39: =D39*E39 -> 4752.0746 | I39: 2241 | J39: 28 | K39: 6860 | L39: 10809997 | M39: =IF(L39>0,(L39*2/1000000),(I39*K39*2/1000000)) -> 21.619993 | N39: =D39*M39 -> 43.239987
B40: HG5 | C40: =CONCATENATE("□",I40,"×",J40,"×",K40) -> □2241×12×3139 | D40: 2 | E40: =IF(L40>0,(L40*J40/1000000000*7850),(I40*J40*K40/1000000000*7850)) -> 562.87707 | F40: =D40*E40 -> 1125.7541 | I40: 2241 | J40: 12 | K40: 3139 | L40: 5975340.4 | M40: =IF(L40>0,(L40*2/1000000),(I40*K40*2/1000000)) -> 11.950681 | N40: =D40*M40 -> 23.901362
B41: HG6 | C41: =CONCATENATE("□",I41,"×",J41,"×",K41) -> □2190×12×3937 | D41: 2 | E41: =IF(L41>0,(L41*J41/1000000000*7850),(I41*J41*K41/1000000000*7850)) -> 513.05617 | F41: =D41*E41 -> 1026.1123 | I41: 2190 | J41: 12 | K41: 3937 | L41: 5446456.2 | M41: =IF(L41>0,(L41*2/1000000),(I41*K41*2/1000000)) -> 10.892912 | N41: =D41*M41 -> 21.785825
B42: HG6a | C42: =CONCATENATE("□",I42,"×",J42,"×",K42) -> □2179×12×4207 | D42: 2 | E42: =IF(L42>0,(L42*J42/1000000000*7850),(I42*J42*K42/1000000000*7850)) -> 692.57593 | F42: =D42*E42 -> 1385.1519 | I42: 2179 | J42: 12 | K42: 4207 | L42: =8358442.7236-1006256.5949 -> 7352186.1 | M42: =IF(L42>0,(L42*2/1000000),(I42*K42*2/1000000)) -> 14.704372 | N42: =D42*M42 -> 29.408745
B43: HG7 | C43: =CONCATENATE("□",I43,"×",J43,"×",K43) -> □2179×28×3681 | D43: 2 | E43: =IF(L43>0,(L43*J43/1000000000*7850),(I43*J43*K43/1000000000*7850)) -> 1092.4638 | F43: =D43*E43 -> 2184.9276 | I43: 2179 | J43: 28 | K43: 3681 | L43: =5618168.7453-647905.7293 -> 4970263 | M43: =IF(L43>0,(L43*2/1000000),(I43*K43*2/1000000)) -> 9.940526 | N43: =D43*M43 -> 19.881052
B44: HG7a | C44: =CONCATENATE("□",I44,"×",J44,"×",K44) -> □2179×28×4207 | D44: 2 | E44: =IF(L44>0,(L44*J44/1000000000*7850),(I44*J44*K44/1000000000*7850)) -> 1616.0105 | F44: =D44*E44 -> 3232.021 | I44: 2179 | J44: 28 | K44: 4207 | L44: =8358442.7236-1006256.5949 -> 7352186.1 | M44: =IF(L44>0,(L44*2/1000000),(I44*K44*2/1000000)) -> 14.704372 | N44: =D44*M44 -> 29.408745
B45: HG7b | C45: =CONCATENATE("□",I45,"×",J45,"×",K45) -> □2179×28×4206 | D45: 2 | E45: =IF(L45>0,(L45*J45/1000000000*7850),(I45*J45*K45/1000000000*7850)) -> 1341.4069 | F45: =D45*E45 -> 2682.8137 | I45: 2179 | J45: 28 | K45: 4206 | L45: =6750757.6587-647905.7293 -> 6102851.9 | M45: =IF(L45>0,(L45*2/1000000),(I45*K45*2/1000000)) -> 12.205704 | N45: =D45*M45 -> 24.411408
B46: HG8 | C46: =CONCATENATE("□",I46,"×",J46,"×",K46,"(平均)") -> □4243×12×1011(平均) | D46: 14 | E46: =IF(L46>0,(L46*J46/1000000000*7850),(I46*J46*K46/1000000000*7850)) -> 194.08543 | F46: =D46*E46 -> 2717.196 | I46: 4243 | J46: 12 | K46: 1011 | L46: =(1751017.0968+2369692.63)/2 -> 2060354.9 | M46: =IF(L46>0,(L46*2/1000000),(I46*K46*2/1000000)) -> 4.1207097 | N46: =D46*M46 -> 57.689936
A47: 横隔板加劲 | B47: HJ1 | C47: =CONCATENATE("□",I47,"×",J47,"×",K47) -> □140×12×19180 | D47: 12 | E47: =IF(L47>0,(L47*J47/1000000000*7850),(I47*J47*K47/1000000000*7850)) -> 252.94584 | F47: =D47*E47 -> 3035.3501 | I47: 140 | J47: 12 | K47: =9590*2 -> 19180 | M47: =IF(L47>0,(L47*2/1000000),(I47*K47*2/1000000)) -> 5.3704 | N47: =D47*M47 -> 64.4448
B48: HJ2 | C48: =CONCATENATE("□",I48,"×",J48,"×",K48) -> □180×12×1884 | D48: 24 | E48: =IF(L48>0,(L48*J48/1000000000*7850),(I48*J48*K48/1000000000*7850)) -> 31.945104 | F48: =D48*E48 -> 766.6825 | I48: 180 | J48: 12 | K48: 1884 | M48: =IF(L48>0,(L48*2/1000000),(I48*K48*2/1000000)) -> 0.67824 | N48: =D48*M48 -> 16.27776
B49: HJ3 | C49: =CONCATENATE("□",I49,"×",J49,"×",K49) -> □180×12×1857 | D49: 24 | E49: =IF(L49>0,(L49*J49/1000000000*7850),(I49*J49*K49/1000000000*7850)) -> 31.487292 | F49: =D49*E49 -> 755.69501 | I49: 180 | J49: 12 | K49: 1857 | M49: =IF(L49>0,(L49*2/1000000),(I49*K49*2/1000000)) -> 0.66852 | N49: =D49*M49 -> 16.04448
B50: HJ4 | C50: =CONCATENATE("□",I50,"×",J50,"×",K50) -> □180×12×1830 | D50: 24 | E50: =IF(L50>0,(L50*J50/1000000000*7850),(I50*J50*K50/1000000000*7850)) -> 31.02948 | F50: =D50*E50 -> 744.70752 | I50: 180 | J50: 12 | K50: 1830 | M50: =IF(L50>0,(L50*2/1000000),(I50*K50*2/1000000)) -> 0.6588 | N50: =D50*M50 -> 15.8112
B51: HJ5 | C51: =CONCATENATE("□",I51,"×",J51,"×",K51) -> □180×12×1803 | D51: 24 | E51: =IF(L51>0,(L51*J51/1000000000*7850),(I51*J51*K51/1000000000*7850)) -> 30.571668 | F51: =D51*E51 -> 733.72003 | I51: 180 | J51: 12 | K51: 1803 | M51: =IF(L51>0,(L51*2/1000000),(I51*K51*2/1000000)) -> 0.64908 | N51: =D51*M51 -> 15.57792
...

Sheet C1类梁段
A5: 位置 | B5: 编号 | C5: 规格(mm) | D5: 数量 | E5: 单件重(kg) | F5: 共重(kg) | I5: 长边 | J5: 厚度 | K5: 短边 | L5: 侧面S | M5: 涂装
A6: 顶板 | B6: T1 | C6: =CONCATENATE("□",I6,"×",J6,"×",K6) -> □19380×16×45500 | D6: 1 | E6: =IF(L6>0,(L6*J6/1000000000*7850),(I6*J6*K6/1000000000*7850)) -> 109178.01 | F6: =D6*E6 -> 109178.01 | I6: 19380 | J6: 16 | K6: 45500 | L6: 8.692517e+08 | M6: =IF(L6>0,(L6*2/1000000),(I6*K6*2/1000000)) -> 1738.5034 | N6: =D6*M6 -> 1738.5034
B7: TJ1 | C7: =CONCATENATE("□",I7,"×",J7,"×",K7) -> □460×24×19437 | D7: 2 | E7: =IF(L7>0,(L7*J7/1000000000*7850),(I7*J7*K7/1000000000*7850)) -> 1684.4882 | F7: =D7*E7 -> 3368.9763 | I7: 460 | J7: 24 | K7: 19437 | M7: =IF(L7>0,(L7*2/1000000),(I7*K7*2/1000000)) -> 17.88204 | N7: =D7*M7 -> 35.76408
B8: TJ2 | C8: =CONCATENATE("□",I8,"×",J8,"×",K8,"(总长)") -> □140×12×794500(总长) | D8: 1 | E8: =IF(L8>0,(L8*J8/1000000000*7850),(I8*J8*K8/1000000000*7850)) -> 10477.866 | F8: =D8*E8 -> 10477.866 | I8: 140 | J8: 12 | K8: =397250*2 -> 794500 | M8: =IF(L8>0,(L8*2/1000000),(I8*K8*2/1000000)) -> 222.46 | N8: =D8*M8 -> 222.46
B9: TU1 | C9: =CONCATENATE("U",I9,"×",J9,"×",K9) -> U300×8×19010 | D9: 40 | E9: =L9*I9/1000000000*7850 -> 13.425314 | F9: =D9*E9 -> 537.01257 | I9: 300 | J9: 8 | K9: 19010 | L9: 5700.7704 | M9: =IF(L9>0,(L9*2/1000000),(I9*K9*2/1000000)) -> 0.011401541 | N9: =D9*M9 -> 0.45606163
A10: 底板 | B10: D1 | C10: =CONCATENATE("□",I10,"×",J10,"×",K10) -> □500×16×19518 | D10: 3 | E10: =IF(L10>0,(L10*J10/1000000000*7850),(I10*J10*K10/1000000000*7850)) -> 1225.7304 | F10: =D10*E10 -> 3677.1912 | I10: 500 | J10: 16 | K10: =9759*2 -> 19518 | M10: =IF(L10>0,(L10*2/1000000),(I10*K10*2/1000000)) -> 19.518 | N10: =D10*M10 -> 58.554
B11: D2 | C11: =CONCATENATE("□",I11,"×",J11,"×",K11) -> □8813×16×19778 | D11: 1 | E11: =IF(L11>0,(L11*J11/1000000000*7850),(I11*J11*K11/1000000000*7850)) -> 21892.521 | F11: =D11*E11 -> 21892.521 | I11: 8813 | J11: 16 | K11: =9889*2 -> 19778 | M11: =IF(L11>0,(L11*2/1000000),(I11*K11*2/1000000)) -> 348.60703 | N11: =D11*M11 -> 348.60703
B12: D3 | C12: =CONCATENATE("□",I12,"×",J12,"×",K12) -> □8696×36×19780 | D12: 2 | E12: =IF(L12>0,(L12*J12/1000000000*7850),(I12*J12*K12/1000000000*7850)) -> 45355.047 | F12: =D12*E12 -> 90710.095 | I12: 8696 | J12: 36 | K12: 19780 | L12: 1.6049203e+08 | M12: =IF(L12>0,(L12*2/1000000),(I12*K12*2/1000000)) -> 320.98406 | N12: =D12*M12 -> 641.96812
B13: D4 | C13: =CONCATENATE("□",I13,"×",J13,"×",K13,"(平均)") -> □380×16×3021(平均) | D13: 14 | E13: =IF(L13>0,(L13*J13/1000000000*7850),(I13*J13*K13/1000000000*7850)) -> 144.18629 | F13: =D13*E13 -> 2018.608 | I13: 380 | J13: 16 | K13: =(2656+3386)/2 -> 3021 | M13: =IF(L13>0,(L13*2/1000000),(I13*K13*2/1000000)) -> 2.29596 | N13: =D13*M13 -> 32.14344
B14: D4a | C14: =CONCATENATE("□",I14,"×",J14,"×",K14) -> □246×16×2656 | D14: 2 | E14: =IF(L14>0,(L14*J14/1000000000*7850),(I14*J14*K14/1000000000*7850)) -> 82.064026 | F14: =D14*E14 -> 164.12805 | I14: 246 | J14: 16 | K14: 2656 | M14: =IF(L14>0,(L14*2/1000000),(I14*K14*2/1000000)) -> 1.306752 | N14: =D14*M14 -> 2.613504
B15: DJ1 | C15: =CONCATENATE("□",I15,"×",J15,"×",K15,"(总长)") -> □140×12×352038(总长) | D15: 1 | E15: =IF(L15>0,(L15*J15/1000000000*7850),(I15*J15*K15/1000000000*7850)) -> 4642.6771 | F15: =D15*E15 -> 4642.6771 | I15: 140 | J15: 12 | K15: =176019*2 -> 352038 | M15: =IF(L15>0,(L15*2/1000000),(I15*K15*2/1000000)) -> 98.57064 | N15: =D15*M15 -> 98.57064
B16: DJ2 | C16: =CONCATENATE("□",I16,"×",J16,"×",K16) -> □140×12×19878 | D16: 12 | E16: =IF(L16>0,(L16*J16/1000000000*7850),(I16*J16*K16/1000000000*7850)) -> 262.15106 | F16: =D16*E16 -> 3145.8128 | I16: 140 | J16: 12 | K16: =9939*2 -> 19878 | M16: =IF(L16>0,(L16*2/1000000),(I16*K16*2/1000000)) -> 5.56584 | N16: =D16*M16 -> 66.79008
A17: 腹板 | B17: F1 | C17: =CONCATENATE("□",I17,"×",J17,"×",K17) -> □3056×14×19749 | D17: 2 | E17: =IF(L17>0,(L17*J17/1000000000*7850),(I17*J17*K17/1000000000*7850)) -> 6615.7028 | F17: =D17*E17 -> 13231.406 | I17: 3056 | J17: 14 | K17: 19749 | L17: 60197478 | M17: =IF(L17>0,(L17*2/1000000),(I17*K17*2/1000000)) -> 120.39496 | N17: =D17*M17 -> 240.78991
B18: F2 | C18: =CONCATENATE("□",I18,"×",J18,"×",K18) -> □2285×14×19218 | D18: 2 | E18: =IF(L18>0,(L18*J18/1000000000*7850),(I18*J18*K18/1000000000*7850)) -> 4826.053 | F18: =D18*E18 -> 9652.106 | I18: 2285 | J18: 14 | K18: 19218 | M18: =IF(L18>0,(L18*2/1000000),(I18*K18*2/1000000)) -> 87.82626 | N18: =D18*M18 -> 175.65252
B19: F3 | C19: =CONCATENATE("□",I19,"×",J19,"×",K19) -> □2195×40×16283 | D19: 2 | E19: =IF(L19>0,(L19*J19/1000000000*7850),(I19*J19*K19/1000000000*7850)) -> 10733.962 | F19: =D19*E19 -> 21467.923 | I19: 2195 | J19: 40 | K19: 16283 | L19: 34184591 | M19: =IF(L19>0,(L19*2/1000000),(I19*K19*2/1000000)) -> 68.369182 | N19: =D19*M19 -> 136.73836
B20: F3a | C20: =CONCATENATE("□",I20,"×",J20,"×",K20) -> □2195×24×138 | D20: 2 | E20: =IF(L20>0,(L20*J20/1000000000*7850),(I20*J20*K20/1000000000*7850)) -> 57.068244 | F20: =D20*E20 -> 114.13649 | I20: 2195 | J20: 24 | K20: 138 | M20: =IF(L20>0,(L20*2/1000000),(I20*K20*2/1000000)) -> 0.60582 | N20: =D20*M20 -> 1.21164
B21: F4 | C21: =CONCATENATE("□",I21,"×",J21,"×",K21) -> □2187×40×18418 | D21: 2 | E21: =IF(L21>0,(L21*J21/1000000000*7850),(I21*J21*K21/1000000000*7850)) -> 12213.867 | F21: =D21*E21 -> 24427.734 | I21: 2187 | J21: 40 | K21: 18418 | L21: 38897666 | M21: =IF(L21>0,(L21*2/1000000),(I21*K21*2/1000000)) -> 77.795331 | N21: =D21*M21 -> 155.59066
B22: F4a | C22: =CONCATENATE("□",I22,"×",J22,"×",K22) -> □2187×24×138 | D22: 2 | E22: =IF(L22>0,(L22*J22/1000000000*7850),(I22*J22*K22/1000000000*7850)) -> 56.86025 | F22: =D22*E22 -> 113.7205 | I22: =I21 -> 2187 | J22: 24 | K22: 138 | M22: =IF(L22>0,(L22*2/1000000),(I22*K22*2/1000000)) -> 0.603612 | N22: =D22*M22 -> 1.207224
B23: F5 | C23: =CONCATENATE("□",I23,"×",J23,"×",K23) -> □2179×40×19683 | D23: 2 | E23: =IF(L23>0,(L23*J23/1000000000*7850),(I23*J23*K23/1000000000*7850)) -> 13467.227 | F23: =D23*E23 -> 26934.453 | I23: 2179 | J23: 40 | K23: 19683 | M23: =IF(L23>0,(L23*2/1000000),(I23*K23*2/1000000)) -> 85.778514 | N23: =D23*M23 -> 171.55703
B24: F5a | C24: =CONCATENATE("□",I24,"×",J24,"×",K24) -> □2179×24×138 | D24: 2 | E24: =IF(L24>0,(L24*J24/1000000000*7850),(I24*J24*K24/1000000000*7850)) -> 56.652257 | F24: =D24*E24 -> 113.30451 | I24: =I23 -> 2179 | J24: 24 | K24: 138 | M24: =IF(L24>0,(L24*2/1000000),(I24*K24*2/1000000)) -> 0.601404 | N24: =D24*M24 -> 1.202808
B25: F6 | C25: =CONCATENATE("□",I25,"×",J25,"×",K25,"(平均)") -> □2126×12×2353(平均) | D25: 16 | E25: =IF(L25>0,(L25*J25/1000000000*7850),(I25*J25*K25/1000000000*7850)) -> 398.08149 | F25: =D25*E25 -> 6369.3039 | I25: =(1764+2488)/2 -> 2126 | J25: 12 | K25: =(2326+2380)/2 -> 2353 | L25: =(3396121.3827+5055714.954)/2 -> 4225918.2 | M25: =IF(L25>0,(L25*2/1000000),(I25*K25*2/1000000)) -> 8.4518363 | N25: =D25*M25 -> 135.22938
B26: FJ1 | C26: =CONCATENATE("□",I26,"×",J26,"×",K26,"(总长)") -> □140×12×746703(总长) | D26: 1 | E26: =IF(L26>0,(L26*J26/1000000000*7850),(I26*J26*K26/1000000000*7850)) -> 9847.5192 | F26: =D26*E26 -> 9847.5192 | I26: 140 | J26: 12 | K26: =373351.5*2 -> 746703 | M26: =IF(L26>0,(L26*2/1000000),(I26*K26*2/1000000)) -> 209.07684 | N26: =D26*M26 -> 209.07684
B27: FJ2 | C27: =CONCATENATE("□",I27,"×",J27,"×",K27) -> □176×16×450 | D27: =4*4+2 -> 18 | E27: =IF(L27>0,(L27*J27/1000000000*7850),(I27*J27*K27/1000000000*7850)) -> 9.94752 | F27: =D27*E27 -> 179.05536 | I27: 176 | J27: 16 | K27: 450 | M27: =IF(L27>0,(L27*2/1000000),(I27*K27*2/1000000)) -> 0.1584 | N27: =D27*M27 -> 2.8512
B28: FJ3 | C28: =CONCATENATE("□",I28,"×",J28,"×",K28) -> □184×16×450 | D28: 12 | E28: =IF(L28>0,(L28*J28/1000000000*7850),(I28*J28*K28/1000000000*7850)) -> 10.39968 | F28: =D28*E28 -> 124.79616 | I28: 184 | J28: 16 | K28: 450 | M28: =IF(L28>0,(L28*2/1000000),(I28*K28*2/1000000)) -> 0.1656 | N28: =D28*M28 -> 1.9872
B29: FJ4 | C29: =CONCATENATE("□",I29,"×",J29,"×",K29,"(平均)") -> □100×10×1500(平均) | D29: =16*2 -> 32 | E29: =IF(L29>0,(L29*J29/1000000000*7850),(I29*J29*K29/1000000000*7850)) -> 11.775 | F29: =D29*E29 -> 376.8 | I29: 100 | J29: 10 | K29: =(1400+1600)/2 -> 1500 | M29: =IF(L29>0,(L29*2/1000000),(I29*K29*2/1000000)) -> 0.3 | N29: =D29*M29 -> 9.6
B30: FJ5 | C30: =CONCATENATE("□",I30,"×",J30,"×",K30) -> □100×10×1290 | D30: =16*2 -> 32 | E30: =IF(L30>0,(L30*J30/1000000000*7850),(I30*J30*K30/1000000000*7850)) -> 10.1265 | F30: =D30*E30 -> 324.048 | I30: 100 | J30: 10 | K30: 1290 | M30: =IF(L30>0,(L30*2/1000000),(I30*K30*2/1000000)) -> 0.258 | N30: =D30*M30 -> 8.256
A31: 横隔板 | B31: HG1 | C31: =CONCATENATE("□",I31,"×",J31,"×",K31) -> □2179×12×4177 | D31: 2 | E31: =IF(L31>0,(L31*J31/1000000000*7850),(I31*J31*K31/1000000000*7850)) -> 686.43671 | F31: =D31*E31 -> 1372.8734 | I31: 2179 | J31: 12 | K31: 4177 | L31: 7287013.9 | M31: =IF(L31>0,(L31*2/1000000),(I31*K31*2/1000000)) -> 14.574028 | N31: =D31*M31 -> 29.148056
B32: HG1a | C32: =CONCATENATE("□",I32,"×",J32,"×",K32) -> □788×12×2187 | D32: 2 | E32: =IF(L32>0,(L32*J32/1000000000*7850),(I32*J32*K32/1000000000*7850)) -> 133.1754 | F32: =D32*E32 -> 266.3508 | I32: 788 | J32: 12 | K32: 2187 | L32: 1413751.6 | M32: =IF(L32>0,(L32*2/1000000),(I32*K32*2/1000000)) -> 2.8275032 | N32: =D32*M32 -> 5.6550063
B33: HG1b | C33: =CONCATENATE("□",I33,"×",J33,"×",K33) -> □2187×12×4443 | D33: 2 | E33: =IF(L33>0,(L33*J33/1000000000*7850),(I33*J33*K33/1000000000*7850)) -> 627.85799 | F33: =D33*E33 -> 1255.716 | I33: 2187 | J33: 12 | K33: 4443 | L33: 6665159.2 | M33: =IF(L33>0,(L33*2/1000000),(I33*K33*2/1000000)) -> 13.330318 | N33: =D33*M33 -> 26.660637
B34: HG2 | C34: =CONCATENATE("□",I34,"×",J34,"×",K34) -> □2179×12×4177 | D34: 2 | E34: =IF(L34>0,(L34*J34/1000000000*7850),(I34*J34*K34/1000000000*7850)) -> 686.43671 | F34: =D34*E34 -> 1372.8734 | I34: 2179 | J34: 12 | K34: 4177 | L34: 7287013.9 | M34: =IF(L34>0,(L34*2/1000000),(I34*K34*2/1000000)) -> 14.574028 | N34: =D34*M34 -> 29.148056
B35: HG2a | C35: =CONCATENATE("□",I35,"×",J35,"×",K35) -> □788×12×2187 | D35: 2 | E35: =IF(L35>0,(L35*J35/1000000000*7850),(I35*J35*K35/1000000000*7850)) -> 133.1754 | F35: =D35*E35 -> 266.3508 | I35: 788 | J35: 12 | K35: 2187 | L35: 1413751.6 | M35: =IF(L35>0,(L35*2/1000000),(I35*K35*2/1000000)) -> 2.8275032 | N35: =D35*M35 -> 5.6550063
B36: HG2b | C36: =CONCATENATE("□",I36,"×",J36,"×",K36) -> □788×12×2195 | D36: 2 | E36: =IF(L36>0,(L36*J36/1000000000*7850),(I36*J36*K36/1000000000*7850)) -> 133.79308 | F36: =D36*E36 -> 267.58615 | I36: 788 | J36: 12 | K36: 2195 | L36: 1420308.7 | M36: =IF(L36>0,(L36*2/1000000),(I36*K36*2/1000000)) -> 2.8406173 | N36: =D36*M36 -> 5.6812347
B37: HG2c | C37: =CONCATENATE("□",I37,"×",J37,"×",K37) -> □2195×12×4141 | D37: 2 | E37: =IF(L37>0,(L37*J37/1000000000*7850),(I37*J37*K37/1000000000*7850)) -> 566.47543 | F37: =D37*E37 -> 1132.9509 | I37: 2195 | J37: 12 | K37: 4141 | L37: 6013539.5 | M37: =IF(L37>0,(L37*2/1000000),(I37*K37*2/1000000)) -> 12.027079 | N37: =D37*M37 -> 24.054158
B38: HG3 | C38: =CONCATENATE("□",I38,"×",J38,"×",K38) -> □2179×12×4177 | D38: 2 | E38: =IF(L38>0,(L38*J38/1000000000*7850),(I38*J38*K38/1000000000*7850)) -> 686.43671 | F38: =D38*E38 -> 1372.8734 | I38: 2179 | J38: 12 | K38: 4177 | L38: 7287013.9 | M38: =IF(L38>0,(L38*2/1000000),(I38*K38*2/1000000)) -> 14.574028 | N38: =D38*M38 -> 29.148056
B39: HG3a | C39: =CONCATENATE("□",I39,"×",J39,"×",K39) -> □788×12×2187 | D39: 2 | E39: =IF(L39>0,(L39*J39/1000000000*7850),(I39*J39*K39/1000000000*7850)) -> 133.1754 | F39: =D39*E39 -> 266.3508 | I39: 788 | J39: 12 | K39: 2187 | L39: 1413751.6 | M39: =IF(L39>0,(L39*2/1000000),(I39*K39*2/1000000)) -> 2.8275032 | N39: =D39*M39 -> 5.6550063
B40: HG3b | C40: =CONCATENATE("□",I40,"×",J40,"×",K40) -> □788×12×2195 | D40: 2 | E40: =IF(L40>0,(L40*J40/1000000000*7850),(I40*J40*K40/1000000000*7850)) -> 133.79308 | F40: =D40*E40 -> 267.58615 | I40: 788 | J40: 12 | K40: 2195 | L40: 1420308.7 | M40: =IF(L40>0,(L40*2/1000000),(I40*K40*2/1000000)) -> 2.8406173 | N40: =D40*M40 -> 5.6812347
B41: HG3c | C41: =CONCATENATE("□",I41,"×",J41,"×",K41) -> □2195×12×4666 | D41: 2 | E41: =IF(L41>0,(L41*J41/1000000000*7850),(I41*J41*K41/1000000000*7850)) -> 675.37581 | F41: =D41*E41 -> 1350.7516 | I41: 2195 | J41: 12 | K41: 4666 | L41: 7169594.6 | M41: =IF(L41>0,(L41*2/1000000),(I41*K41*2/1000000)) -> 14.339189 | N41: =D41*M41 -> 28.678378
B42: HG4 | C42: =CONCATENATE("□",I42,"×",J42,"×",K42) -> □2179×28×4177 | D42: 2 | E42: =IF(L42>0,(L42*J42/1000000000*7850),(I42*J42*K42/1000000000*7850)) -> 1606.0032 | F42: =D42*E42 -> 3212.0065 | I42: 2179 | J42: 28 | K42: 4177 | L42: 7306657.2 | M42: =IF(L42>0,(L42*2/1000000),(I42*K42*2/1000000)) -> 14.613314 | N42: =D42*M42 -> 29.226629
B43: HG4a | C43: =CONCATENATE("□",I43,"×",J43,"×",K43) -> □819×40×2187 | D43: 2 | E43: =IF(L43>0,(L43*J43/1000000000*7850),(I43*J43*K43/1000000000*7850)) -> 465.32316 | F43: =D43*E43 -> 930.64631 | I43: 819 | J43: 40 | K43: 2187 | L43: 1481920.9 | M43: =IF(L43>0,(L43*2/1000000),(I43*K43*2/1000000)) -> 2.9638418 | N43: =D43*M43 -> 5.9276835
... B57: HG7c | C57: =CONCATENATE("□",I57,"×",J57,"×",K57) -> □2196×28×5213 | D57: 2 | E57: =IF(L57>0,(L57*J57/1000000000*7850),(I57*J57*K57/1000000000*7850)) -> 1843.4331 | F57: =D57*E57 -> 3686.8662 | I57: 2196 | J57: 28 | K57: 5213 | L57: 8386865.9 | M57: =IF(L57>0,(L57*2/1000000),(I57*K57*2/1000000)) -> 16.773732 | N57: =D57*M57 -> 33.547464
...

Sheet C2类梁段
A5: 位置 | B5: 编号 | C5: 规格(mm) | D5: 数量 | E5: 单件重(kg) | F5: 共重(kg) | I5: 长边 | J5: 厚度 | K5: 短边 | L5: 侧面S | M5: 涂装
A6: 顶板 | B6: T1 | C6: =CONCATENATE("□",I6,"×",J6,"×",K6) -> □19380×16×45500 | D6: 1 | E6: =IF(L6>0,(L6*J6/1000000000*7850),(I6*J6*K6/1000000000*7850)) -> 108067.29 | F6: =D6*E6 -> 108067.29 | I6: 19380 | J6: 16 | K6: 45500 | L6: =430204171.5788*2 -> 8.6040834e+08 | M6: =IF(L6>0,(L6*2/1000000),(I6*K6*2/1000000)) -> 1720.8167 | N6: =D6*M6 -> 1720.8167
B7: TJ1 | C7: =CONCATENATE("□",I7,"×",J7,"×",K7) -> □460×24×19433 | D7: 2 | E7: =IF(L7>0,(L7*J7/1000000000*7850),(I7*J7*K7/1000000000*7850)) -> 1684.1415 | F7: =D7*E7 -> 3368.283 | I7: 460 | J7: 24 | K7: 19433 | M7: =IF(L7>0,(L7*2/1000000),(I7*K7*2/1000000)) -> 17.87836 | N7: =D7*M7 -> 35.75672
B8: TJ2 | C8: =CONCATENATE("□",I8,"×",J8,"×",K8,"(总长)") -> □140×12×740106(总长) | D8: 1 | E8: =IF(L8>0,(L8*J8/1000000000*7850),(I8*J8*K8/1000000000*7850)) -> 9760.5179 | F8: =D8*E8 -> 9760.5179 | I8: 140 | J8: 12 | K8: =370053*2 -> 740106 | M8: =IF(L8>0,(L8*2/1000000),(I8*K8*2/1000000)) -> 207.22968 | N8: =D8*M8 -> 207.22968
B9: TU1 | C9: =CONCATENATE("U",I9,"×",J9,"×",K9) -> U300×8×19010 | D9: 40 | E9: =L9*I9/1000000000*7850 -> 13.425314 | F9: =D9*E9 -> 537.01257 | I9: 300 | J9: 8 | K9: 19010 | L9: 5700.7704 | M9: =IF(L9>0,(L9*2/1000000),(I9*K9*2/1000000)) -> 0.011401541 | N9: =D9*M9 -> 0.45606163
A10: 底板 | B10: D1 | C10: =CONCATENATE("□",I10,"×",J10,"×",K10) -> □500×16×19518 | D10: 4 | E10: =IF(L10>0,(L10*J10/1000000000*7850),(I10*J10*K10/1000000000*7850)) -> 1225.7304 | F10: =D10*E10 -> 4902.9216 | I10: 500 | J10: 16 | K10: =9759*2 -> 19518 | M10: =IF(L10>0,(L10*2/1000000),(I10*K10*2/1000000)) -> 19.518 | N10: =D10*M10 -> 78.072
B11: D2 | C11: =CONCATENATE("□",I11,"×",J11,"×",K11) -> □8687×16×19778 | D11: 1 | E11: =IF(L11>0,(L11*J11/1000000000*7850),(I11*J11*K11/1000000000*7850)) -> 21892.8 | F11: =D11*E11 -> 21892.8 | I11: 8687 | J11: 16 | K11: =9889*2 -> 19778 | L11: 1.7430574e+08 | M11: =IF(L11>0,(L11*2/1000000),(I11*K11*2/1000000)) -> 348.61147 | N11: =D11*M11 -> 348.61147
B12: D3 | C12: =CONCATENATE("□",I12,"×",J12,"×",K12) -> □8696×36×18980 | D12: 2 | E12: =IF(L12>0,(L12*J12/1000000000*7850),(I12*J12*K12/1000000000*7850)) -> 43872.755 | F12: =D12*E12 -> 87745.509 | I12: 8696 | J12: 36 | K12: 18980 | L12: 1.5524683e+08 | M12: =IF(L12>0,(L12*2/1000000),(I12*K12*2/1000000)) -> 310.49366 | N12: =D12*M12 -> 620.98733
B13: D4 | C13: =CONCATENATE("□",I13,"×",J13,"×",K13,"(平均)") -> □380×16×3050(平均) | D13: 16 | E13: =IF(L13>0,(L13*J13/1000000000*7850),(I13*J13*K13/1000000000*7850)) -> 145.5704 | F13: =D13*E13 -> 2329.1264 | I13: 380 | J13: 16 | K13: =(2656+3444)/2 -> 3050 | M13: =IF(L13>0,(L13*2/1000000),(I13*K13*2/1000000)) -> 2.318 | N13: =D13*M13 -> 37.088
B14: D4a | C14: =CONCATENATE("□",I14,"×",J14,"×",K14) -> □246×16×2656 | D14: 2 | E14: =IF(L14>0,(L14*J14/1000000000*7850),(I14*J14*K14/1000000000*7850)) -> 82.064026 | F14: =D14*E14 -> 164.12805 | I14: 246 | J14: 16 | K14: 2656 | M14: =IF(L14>0,(L14*2/1000000),(I14*K14*2/1000000)) -> 1.306752 | N14: =D14*M14 -> 2.613504
B15: DJ1 | C15: =CONCATENATE("□",I15,"×",J15,"×",K15,"(总长)") -> □140×12×470644(总长) | D15: 1 | E15: =IF(L15>0,(L15*J15/1000000000*7850),(I15*J15*K15/1000000000*7850)) -> 6206.8531 | F15: =D15*E15 -> 6206.8531 | I15: 140 | J15: 12 | K15: =235322*2 -> 470644 | M15: =IF(L15>0,(L15*2/1000000),(I15*K15*2/1000000)) -> 131.78032 | N15: =D15*M15 -> 131.78032
B16: DJ2 | C16: =CONCATENATE("□",I16,"×",J16,"×",K16) -> □140×12×19878 | D16: 14 | E16: =IF(L16>0,(L16*J16/1000000000*7850),(I16*J16*K16/1000000000*7850)) -> 262.15106 | F16: =D16*E16 -> 3670.1149 | I16: 140 | J16: 12 | K16: =9939*2 -> 19878 | M16: =IF(L16>0,(L16*2/1000000),(I16*K16*2/1000000)) -> 5.56584 | N16: =D16*M16 -> 77.92176
A17: 腹板 | B17: F1 | C17: =CONCATENATE("□",I17,"×",J17,"×",K17) -> □3056×14×19332 | D17: 2 | E17: =IF(L17>0,(L17*J17/1000000000*7850),(I17*J17*K17/1000000000*7850)) -> 6492.7373 | F17: =D17*E17 -> 12985.475 | I17: 3056 | J17: 14 | K17: 19332 | M17: =IF(L17>0,(L17*2/1000000),(I17*K17*2/1000000)) -> 118.15718 | N17: =D17*M17 -> 236.31437
B18: F2 | C18: =CONCATENATE("□",I18,"×",J18,"×",K18) -> □2285×14×19018 | D18: 2 | E18: =IF(L18>0,(L18*J18/1000000000*7850),(I18*J18*K18/1000000000*7850)) -> 4775.8287 | F18: =D18*E18 -> 9551.6574 | I18: 2285 | J18: 14 | K18: 19018 | M18: =IF(L18>0,(L18*2/1000000),(I18*K18*2/1000000)) -> 86.91226 | N18: =D18*M18 -> 173.82452
B19: F3 | C19: =CONCATENATE("□",I19,"×",J19,"×",K19) -> □2196×40×15283 | D19: 2 | E19: =IF(L19>0,(L19*J19/1000000000*7850),(I19*J19*K19/1000000000*7850)) -> 10050.386 | F19: =D19*E19 -> 20100.772 | I19: 2196 | J19: 40 | K19: 15283 | L19: 32007599 | M19: =IF(L19>0,(L19*2/1000000),(I19*K19*2/1000000)) -> 64.015198 | N19: =D19*M19 -> 128.0304
B20: F3a | C20: =CONCATENATE("□",I20,"×",J20,"×",K20) -> □2196×24×138 | D20: 2 | E20: =IF(L20>0,(L20*J20/1000000000*7850),(I20*J20*K20/1000000000*7850)) -> 57.094243 | F20: =D20*E20 -> 114.18849 | I20: =I19 -> 2196 | J20: 24 | K20: 138 | M20: =IF(L20>0,(L20*2/1000000),(I20*K20*2/1000000)) -> 0.606096 | N20: =D20*M20 -> 1.212192
B21: F4 | C21: =CONCATENATE("□",I21,"×",J21,"×",K21) -> □2188×40×17218 | D21: 2 | E21: =IF(L21>0,(L21*J21/1000000000*7850),(I21*J21*K21/1000000000*7850)) -> 11346.292 | F21: =D21*E21 -> 22692.584 | I21: 2188 | J21: 40 | K21: 17218 | L21: 36134687 | M21: =IF(L21>0,(L21*2/1000000),(I21*K21*2/1000000)) -> 72.269374 | N21: =D21*M21 -> 144.53875
B22: F4a | C22: =CONCATENATE("□",I22,"×",J22,"×",K22) -> □2188×24×138 | D22: 2 | E22: =IF(L22>0,(L22*J22/1000000000*7850),(I22*J22*K22/1000000000*7850)) -> 56.88625 | F22: =D22*E22 -> 113.7725 | I22: =I21 -> 2188 | J22: 24 | K22: 138 | M22: =IF(L22>0,(L22*2/1000000),(I22*K22*2/1000000)) -> 0.603888 | N22: =D22*M22 -> 1.207776
B23: F5 | C23: =CONCATENATE("□",I23,"×",J23,"×",K23) -> □2178×40×18883 | D23: 2 | E23: =IF(L23>0,(L23*J23/1000000000*7850),(I23*J23*K23/1000000000*7850)) -> 12913.933 | F23: =D23*E23 -> 25827.865 | I23: 2178 | J23: 40 | K23: 18883 | M23: =IF(L23>0,(L23*2/1000000),(I23*K23*2/1000000)) -> 82.254348 | N23: =D23*M23 -> 164.5087
B24: F5a | C24: =CONCATENATE("□",I24,"×",J24,"×",K24) -> □2178×24×138 | D24: 2 | E24: =IF(L24>0,(L24*J24/1000000000*7850),(I24*J24*K24/1000000000*7850)) -> 56.626258 | F24: =D24*E24 -> 113.25252 | I24: =I23 -> 2178 | J24: 24 | K24: 138 | M24: =IF(L24>0,(L24*2/1000000),(I24*K24*2/1000000)) -> 0.601128 | N24: =D24*M24 -> 1.202256
B25: F6 | C25: =CONCATENATE("□",I25,"×",J25,"×",K25,"(平均)") -> □2031×12×2321(平均) | D25: 16 | E25: =IF(L25>0,(L25*J25/1000000000*7850),(I25*J25*K25/1000000000*7850)) -> 383.02146 | F25: =D25*E25 -> 6128.3434 | I25: 2031 | J25: 12 | K25: 2321 | L25: 4066045.3 | M25: =IF(L25>0,(L25*2/1000000),(I25*K25*2/1000000)) -> 8.1320905 | N25: =D25*M25 -> 130.11345
B26: FJ1 | C26: =CONCATENATE("□",I26,"×",J26,"×",K26,"(总长)") -> □140×12×715335(总长) | D26: 1 | E26: =IF(L26>0,(L26*J26/1000000000*7850),(I26*J26*K26/1000000000*7850)) -> 9433.838 | F26: =D26*E26 -> 9433.838 | I26: 140 | J26: 12 | K26: =357667.5*2 -> 715335 | M26: =IF(L26>0,(L26*2/1000000),(I26*K26*2/1000000)) -> 200.2938 | N26: =D26*M26 -> 200.2938
B27: FJ2 | C27: =CONCATENATE("□",I27,"×",J27,"×",K27) -> □176×16×450 | D27: 18 | E27: =IF(L27>0,(L27*J27/1000000000*7850),(I27*J27*K27/1000000000*7850)) -> 9.94752 | F27: =D27*E27 -> 179.05536 | I27: 176 | J27: 16 | K27: 450 | M27: =IF(L27>0,(L27*2/1000000),(I27*K27*2/1000000)) -> 0.1584 | N27: =D27*M27 -> 2.8512
B28: FJ3 | C28: =CONCATENATE("□",I28,"×",J28,"×",K28) -> □184×16×450 | D28: =4*4 -> 16 | E28: =IF(L28>0,(L28*J28/1000000000*7850),(I28*J28*K28/1000000000*7850)) -> 10.39968 | F28: =D28*E28 -> 166.39488 | I28: 184 | J28: 16 | K28: 450 | M28: =IF(L28>0,(L28*2/1000000),(I28*K28*2/1000000)) -> 0.1656 | N28: =D28*M28 -> 2.6496
B29: FJ4 | C29: =CONCATENATE("□",I29,"×",J29,"×",K29,"(平均)") -> □100×10×1310(平均) | D29: 32 | E29: =IF(L29>0,(L29*J29/1000000000*7850),(I29*J29*K29/1000000000*7850)) -> 10.2835 | F29: =D29*E29 -> 329.072 | I29: 100 | J29: 10 | K29: =(1020+1600)/2 -> 1310 | M29: =IF(L29>0,(L29*2/1000000),(I29*K29*2/1000000)) -> 0.262 | N29: =D29*M29 -> 8.384
B30: FJ5 | C30: =CONCATENATE("□",I30,"×",J30,"×",K30) -> □100×10×1290 | D30: 24 | E30: =IF(L30>0,(L30*J30/1000000000*7850),(I30*J30*K30/1000000000*7850)) -> 10.1265 | F30: =D30*E30 -> 243.036 | I30: 100 | J30: 10 | K30: 1290 | M30: =IF(L30>0,(L30*2/1000000),(I30*K30*2/1000000)) -> 0.258 | N30: =D30*M30 -> 6.192
A31: 横隔板 | B31: HG1 | C31: =CONCATENATE("□",I31,"×",J31,"×",K31) -> □2181×12×4320 | D31: 2 | E31: =IF(L31>0,(L31*J31/1000000000*7850),(I31*J31*K31/1000000000*7850)) -> 715.8742 | F31: =D31*E31 -> 1431.7484 | I31: 2181 | J31: 12 | K31: 4320 | L31: 7599513.8 | M31: =IF(L31>0,(L31*2/1000000),(I31*K31*2/1000000)) -> 15.199028 | N31: =D31*M31 -> 30.398055
B32: HG1a | C32: =CONCATENATE("□",I32,"×",J32,"×",K32) -> □2180×12×5002 | D32: 2 | E32: =IF(L32>0,(L32*J32/1000000000*7850),(I32*J32*K32/1000000000*7850)) -> 739.73563 | F32: =D32*E32 -> 1479.4713 | I32: 2180 | J32: 12 | K32: 5002 | L32: 7852819.8 | M32: =IF(L32>0,(L32*2/1000000),(I32*K32*2/1000000)) -> 15.70564 | N32: =D32*M32 -> 31.411279
B33: HG2 | C33: =CONCATENATE("□",I33,"×",J33,"×",K33) -> □2180×12×4320 | D33: 2 | E33: =IF(L33>0,(L33*J33/1000000000*7850),(I33*J33*K33/1000000000*7850)) -> 715.87024 | F33: =D33*E33 -> 1431.7405 | I33: 2180 | J33: 12 | K33: 4320 | L33: 7599471.8 | M33: =IF(L33>0,(L33*2/1000000),(I33*K33*2/1000000)) -> 15.198944 | N33: =D33*M33 -> 30.397887
B34: HG2a | C34: =CONCATENATE("□",I34,"×",J34,"×",K34) -> □806×12×2188 | D34: 2 | E34: =IF(L34>0,(L34*J34/1000000000*7850),(I34*J34*K34/1000000000*7850)) -> 136.82804 | F34: =D34*E34 -> 273.65608 | I34: 806 | J34: 12 | K34: 2188 | L34: 1452526.9 | M34: =IF(L34>0,(L34*2/1000000),(I34*K34*2/1000000)) -> 2.9050539 | N34: =D34*M34 -> 5.8101078
B35: HG2b | C35: =CONCATENATE("□",I35,"×",J35,"×",K35) -> □2189×12×4577 | D35: 2 | E35: =IF(L35>0,(L35*J35/1000000000*7850),(I35*J35*K35/1000000000*7850)) -> 655.22511 | F35: =D35*E35 -> 1310.4502 | I35: 2189 | J35: 12 | K35: 4577 | L35: 6955680.5 | M35: =IF(L35>0,(L35*2/1000000),(I35*K35*2/1000000)) -> 13.911361 | N35: =D35*M35 -> 27.822722
