Workbook

Sheet C1节段
A3: 位置 | B3: 编号 | C3: 规格(mm) | D3: 数量 | E3: 单件重(kg) | F3: 共重(kg) | G3: 全桥合计(共4段) | H3: 牌号 | J3: 短边 | K3: 厚度 | L3: 长边 | M3: 侧面S | N3: 涂装
A4: 副拱顶板 | B4: FT1 | C4: =CONCATENATE("□",J4,"×",K4,"×",L4) -> □1508×16×19266 | D4: 1 | E4: =IF(M4>0,(M4*K4/1000000000*7850),(J4*K4*L4/1000000000*7850)) -> 3649.0729 | F4: =D4*E4 -> 3649.0729 | G4: =F4*4 -> 14596.292 | H4: Q355D | J4: 1508 | K4: 16 | L4: 19266 | N4: =IF(M4>0,(M4*2/1000000),(J4*L4*2/1000000)) -> 58.106256 | O4: =N4*D4*4 -> 232.42502
B5: FT2 | C5: =CONCATENATE("□",J5,"×",K5,"×",L5) -> □2772×24×9596 | D5: 1 | E5: =IF(M5>0,(M5*K5/1000000000*7850),(J5*K5*L5/1000000000*7850)) -> 3868.9978 | F5: =D5*E5 -> 3868.9978 | G5: =F5*4 -> 15475.991 | J5: 2772 | K5: 24 | L5: 9596 | M5: 20536082 | N5: =IF(M5>0,(M5*2/1000000),(J5*L5*2/1000000)) -> 41.072164 | O5: =N5*D5*4 -> 164.28866
A6: 副拱底板 | B6: FD1 | C6: =CONCATENATE("□",J6,"×",K6,"×",L6) -> □1000×16×19197 | D6: 1 | E6: =IF(M6>0,(M6*K6/1000000000*7850),(J6*K6*L6/1000000000*7850)) -> 2411.1432 | F6: =D6*E6 -> 2411.1432 | G6: =F6*4 -> 9644.5728 | J6: 1000 | K6: 16 | L6: 19197 | N6: =IF(M6>0,(M6*2/1000000),(J6*L6*2/1000000)) -> 38.394 | O6: =N6*D6*4 -> 153.576
B7: FD2 | C7: =CONCATENATE("□",J7,"×",K7,"×",L7) -> □2256×24×9557 | D7: 1 | E7: =IF(M7>0,(M7*K7/1000000000*7850),(J7*K7*L7/1000000000*7850)) -> 2931.3719 | F7: =D7*E7 -> 2931.3719 | G7: =F7*4 -> 11725.488 | J7: 2256 | K7: 24 | L7: 9557 | M7: 15559299 | N7: =IF(M7>0,(M7*2/1000000),(J7*L7*2/1000000)) -> 31.118598 | O7: =N7*D7*4 -> 124.47439
A8: 副拱腹板 | B8: FF1 | C8: =CONCATENATE("□",J8,"×",K8,"×",L8) -> □1064×16×19266 | D8: 2 | E8: =IF(M8>0,(M8*K8/1000000000*7850),(J8*K8*L8/1000000000*7850)) -> 2574.6774 | F8: =D8*E8 -> 5149.3548 | G8: =F8*4 -> 20597.419 | J8: 1064 | K8: 16 | L8: =L4 -> 19266 | N8: =IF(M8>0,(M8*2/1000000),(J8*L8*2/1000000)) -> 40.998048 | O8: =N8*D8*4 -> 327.98438
B9: FF2 | C9: =CONCATENATE("□",J9,"×",K9,"×",L9) -> □1000×20×2339 | D9: 2 | E9: =IF(M9>0,(M9*K9/1000000000*7850),(J9*K9*L9/1000000000*7850)) -> 305.18623 | F9: =D9*E9 -> 610.37247 | G9: =F9*4 -> 2441.4899 | J9: 1000 | K9: 20 | L9: 2339 | M9: 1943861.4 | N9: =IF(M9>0,(M9*2/1000000),(J9*L9*2/1000000)) -> 3.8877227 | O9: =N9*D9*4 -> 31.101782
B10: FF3 | C10: =CONCATENATE("□",J10,"×",K10,"×",L10) -> □1081×24×9577 | D10: 2 | E10: =IF(M10>0,(M10*K10/1000000000*7850),(J10*K10*L10/1000000000*7850)) -> 1935.0933 | F10: =D10*E10 -> 3870.1867 | G10: =F10*4 -> 15480.747 | J10: 1081 | K10: 24 | L10: 9577 | M10: 10271196 | N10: =IF(M10>0,(M10*2/1000000),(J10*L10*2/1000000)) -> 20.542392 | O10: =N10*D10*4 -> 164.33914
B11: FJ1 | C11: =CONCATENATE("□",J11,"×",K11,"×",L11) -> □1657×12×120 | D11: 2 | E11: =IF(M11>0,(M11*K11/1000000000*7850),(J11*K11*L11/1000000000*7850)) -> 18.730728 | F11: =D11*E11 -> 37.461456 | G11: =F11*4 -> 149.84582 | J11: 1657 | K11: 12 | L11: 120 | N11: =IF(M11>0,(M11*2/1000000),(J11*L11*2/1000000)) -> 0.39768 | O11: =N11*D11*4 -> 3.18144
B12: FJ2 | C12: =CONCATENATE("□",J12,"×",K12,"×",L12) -> □1457×12×120 | D12: 2 | E12: =IF(M12>0,(M12*K12/1000000000*7850),(J12*K12*L12/1000000000*7850)) -> 16.469928 | F12: =D12*E12 -> 32.939856 | G12: =F12*4 -> 131.75942 | J12: 1457 | K12: 12 | L12: 120 | N12: =IF(M12>0,(M12*2/1000000),(J12*L12*2/1000000)) -> 0.34968 | O12: =N12*D12*4 -> 2.79744
A13: 副拱横隔 | B13: HG1 | C13: =CONCATENATE("□",J13,"×",K13,"×",L13) -> □1000×12×1500 | D13: 6 | E13: =IF(M13>0,(M13*K13/1000000000*7850),(J13*K13*L13/1000000000*7850)) -> 89.037229 | F13: =D13*E13 -> 534.22337 | G13: =F13*4 -> 2136.8935 | J13: 1000 | K13: 12 | L13: 1500 | M13: 945193.51 | N13: =IF(M13>0,(M13*2/1000000),(J13*L13*2/1000000)) -> 1.890387 | O13: =N13*D13*4 -> 45.369289
B14: HG1a | C14: =CONCATENATE("□",J14,"×",K14,"×",L14,"(平均)") -> □1000×12×2300(平均) | D14: 3 | E14: =IF(M14>0,(M14*K14/1000000000*7850),(J14*K14*L14/1000000000*7850)) -> 142.78726 | F14: =D14*E14 -> 428.36178 | G14: =F14*4 -> 1713.4471 | J14: 1000 | K14: 12 | L14: =(1836+2764)/2 -> 2300 | M14: 1515788.3 | N14: =IF(M14>0,(M14*2/1000000),(J14*L14*2/1000000)) -> 3.0315767 | O14: =N14*D14*4 -> 36.37892
B15: HG2 | C15: =CONCATENATE("□",J15,"×",K15,"×",L15) -> □1000×16×1500 | D15: 2 | E15: =IF(M15>0,(M15*K15/1000000000*7850),(J15*K15*L15/1000000000*7850)) -> 127.00063 | F15: =D15*E15 -> 254.00127 | G15: =F15*4 -> 1016.0051 | J15: 1000 | K15: 16 | L15: 1500 | M15: 1011151.5 | N15: =IF(M15>0,(M15*2/1000000),(J15*L15*2/1000000)) -> 2.0223031 | O15: =N15*D15*4 -> 16.178425
B16: HG3 | C16: =CONCATENATE("□",J16,"×",K16,"×",L16) -> □509×16×1000 | D16: 2 | E16: =IF(M16>0,(M16*K16/1000000000*7850),(J16*K16*L16/1000000000*7850)) -> 47.747035 | F16: =D16*E16 -> 95.494069 | G16: =F16*4 -> 381.97628 | J16: 509 | K16: 16 | L16: 1000 | M16: 380151.55 | N16: =IF(M16>0,(M16*2/1000000),(J16*L16*2/1000000)) -> 0.7603031 | O16: =N16*D16*4 -> 6.0824248
B17: HG3a | C17: =CONCATENATE("□",J17,"×",K17,"×",L17) -> □442×16×500 | D17: 1 | E17: =IF(M17>0,(M17*K17/1000000000*7850),(J17*K17*L17/1000000000*7850)) -> 27.274235 | F17: =D17*E17 -> 27.274235 | G17: =F17*4 -> 109.09694 | J17: 442 | K17: 16 | L17: 500 | M17: 217151.55 | N17: =IF(M17>0,(M17*2/1000000),(J17*L17*2/1000000)) -> 0.4343031 | O17: =N17*D17*4 -> 1.7372124
B18: HJ1 | C18: =CONCATENATE("□",J18,"×",K18,"×",L18) -> □110×10×1719 | D18: 9 | E18: =IF(M18>0,(M18*K18/1000000000*7850),(J18*K18*L18/1000000000*7850)) -> 14.843565 | F18: =D18*E18 -> 133.59208 | G18: =F18*4 -> 534.36834 | J18: 110 | K18: 10 | L18: 1719 | N18: =IF(M18>0,(M18*2/1000000),(J18*L18*2/1000000)) -> 0.37818 | O18: =N18*D18*4 -> 13.61448
B19: HJ2 | C19: =CONCATENATE("□",J19,"×",K19,"×",L19) -> □120×12×442 | D19: 3 | E19: =IF(M19>0,(M19*K19/1000000000*7850),(J19*K19*L19/1000000000*7850)) -> 4.996368 | F19: =D19*E19 -> 14.989104 | G19: =F19*4 -> 59.956416 | J19: 120 | K19: 12 | L19: 442 | N19: =IF(M19>0,(M19*2/1000000),(J19*L19*2/1000000)) -> 0.10608 | O19: =N19*D19*4 -> 1.27296
A20: 副拱加劲 | B20: J1 | C20: =CONCATENATE("□",J20,"×",K20,"×",L20,"(总长)") -> □140×12×258586(总长) | D20: 1 | E20: =IF(M20>0,(M20*K20/1000000000*7850),(J20*K20*L20/1000000000*7850)) -> 3410.2322 | F20: =D20*E20 -> 3410.2322 | G20: =F20*4 -> 13640.929 | J20: 140 | K20: 12 | L20: =(19266+9597+9558+19197+28808*2)*2+(7044+7015)*2 -> 258586 | N20: =IF(M20>0,(M20*2/1000000),(J20*L20*2/1000000)) -> 72.40408 | O20: =N20*D20*4 -> 289.61632
A21: 连杆顶板 | B21: LT1 | C21: =CONCATENATE("□",J21,"×",K21,"×",L21) -> □450×32×4518 | D21: 1 | E21: =IF(M21>0,(M21*K21/1000000000*7850),(J21*K21*L21/1000000000*7850)) -> 510.71472 | F21: =D21*E21 -> 510.71472 | G21: =F21*4 -> 2042.8589 | J21: 450 | K21: 32 | L21: 4518 | N21: =IF(M21>0,(M21*2/1000000),(J21*L21*2/1000000)) -> 4.0662 | O21: =N21*D21*4 -> 16.2648
A22: 连杆底板 | B22: LD1 | C22: =CONCATENATE("□",J22,"×",K22,"×",L22) -> □450×32×5529 | D22: 1 | E22: =IF(M22>0,(M22*K22/1000000000*7850),(J22*K22*L22/1000000000*7850)) -> 624.99816 | F22: =D22*E22 -> 624.99816 | G22: =F22*4 -> 2499.9926 | J22: 450 | K22: 32 | L22: 5529 | N22: =IF(M22>0,(M22*2/1000000),(J22*L22*2/1000000)) -> 4.9761 | O22: =N22*D22*4 -> 19.9044
A23: 连杆腹板 | B23: LF1 | C23: =CONCATENATE("□",J23,"×",K23,"×",L23) -> □724×32×5634 | D23: 2 | E23: =IF(M23>0,(M23*K23/1000000000*7850),(J23*K23*L23/1000000000*7850)) -> 913.71658 | F23: =D23*E23 -> 1827.4332 | G23: =F23*4 -> 7309.7326 | J23: 724 | K23: 32 | L23: 5634 | M23: 3637406.8 | N23: =IF(M23>0,(M23*2/1000000),(J23*L23*2/1000000)) -> 7.2748135 | O23: =N23*D23*4 -> 58.198508
B24: LF2 | C24: =CONCATENATE("□",J24,"×",K24,"×",L24) -> □884×32×884 | D24: 2 | E24: =IF(M24>0,(M24*K24/1000000000*7850),(J24*K24*L24/1000000000*7850)) -> 37.253122 | F24: =D24*E24 -> 74.506244 | G24: =F24*4 -> 298.02498 | J24: 884 | K24: 32 | L24: 884 | M24: 148300.64 | N24: =IF(M24>0,(M24*2/1000000),(J24*L24*2/1000000)) -> 0.29660129 | O24: =N24*D24*4 -> 2.3728103
A25: 连杆横隔 | B25: LG1 | C25: =CONCATENATE("□",J25,"×",K25,"×",L25) -> □450×12×600 | D25: 3 | E25: =IF(M25>0,(M25*K25/1000000000*7850),(J25*K25*L25/1000000000*7850)) -> 12.692096 | F25: =D25*E25 -> 38.076287 | G25: =F25*4 -> 152.30515 | J25: 450 | K25: 12 | L25: 600 | M25: 134735.62 | N25: =IF(M25>0,(M25*2/1000000),(J25*L25*2/1000000)) -> 0.26947124 | O25: =N25*D25*4 -> 3.2336549
B26: LG2 | C26: =CONCATENATE("□",J26,"×",K26,"×",L26) -> □390×12×440 | D26: 3 | E26: =IF(M26>0,(M26*K26/1000000000*7850),(J26*K26*L26/1000000000*7850)) -> 16.16472 | F26: =D26*E26 -> 48.49416 | G26: =F26*4 -> 193.97664 | J26: 390 | K26: 12 | L26: 440 | N26: =IF(M26>0,(M26*2/1000000),(J26*L26*2/1000000)) -> 0.3432 | O26: =N26*D26*4 -> 4.1184
A27: 转轴 | B27: A1 | C27: =CONCATENATE("□",J27,"×",K27,"×",L27) -> □724×282×1162 | D27: 2 | E27: =(785043.4338*282-31415.9265*140-531643.4338*142-724*320*80)/1000000000*7850 -> 965.20657 | F27: =D27*E27 -> 1930.4131 | G27: =F27*4 -> 7721.6526 | H27: 30Mn | J27: 724 | K27: 282 | L27: 1162 | N27: =IF(M27>0,(M27*2/1000000),(J27*L27*2/1000000)) -> 1.682576 | O27: =N27*D27*4 -> 13.460608
B28: A2 | C28: =CONCATENATE("□",J28,"×",K28,"×",L28) -> □875×40×2516 | D28: 2 | E28: =IF(M28>0,(M28*K28/1000000000*7850),(J28*K28*L28/1000000000*7850)) -> 336.423 | F28: =D28*E28 -> 672.846 | G28: =F28*4 -> 2691.384 | H28: S355N | J28: 875 | K28: 40 | L28: 2516 | M28: 1071410.8 | N28: =IF(M28>0,(M28*2/1000000),(J28*L28*2/1000000)) -> 2.1428217 | O28: =N28*D28*4 -> 17.142573
B29: A3 | C29: =CONCATENATE("□",J29,"×",K29,"×",L29) -> □600×50×600 | D29: 4 | E29: =IF(M29>0,(M29*K29/1000000000*7850),(J29*K29*L29/1000000000*7850)) -> 98.646009 | F29: =D29*E29 -> 394.58404 | G29: =F29*4 -> 1578.3361 | J29: 600 | K29: 50 | L29: 600 | M29: 251327.41 | N29: =IF(M29>0,(M29*2/1000000),(J29*L29*2/1000000)) -> 0.50265482 | O29: =N29*D29*4 -> 8.0424772
B30: A4 | C30: =CONCATENATE("□",J30,"×",K30,"×",L30) -> □150×12×150 | D30: 4 | E30: =IF(M30>0,(M30*K30/1000000000*7850),(J30*K30*L30/1000000000*7850)) -> 6.6586056 | F30: =D30*E30 -> 26.634423 | G30: =F30*4 -> 106.53769 | H30: Q355D | J30: 150 | K30: 12 | L30: 150 | M30: 70685.835 | N30: =IF(M30>0,(M30*2/1000000),(J30*L30*2/1000000)) -> 0.14137167 | O30: =N30*D30*4 -> 2.2619467
B31: A5 | C31: =CONCATENATE("D",J31,"×",K31) -> D200×280 | D31: 2 | E31: =0.0314159265*0.28*7850 -> 69.052206 | F31: =D31*E31 -> 138.10441 | G31: =F31*4 -> 552.41765 | H31: 40Cr | J31: 200 | K31: 280 | N31: =PI()*(J31/2)^2/1000000 -> 0.031415927 | O31: =N31*D31*4*2 -> 0.50265482
B32: M30螺栓 | C32: M30×70 GB/T 70.1 10.9 | D32: 4 | E32: - | F32: - | G32: =D32*4 -> 16
B33: 合计（kg） | F33: =SUM(F4:F31) -> 33745.874 | G33: =F33*4 -> 134983.5
B34: 焊缝1.5%（kg） | F34: =F33*0.015 -> 506.18811 | G34: =F34*4 -> 2024.7524
B35: 总计（kg） | F35: =F33+F34 -> 34252.062 | G35: =F35*4 -> 137008.25
A43: Q355D | B43: 10 | C43: =SUMIF($K$4:$K$26,B43,$G$4:$G$26) -> 534.36834
B44: 12 | C44: =SUMIF($K$4:$K$26,B44,$G$4:$G$26)+G30 -> 18285.65
B45: 16 | C45: =SUMIF($K$4:$K$26,B45,$G$4:$G$26) -> 46345.362
B46: 20 | C46: =SUMIF($K$4:$K$26,B46,$G$4:$G$26) -> 2441.4899
B47: 24 | C47: =SUMIF($K$4:$K$26,B47,$G$4:$G$26) -> 42682.226
B48: 32 | C48: =SUMIF($K$4:$K$26,B48,$G$4:$G$26) -> 12150.609
B49: 合计 | C49: =SUM(C43:C48) -> 122439.71
...

Sheet C2节段
A3: 位置 | B3: 编号 | C3: 规格(mm) | D3: 数量 | E3: 单件重(kg) | F3: 共重(kg) | G3: 全桥合计(共4段) | H3: 牌号 | J3: 短边 | K3: 厚度 | L3: 长边 | M3: 侧面S | N3: 涂装
A4: 副拱顶板 | B4: FT1 | C4: =CONCATENATE("□",J4,"×",K4,"×",L4) -> □1508×16×24221 | D4: 1 | E4: =IF(M4>0,(M4*K4/1000000000*7850),(J4*K4*L4/1000000000*7850)) -> 4587.5737 | F4: =D4*E4 -> 4587.5737 | G4: =F4*4 -> 18350.295 | H4: Q355D | J4: 1508 | K4: 16 | L4: 24221 | N4: =IF(M4>0,(M4*2/1000000),(J4*L4*2/1000000)) -> 73.050536 | O4: =N4*D4*4 -> 292.20214
A5: 副拱底板 | B5: FD1 | C5: =CONCATENATE("□",J5,"×",K5,"×",L5) -> □1000×16×24137 | D5: 1 | E5: =IF(M5>0,(M5*K5/1000000000*7850),(J5*K5*L5/1000000000*7850)) -> 3031.6072 | F5: =D5*E5 -> 3031.6072 | G5: =F5*4 -> 12126.429 | J5: 1000 | K5: 16 | L5: 24137 | N5: =IF(M5>0,(M5*2/1000000),(J5*L5*2/1000000)) -> 48.274 | O5: =N5*D5*4 -> 193.096
A6: 副拱腹板 | B6: FF1 | C6: =CONCATENATE("□",J6,"×",K6,"×",L6) -> □1064×16×24221 | D6: 2 | E6: =IF(M6>0,(M6*K6/1000000000*7850),(J6*K6*L6/1000000000*7850)) -> 3236.8557 | F6: =D6*E6 -> 6473.7114 | G6: =F6*4 -> 25894.845 | J6: 1064 | K6: 16 | L6: =L4 -> 24221 | N6: =IF(M6>0,(M6*2/1000000),(J6*L6*2/1000000)) -> 51.542288 | O6: =N6*D6*4 -> 412.3383
B7: FF2 | C7: =CONCATENATE("□",J7,"×",K7,"×",L7) -> □800×20×953 | D7: 2 | E7: =IF(M7>0,(M7*K7/1000000000*7850),(J7*K7*L7/1000000000*7850)) -> 242.48698 | F7: =D7*E7 -> 484.97396 | G7: =F7*4 -> 1939.8958 | J7: 800 | K7: 20 | L7: 953 | M7: 1544503.1 | N7: =IF(M7>0,(M7*2/1000000),(J7*L7*2/1000000)) -> 3.0890061 | O7: =N7*D7*4 -> 24.712049
B8: FJ1 | C8: =CONCATENATE("□",J8,"×",K8,"×",L8) -> □1657×12×120 | D8: 2 | E8: =IF(M8>0,(M8*K8/1000000000*7850),(J8*K8*L8/1000000000*7850)) -> 18.730728 | F8: =D8*E8 -> 37.461456 | G8: =F8*4 -> 149.84582 | J8: 1657 | K8: 12 | L8: 120 | N8: =IF(M8>0,(M8*2/1000000),(J8*L8*2/1000000)) -> 0.39768 | O8: =N8*D8*4 -> 3.18144
B9: FJ2 | C9: =CONCATENATE("□",J9,"×",K9,"×",L9) -> □1457×12×120 | D9: 2 | E9: =IF(M9>0,(M9*K9/1000000000*7850),(J9*K9*L9/1000000000*7850)) -> 16.469928 | F9: =D9*E9 -> 32.939856 | G9: =F9*4 -> 131.75942 | J9: 1457 | K9: 12 | L9: 120 | N9: =IF(M9>0,(M9*2/1000000),(J9*L9*2/1000000)) -> 0.34968 | O9: =N9*D9*4 -> 2.79744
A10: 副拱横隔 | B10: HG1 | C10: =CONCATENATE("□",J10,"×",K10,"×",L10) -> □1000×12×1500 | D10: 8 | E10: =IF(M10>0,(M10*K10/1000000000*7850),(J10*K10*L10/1000000000*7850)) -> 89.037229 | F10: =D10*E10 -> 712.29783 | G10: =F10*4 -> 2849.1913 | J10: 1000 | K10: 12 | L10: 1500 | M10: 945193.51 | N10: =IF(M10>0,(M10*2/1000000),(J10*L10*2/1000000)) -> 1.890387 | O10: =N10*D10*4 -> 60.492385
B11: HG2 | C11: =CONCATENATE("□",J11,"×",K11,"×",L11) -> □1000×16×1500 | D11: 2 | E11: =IF(M11>0,(M11*K11/1000000000*7850),(J11*K11*L11/1000000000*7850)) -> 127.00063 | F11: =D11*E11 -> 254.00127 | G11: =F11*4 -> 1016.0051 | J11: 1000 | K11: 16 | L11: 1500 | M11: 1011151.5 | N11: =IF(M11>0,(M11*2/1000000),(J11*L11*2/1000000)) -> 2.0223031 | O11: =N11*D11*4 -> 16.178425
B12: HG3 | C12: =CONCATENATE("□",J12,"×",K12,"×",L12) -> □509×16×1000 | D12: 2 | E12: =IF(M12>0,(M12*K12/1000000000*7850),(J12*K12*L12/1000000000*7850)) -> 47.747035 | F12: =D12*E12 -> 95.494069 | G12: =F12*4 -> 381.97628 | J12: 509 | K12: 16 | L12: 1000 | M12: 380151.55 | N12: =IF(M12>0,(M12*2/1000000),(J12*L12*2/1000000)) -> 0.7603031 | O12: =N12*D12*4 -> 6.0824248
B13: HG3a | C13: =CONCATENATE("□",J13,"×",K13,"×",L13) -> □442×16×500 | D13: 1 | E13: =IF(M13>0,(M13*K13/1000000000*7850),(J13*K13*L13/1000000000*7850)) -> 27.274235 | F13: =D13*E13 -> 27.274235 | G13: =F13*4 -> 109.09694 | J13: 442 | K13: 16 | L13: 500 | M13: 217151.55 | N13: =IF(M13>0,(M13*2/1000000),(J13*L13*2/1000000)) -> 0.4343031 | O13: =N13*D13*4 -> 1.7372124
B14: HJ1 | C14: =CONCATENATE("□",J14,"×",K14,"×",L14) -> □110×10×1719 | D14: 8 | E14: =IF(M14>0,(M14*K14/1000000000*7850),(J14*K14*L14/1000000000*7850)) -> 14.843565 | F14: =D14*E14 -> 118.74852 | G14: =F14*4 -> 474.99408 | J14: 110 | K14: 10 | L14: 1719 | N14: =IF(M14>0,(M14*2/1000000),(J14*L14*2/1000000)) -> 0.37818 | O14: =N14*D14*4 -> 12.10176
B15: HJ2 | C15: =CONCATENATE("□",J15,"×",K15,"×",L15) -> □120×12×442 | D15: 3 | E15: =IF(M15>0,(M15*K15/1000000000*7850),(J15*K15*L15/1000000000*7850)) -> 4.996368 | F15: =D15*E15 -> 14.989104 | G15: =F15*4 -> 59.956416 | J15: 120 | K15: 12 | L15: 442 | N15: =IF(M15>0,(M15*2/1000000),(J15*L15*2/1000000)) -> 0.10608 | O15: =N15*D15*4 -> 1.27296
A16: 副拱加劲 | B16: J1 | C16: =CONCATENATE("□",J16,"×",K16,"×",L16,"(平均)") -> □140×12×22228(平均) | D16: 8 | E16: =IF(M16>0,(M16*K16/1000000000*7850),(J16*K16*L16/1000000000*7850)) -> 293.14286 | F16: =D16*E16 -> 2345.1429 | G16: =F16*4 -> 9380.5716 | J16: 140 | K16: 12 | L16: =(22268+22188)/2 -> 22228 | N16: =IF(M16>0,(M16*2/1000000),(J16*L16*2/1000000)) -> 6.22384 | O16: =N16*D16*4 -> 199.16288
A17: 连杆顶板 | B17: LT1 | C17: =CONCATENATE("□",J17,"×",K17,"×",L17) -> □450×32×9209 | D17: 1 | E17: =IF(M17>0,(M17*K17/1000000000*7850),(J17*K17*L17/1000000000*7850)) -> 1040.9854 | F17: =D17*E17 -> 1040.9854 | G17: =F17*4 -> 4163.9414 | J17: 450 | K17: 32 | L17: 9209 | N17: =IF(M17>0,(M17*2/1000000),(J17*L17*2/1000000)) -> 8.2881 | O17: =N17*D17*4 -> 33.1524
A18: 连杆底板 | B18: LD1 | C18: =CONCATENATE("□",J18,"×",K18,"×",L18) -> □450×32×10389 | D18: 1 | E18: =IF(M18>0,(M18*K18/1000000000*7850),(J18*K18*L18/1000000000*7850)) -> 1174.3726 | F18: =D18*E18 -> 1174.3726 | G18: =F18*4 -> 4697.4902 | J18: 450 | K18: 32 | L18: 10389 | N18: =IF(M18>0,(M18*2/1000000),(J18*L18*2/1000000)) -> 9.3501 | O18: =N18*D18*4 -> 37.4004
A19: 连杆腹板 | B19: LF1 | C19: =CONCATENATE("□",J19,"×",K19,"×",L19) -> □724×32×10456 | D19: 2 | E19: =IF(M19>0,(M19*K19/1000000000*7850),(J19*K19*L19/1000000000*7850)) -> 1901.6202 | F19: =D19*E19 -> 3803.2403 | G19: =F19*4 -> 15212.961 | J19: 724 | K19: 32 | L19: 10456 | N19: =IF(M19>0,(M19*2/1000000),(J19*L19*2/1000000)) -> 15.140288 | O19: =N19*D19*4 -> 121.1223
B20: LF2 | C20: =CONCATENATE("□",J20,"×",K20,"×",L20) -> □764×32×764 | D20: 2 | E20: =IF(M20>0,(M20*K20/1000000000*7850),(J20*K20*L20/1000000000*7850)) -> 30.203857 | F20: =D20*E20 -> 60.407713 | G20: =F20*4 -> 241.63085 | J20: 764 | K20: 32 | L20: 764 | M20: 120238.28 | N20: =IF(M20>0,(M20*2/1000000),(J20*L20*2/1000000)) -> 0.24047657 | O20: =N20*D20*4 -> 1.9238125
A21: 连杆横隔 | B21: LG1 | C21: =CONCATENATE("□",J21,"×",K21,"×",L21) -> □450×12×600 | D21: 5 | E21: =IF(M21>0,(M21*K21/1000000000*7850),(J21*K21*L21/1000000000*7850)) -> 12.692096 | F21: =D21*E21 -> 63.460478 | G21: =F21*4 -> 253.84191 | J21: 450 | K21: 12 | L21: 600 | M21: 134735.62 | N21: =IF(M21>0,(M21*2/1000000),(J21*L21*2/1000000)) -> 0.26947124 | O21: =N21*D21*4 -> 5.3894249
B22: LG2 | C22: =CONCATENATE("□",J22,"×",K22,"×",L22) -> □390×12×440 | D22: 5 | E22: =IF(M22>0,(M22*K22/1000000000*7850),(J22*K22*L22/1000000000*7850)) -> 16.16472 | F22: =D22*E22 -> 80.8236 | G22: =F22*4 -> 323.2944 | J22: 390 | K22: 12 | L22: 440 | N22: =IF(M22>0,(M22*2/1000000),(J22*L22*2/1000000)) -> 0.3432 | O22: =N22*D22*4 -> 6.864
A23: 转轴 | B23: A1 | C23: =CONCATENATE("□",J23,"×",K23,"×",L23) -> □724×282×1162 | D23: 2 | E23: =(785043.4338*282-31415.9265*140-531643.4338*142-724*320*80)/1000000000*7850 -> 965.20657 | F23: =D23*E23 -> 1930.4131 | G23: =F23*4 -> 7721.6526 | H23: 30Mn | J23: 724 | K23: 282 | L23: 1162 | N23: =IF(M23>0,(M23*2/1000000),(J23*L23*2/1000000)) -> 1.682576 | O23: =N23*D23*4 -> 13.460608
B24: A2 | C24: =CONCATENATE("□",J24,"×",K24,"×",L24) -> □875×40×2516 | D24: 2 | E24: =IF(M24>0,(M24*K24/1000000000*7850),(J24*K24*L24/1000000000*7850)) -> 364.72136 | F24: =D24*E24 -> 729.44271 | G24: =F24*4 -> 2917.7709 | H24: S355N | J24: 875 | K24: 40 | L24: 2516 | M24: 1161533 | N24: =IF(M24>0,(M24*2/1000000),(J24*L24*2/1000000)) -> 2.323066 | O24: =N24*D24*4 -> 18.584528
B25: A3 | C25: =CONCATENATE("□",J25,"×",K25,"×",L25) -> □600×50×600 | D25: 4 | E25: =IF(M25>0,(M25*K25/1000000000*7850),(J25*K25*L25/1000000000*7850)) -> 98.646009 | F25: =D25*E25 -> 394.58404 | G25: =F25*4 -> 1578.3361 | J25: 600 | K25: 50 | L25: 600 | M25: 251327.41 | N25: =IF(M25>0,(M25*2/1000000),(J25*L25*2/1000000)) -> 0.50265482 | O25: =N25*D25*4 -> 8.0424772
B26: A4 | C26: =CONCATENATE("□",J26,"×",K26,"×",L26) -> □150×12×150 | D26: 4 | E26: =IF(M26>0,(M26*K26/1000000000*7850),(J26*K26*L26/1000000000*7850)) -> 6.6586056 | F26: =D26*E26 -> 26.634423 | G26: =F26*4 -> 106.53769 | H26: Q355D | J26: 150 | K26: 12 | L26: 150 | M26: 70685.835 | N26: =IF(M26>0,(M26*2/1000000),(J26*L26*2/1000000)) -> 0.14137167 | O26: =N26*D26*4 -> 2.2619467
B27: A5 | C27: =CONCATENATE("D",J27,"×",K27) -> D200×280 | D27: 2 | E27: =0.0314159265*0.28*7850 -> 69.052206 | F27: =D27*E27 -> 138.10441 | G27: =F27*4 -> 552.41765 | H27: 40Cr | J27: 200 | K27: 280 | N27: =PI()*(J27/2)^2/1000000 -> 0.031415927 | O27: =N27*D27*4*2 -> 0.50265482
B28: M30螺栓 | C28: M30×70 GB/T 70.1 10.9 | D28: 4 | E28: - | F28: - | G28: =D28*4 -> 16
B29: 合计（kg） | F29: =SUM(F4:F27) -> 27658.684 | G29: =F29*4 -> 110634.74
B30: 焊缝1.5%（kg） | F30: =F29*0.015 -> 414.88026 | G30: =F30*4 -> 1659.5211
B31: 总计（kg） | F31: =F29+F30 -> 28073.564 | G31: =F31*4 -> 112294.26
A39: Q355D | B39: 10 | C39: =SUMIF($K$4:$K$22,B39,$G$4:$G$22) -> 474.99408
B40: 12 | C40: =SUMIF($K$4:$K$22,B40,$G$4:$G$22)+G26 -> 13254.999
B41: 16 | C41: =SUMIF($K$4:$K$22,B41,$G$4:$G$22) -> 57878.647
B42: 20 | C42: =SUMIF($K$4:$K$22,B42,$G$4:$G$22) -> 1939.8958
B43: 32 | C43: =SUMIF($K$4:$K$22,B43,$G$4:$G$22) -> 24316.024
B44: 合计 | C44: =SUM(C39:C43) -> 97864.56
A45: 30Mn | B45: 282 | C45: =G23 -> 7721.6526
A46: S355N | B46: 40 | C46: =G24 -> 2917.7709
B47: 50 | C47: =G25 -> 1578.3361 | D47: =SUM(C39:C48) -> 208499.3
A48: 40Cr | B48: D200 | C48: =G27 -> 552.41765
A49: 涂装 | B49: 外涂 | C49: =SUM(O4:O9)/2+SUM(O17:O20)/2+SUM(O23:O27) -> 603.81536
...

Sheet C3节段
A3: 位置 | B3: 编号 | C3: 规格(mm) | D3: 数量 | E3: 单件重(kg) | F3: 共重(kg) | G3: 全桥合计(共4段) | H3: 牌号 | J3: 短边 | K3: 厚度 | L3: 长边 | M3: 侧面S | N3: 涂装
A4: 顶板 | B4: FT1 | C4: =CONCATENATE("□",J4,"×",K4,"×",L4) -> □1508×16×25289 | D4: 1 | E4: =IF(M4>0,(M4*K4/1000000000*7850),(J4*K4*L4/1000000000*7850)) -> 4789.858 | F4: =D4*E4 -> 4789.858 | G4: =F4*4 -> 19159.432 | H4: Q355D | J4: 1508 | K4: 16 | L4: 25289 | N4: =IF(M4>0,(M4*2/1000000),(J4*L4*2/1000000)) -> 76.271624 | O4: =N4*D4*N4 -> 5817.3606
A5: 底板 | B5: FD1 | C5: =CONCATENATE("□",J5,"×",K5,"×",L5) -> □1000×16×25206 | D5: 1 | E5: =IF(M5>0,(M5*K5/1000000000*7850),(J5*K5*L5/1000000000*7850)) -> 3165.8736 | F5: =D5*E5 -> 3165.8736 | G5: =F5*4 -> 12663.494 | J5: 1000 | K5: 16 | L5: 25206 | N5: =IF(M5>0,(M5*2/1000000),(J5*L5*2/1000000)) -> 50.412 | O5: =N5*D5*N5 -> 2541.3697
A6: 腹板 | B6: FF1 | C6: =CONCATENATE("□",J6,"×",K6,"×",L6) -> □1064×16×25289 | D6: 2 | E6: =IF(M6>0,(M6*K6/1000000000*7850),(J6*K6*L6/1000000000*7850)) -> 3379.5815 | F6: =D6*E6 -> 6759.163 | G6: =F6*4 -> 27036.652 | J6: 1064 | K6: 16 | L6: 25289 | N6: =IF(M6>0,(M6*2/1000000),(J6*L6*2/1000000)) -> 53.814992 | O6: =N6*D6*N6 -> 5792.1067
A7: 横隔 | B7: HG1 | C7: =CONCATENATE("□",J7,"×",K7,"×",L7) -> □1500×12×1000 | D7: 10 | E7: =IF(M7>0,(M7*K7/1000000000*7850),(J7*K7*L7/1000000000*7850)) -> 90.627375 | F7: =D7*E7 -> 906.27375 | G7: =F7*4 -> 3625.095 | J7: 1500 | K7: 12 | L7: 1000 | M7: 962074.04 | N7: =IF(M7>0,(M7*2/1000000),(J7*L7*2/1000000)) -> 1.9241481 | O7: =N7*D7*N7 -> 37.023458
B8: HJ1 | C8: =CONCATENATE("□",J8,"×",K8,"×",L8) -> □1719×10×110 | D8: 10 | E8: =IF(M8>0,(M8*K8/1000000000*7850),(J8*K8*L8/1000000000*7850)) -> 14.843565 | F8: =D8*E8 -> 148.43565 | G8: =F8*4 -> 593.7426 | J8: 1719 | K8: 10 | L8: 110 | N8: =IF(M8>0,(M8*2/1000000),(J8*L8*2/1000000)) -> 0.37818 | O8: =N8*D8*N8 -> 1.4302011
A9: 加劲 | B9: J1 | C9: =CONCATENATE("□",J9,"×",K9,"×",L9,"(平均)") -> □140×12×25248(平均) | D9: 8 | E9: =IF(M9>0,(M9*K9/1000000000*7850),(J9*K9*L9/1000000000*7850)) -> 332.97062 | F9: =D9*E9 -> 2663.765 | G9: =F9*4 -> 10655.06 | J9: 140 | K9: 12 | L9: =(25289+25207)/2 -> 25248 | N9: =IF(M9>0,(M9*2/1000000),(J9*L9*2/1000000)) -> 7.06944 | O9: =N9*D9*N9 -> 399.81586
B10: 合计（kg） | F10: =SUM(F4:F9) -> 18433.369 | G10: =F10*4 -> 73733.476
B11: 焊缝1.5%（kg） | F11: =F10*0.015 -> 276.50053 | G11: =F11*4 -> 1106.0021
B12: 总计（kg） | F12: =F10+F11 -> 18709.87 | G12: =F12*4 -> 74839.478
A19: Q355D | B19: 10 | C19: =SUMIF($K$4:$K$9,B19,$G$4:$G$9) -> 593.7426
B20: 12 | C20: =SUMIF($K$4:$K$9,B20,$G$4:$G$9) -> 14280.155
B21: 16 | C21: =SUMIF($K$4:$K$9,B21,$G$4:$G$9) -> 58859.578
B22: 合计 | C22: =SUM(C19:C21) -> 73733.476
A23: 涂装 | B23: 外涂 | C23: =SUM(O4:O5)/2 -> 4179.3652
B24: 内涂 | C24: =SUM(O4:O5)/2+SUM(O6:O9)*4 -> 29100.87

Sheet C4节段
A3: 位置 | B3: 编号 | C3: 规格(mm) | D3: 数量 | E3: 单件重(kg) | F3: 共重(kg) | G3: 全桥合计(共2段) | H3: 牌号 | J3: 短边 | K3: 厚度 | L3: 长边 | M3: 侧面S | N3: 涂装
A4: 副拱顶板 | B4: FT1 | C4: =CONCATENATE("□",J4,"×",K4,"×",L4) -> □1508×24×10667 | D4: 1 | E4: =IF(M4>0,(M4*K4/1000000000*7850),(J4*K4*L4/1000000000*7850)) -> 3030.5715 | F4: =D4*E4 -> 3030.5715 | G4: =F4*2 -> 6061.143 | H4: Q355D | J4: 1508 | K4: 24 | L4: =10679-12 -> 10667 | N4: =IF(M4>0,(M4*2/1000000),(J4*L4*2/1000000)) -> 32.171672 | O4: =N4*D4*2 -> 64.343344
A5: 副拱底板 | B5: FD1 | C5: =CONCATENATE("□",J5,"×",K5,"×",L5) -> □1000×24×9332 | D5: 1 | E5: =IF(M5>0,(M5*K5/1000000000*7850),(J5*K5*L5/1000000000*7850)) -> 1758.1488 | F5: =D5*E5 -> 1758.1488 | G5: =F5*2 -> 3516.2976 | J5: 1000 | K5: 24 | L5: 9332 | N5: =IF(M5>0,(M5*2/1000000),(J5*L5*2/1000000)) -> 18.664 | O5: =N5*D5*2 -> 37.328
A6: 副拱腹板 | B6: FF1 | C6: =CONCATENATE("□",J6,"×",K6,"×",L6) -> □1080×24×10667 | D6: 2 | E6: =IF(M6>0,(M6*K6/1000000000*7850),(J6*K6*L6/1000000000*7850)) -> 2170.4358 | F6: =D6*E6 -> 4340.8716 | G6: =F6*2 -> 8681.7433 | J6: 1080 | K6: 24 | L6: =L4 -> 10667 | N6: =IF(M6>0,(M6*2/1000000),(J6*L6*2/1000000)) -> 23.04072 | O6: =N6*D6*2 -> 92.16288
B7: FF2 | C7: =CONCATENATE("□",J7,"×",K7,"×",L7) -> □1321×24×1310 | D7: 2 | E7: =IF(M7>0,(M7*K7/1000000000*7850),(J7*K7*L7/1000000000*7850)) -> 51.826604 | F7: =D7*E7 -> 103.65321 | G7: =F7*2 -> 207.30642 | J7: 1321 | K7: 24 | L7: 1310 | M7: 275088.13 | N7: =IF(M7>0,(M7*2/1000000),(J7*L7*2/1000000)) -> 0.55017626 | O7: =N7*D7*2 -> 2.2007051
A8: 副拱横隔 | B8: HG1 | C8: =CONCATENATE("□",J8,"×",K8,"×",L8) -> □1000×12×1500 | D8: 3 | E8: =IF(M8>0,(M8*K8/1000000000*7850),(J8*K8*L8/1000000000*7850)) -> 89.037229 | F8: =D8*E8 -> 267.11169 | G8: =F8*2 -> 534.22337 | J8: 1000 | K8: 12 | L8: 1500 | M8: 945193.51 | N8: =IF(M8>0,(M8*2/1000000),(J8*L8*2/1000000)) -> 1.890387 | O8: =N8*D8*2 -> 11.342322
B9: HG2 | C9: =CONCATENATE("□",J9,"×",K9,"×",L9) -> □1000×24×1500 | D9: 2 | E9: =IF(M9>0,(M9*K9/1000000000*7850),(J9*K9*L9/1000000000*7850)) -> 178.07446 | F9: =D9*E9 -> 356.14892 | G9: =F9*2 -> 712.29783 | J9: 1000 | K9: 24 | L9: 1500 | M9: 945193.51 | N9: =IF(M9>0,(M9*2/1000000),(J9*L9*2/1000000)) -> 1.890387 | O9: =N9*D9*2 -> 7.5615481
B10: HG3 | C10: =CONCATENATE("□",J10,"×",K10,"×",L10) -> □1500×24×1695 | D10: 1 | E10: =IF(M10>0,(M10*K10/1000000000*7850),(J10*K10*L10/1000000000*7850)) -> 310.94819 | F10: =D10*E10 -> 310.94819 | G10: =F10*2 -> 621.89638 | J10: 1500 | K10: 24 | L10: 1695 | M10: 1650468.1 | N10: =IF(M10>0,(M10*2/1000000),(J10*L10*2/1000000)) -> 3.3009362 | O10: =N10*D10*2 -> 6.6018724
B11: HG4 | C11: =CONCATENATE("□",J11,"×",K11,"×",L11) -> □1500×24×1402 | D11: 1 | E11: =IF(M11>0,(M11*K11/1000000000*7850),(J11*K11*L11/1000000000*7850)) -> 216.95785 | F11: =D11*E11 -> 216.95785 | G11: =F11*2 -> 433.9157 | J11: 1500 | K11: 24 | L11: 1402 | M11: 1151580.9 | N11: =IF(M11>0,(M11*2/1000000),(J11*L11*2/1000000)) -> 2.3031619 | O11: =N11*D11*2 -> 4.6063238
B12: HG4a | C12: =CONCATENATE("□",J12,"×",K12,"×",L12) -> □400×24×488 | D12: 1 | E12: =IF(M12>0,(M12*K12/1000000000*7850),(J12*K12*L12/1000000000*7850)) -> 36.77568 | F12: =D12*E12 -> 36.77568 | G12: =F12*2 -> 73.55136 | J12: 400 | K12: 24 | L12: 488 | N12: =IF(M12>0,(M12*2/1000000),(J12*L12*2/1000000)) -> 0.3904 | O12: =N12*D12*2 -> 0.7808
B13: HG5 | C13: =CONCATENATE("□",J13,"×",K13,"×",L13) -> □1057×24×1561 | D13: 1 | E13: =IF(M13>0,(M13*K13/1000000000*7850),(J13*K13*L13/1000000000*7850)) -> 204.97897 | F13: =D13*E13 -> 204.97897 | G13: =F13*2 -> 409.95795 | J13: 1057 | K13: 24 | L13: 1561 | M13: 1087998.8 | N13: =IF(M13>0,(M13*2/1000000),(J13*L13*2/1000000)) -> 2.1759976 | O13: =N13*D13*2 -> 4.3519952
B14: HG5a | C14: =CONCATENATE("□",J14,"×",K14,"×",L14) -> □584×16×584 | D14: =D13 -> 1 | E14: =IF(M14>0,(M14*K14/1000000000*7850),(J14*K14*L14/1000000000*7850)) -> 33.643813 | F14: =D14*E14 -> 33.643813 | G14: =F14*2 -> 67.287627 | J14: 584 | K14: 16 | L14: 584 | M14: 267864.76 | N14: =IF(M14>0,(M14*2/1000000),(J14*L14*2/1000000)) -> 0.53572951 | O14: =N14*D14*2 -> 1.071459
B15: HG5b | C15: =CONCATENATE("□",J15,"×",K15,"×",L15) -> □150×8×150 | D15: =D13*4 -> 4 | E15: =IF(M15>0,(M15*K15/1000000000*7850),(J15*K15*L15/1000000000*7850)) -> 1.413 | F15: =D15*E15 -> 5.652 | G15: =F15*2 -> 11.304 | J15: 150 | K15: 8 | L15: 150 | N15: =IF(M15>0,(M15*2/1000000),(J15*L15*2/1000000)) -> 0.045 | O15: =N15*D15*2 -> 0.36
B16: HJ1 | C16: =CONCATENATE("□",J16,"×",K16,"×",L16) -> □110×10×1719 | D16: =SUM(D8:D10) -> 6 | E16: =IF(M16>0,(M16*K16/1000000000*7850),(J16*K16*L16/1000000000*7850)) -> 14.843565 | F16: =D16*E16 -> 89.06139 | G16: =F16*2 -> 178.12278 | J16: 110 | K16: 10 | L16: 1719 | N16: =IF(M16>0,(M16*2/1000000),(J16*L16*2/1000000)) -> 0.37818 | O16: =N16*D16*2 -> 4.53816
B17: HJ2 | C17: =CONCATENATE("□",J17,"×",K17,"×",L17) -> □300×12×448 | D17: 1 | E17: =IF(M17>0,(M17*K17/1000000000*7850),(J17*K17*L17/1000000000*7850)) -> 12.66048 | F17: =D17*E17 -> 12.66048 | G17: =F17*2 -> 25.32096 | J17: 300 | K17: 12 | L17: 448 | N17: =IF(M17>0,(M17*2/1000000),(J17*L17*2/1000000)) -> 0.2688 | O17: =N17*D17*2 -> 0.5376
B18: HJ2a | C18: =CONCATENATE("□",J18,"×",K18,"×",L18) -> □400×12×500 | D18: 1 | E18: =IF(M18>0,(M18*K18/1000000000*7850),(J18*K18*L18/1000000000*7850)) -> 18.84 | F18: =D18*E18 -> 18.84 | G18: =F18*2 -> 37.68 | J18: 400 | K18: 12 | L18: 500 | N18: =IF(M18>0,(M18*2/1000000),(J18*L18*2/1000000)) -> 0.4 | O18: =N18*D18*2 -> 0.8
B19: HJ3 | C19: =CONCATENATE("□",J19,"×",K19,"×",L19) -> □900×24×1058 | D19: 2 | E19: =IF(M19>0,(M19*K19/1000000000*7850),(J19*K19*L19/1000000000*7850)) -> 103.50425 | F19: =D19*E19 -> 207.00851 | G19: =F19*2 -> 414.01702 | J19: 900 | K19: 24 | L19: 1058 | M19: 549385.64 | N19: =IF(M19>0,(M19*2/1000000),(J19*L19*2/1000000)) -> 1.0987713 | O19: =N19*D19*2 -> 4.3950851
B20: HJ4 | C20: =CONCATENATE("□",J20,"×",K20,"×",L20) -> □200×24×900 | D20: 2 | E20: =IF(M20>0,(M20*K20/1000000000*7850),(J20*K20*L20/1000000000*7850)) -> 33.912 | F20: =D20*E20 -> 67.824 | G20: =F20*2 -> 135.648 | J20: 200 | K20: 24 | L20: 900 | N20: =IF(M20>0,(M20*2/1000000),(J20*L20*2/1000000)) -> 0.36 | O20: =N20*D20*2 -> 1.44
A21: 副拱加劲 | B21: FJ1 | C21: =CONCATENATE("□",J21,"×",K21,"×",L21,"(总长)") -> □140×12×85432(总长) | D21: 1 | E21: =IF(M21>0,(M21*K21/1000000000*7850),(J21*K21*L21/1000000000*7850)) -> 1126.6772 | F21: =D21*E21 -> 1126.6772 | G21: =F21*2 -> 2253.3544 | J21: 140 | K21: 12 | L21: =10679*8 -> 85432 | N21: =IF(M21>0,(M21*2/1000000),(J21*L21*2/1000000)) -> 23.92096 | O21: =N21*D21*2 -> 47.84192
A22: 连梁顶板 | B22: LT1 | C22: =CONCATENATE("□",J22,"×",K22,"×",L22) -> □1000×24×21330 | D22: 1 | E22: =IF(M22>0,(M22*K22/1000000000*7850),(J22*K22*L22/1000000000*7850)) -> 4018.572 | F22: =D22*E22 -> 4018.572 | G22: =F22*2 -> 8037.144 | J22: 1000 | K22: 24 | L22: 21330 | N22: =IF(M22>0,(M22*2/1000000),(J22*L22*2/1000000)) -> 42.66 | O22: =N22*D22*2 -> 85.32
A23: 连梁底板 | B23: LD1 | C23: =CONCATENATE("□",J23,"×",K23,"×",L23) -> □1000×24×23379 | D23: 1 | E23: =IF(M23>0,(M23*K23/1000000000*7850),(J23*K23*L23/1000000000*7850)) -> 4404.6036 | F23: =D23*E23 -> 4404.6036 | G23: =F23*2 -> 8809.2072 | J23: 1000 | K23: 24 | L23: 23379 | N23: =IF(M23>0,(M23*2/1000000),(J23*L23*2/1000000)) -> 46.758 | O23: =N23*D23*2 -> 93.516
A24: 连梁腹板 | B24: LF1 | C24: =CONCATENATE("□",J24,"×",K24,"×",L24) -> □1048×24×23380 | D24: 2 | E24: =IF(M24>0,(M24*K24/1000000000*7850),(J24*K24*L24/1000000000*7850)) -> 4414.0844 | F24: =D24*E24 -> 8828.1687 | G24: =F24*2 -> 17656.337 | J24: 1048 | K24: 24 | L24: 23380 | M24: 23429322 | N24: =IF(M24>0,(M24*2/1000000),(J24*L24*2/1000000)) -> 46.858645 | O24: =N24*D24*2 -> 187.43458
A25: 连杆横隔 | B25: LG1 | C25: =CONCATENATE("□",J25,"×",K25,"×",L25) -> □1000×12×1000 | D25: 6 | E25: =IF(M25>0,(M25*K25/1000000000*7850),(J25*K25*L25/1000000000*7850)) -> 70.812446 | F25: =D25*E25 -> 424.87467 | G25: =F25*2 -> 849.74935 | J25: 1000 | K25: 12 | L25: 1000 | M25: 751724.48 | N25: =IF(M25>0,(M25*2/1000000),(J25*L25*2/1000000)) -> 1.503449 | O25: =N25*D25*2 -> 18.041387
B26: LG2 | C26: =CONCATENATE("□",J26,"×",K26,"×",L26) -> □1000×24×1000 | D26: 2 | E26: =IF(M26>0,(M26*K26/1000000000*7850),(J26*K26*L26/1000000000*7850)) -> 141.62489 | F26: =D26*E26 -> 283.24978 | G26: =F26*2 -> 566.49957 | J26: 1000 | K26: 24 | L26: 1000 | M26: 751724.48 | N26: =IF(M26>0,(M26*2/1000000),(J26*L26*2/1000000)) -> 1.503449 | O26: =N26*D26*2 -> 6.0137958
B27: HJ5 | C27: =CONCATENATE("□",J27,"×",K27,"×",L27) -> □110×10×1491 | D27: 8 | E27: =IF(M27>0,(M27*K27/1000000000*7850),(J27*K27*L27/1000000000*7850)) -> 12.874785 | F27: =D27*E27 -> 102.99828 | G27: =F27*2 -> 205.99656 | J27: 110 | K27: 10 | L27: 1491 | N27: =IF(M27>0,(M27*2/1000000),(J27*L27*2/1000000)) -> 0.32802 | O27: =N27*D27*2 -> 5.24832
A28: 副拱加劲 | B28: LJ1 | C28: =CONCATENATE("□",J28,"×",K28,"×",L28,"(总长)") -> □140×12×177854(总长) | D28: 1 | E28: =IF(M28>0,(M28*K28/1000000000*7850),(J28*K28*L28/1000000000*7850)) -> 2345.5386 | F28: =D28*E28 -> 2345.5386 | G28: =F28*2 -> 4691.0771 | J28: 140 | K28: 12 | L28: =(44218+23379+21330)*2 -> 177854 | N28: =IF(M28>0,(M28*2/1000000),(J28*L28*2/1000000)) -> 49.79912 | O28: =N28*D28*2 -> 99.59824
A29: 调平钢板 | B29: Z1 | C29: =CONCATENATE("□",J29,"×",K29,"×",L29) -> □931×110×1000 | D29: 1 | E29: =IF(M29>0,(M29*K29/1000000000*7850),(J29*K29*L29/1000000000*7850)) -> 803.9185 | F29: =D29*E29 -> 803.9185 | G29: =F29*2 -> 1607.837 | H29: ZG310-570 | J29: 931 | K29: 110 | L29: 1000 | N29: =IF(M29>0,(M29*2/1000000),(J29*L29*2/1000000)) -> 1.862 | O29: =N29*D29*2 -> 3.724
B30: 合计（kg） | F30: =SUM(F4:F29) -> 33399.458 | G30: =F30*2 -> 66798.916
B31: 焊缝1.5%（kg） | F31: =F30*0.015 -> 500.99187 | G31: =F31*2 -> 1001.9837
B32: 总计（kg） | F32: =F30+F31 -> 33900.45 | G32: =F32*2 -> 67800.9
A33: M16螺栓 | F33: =4 -> 4 | G33: =F33*2 -> 8
A41: Q355D | B41: 10 | C41: =SUMIF($K$4:$K$29,B41,$G$4:$G$29) -> 384.11934
B42: 12 | C42: =SUMIF($K$4:$K$29,B42,$G$4:$G$29) -> 8391.4052
B43: 24 | C43: =SUMIF($K$4:$K$29,B43,$G$4:$G$29) -> 56336.963
B44: 合计 | C44: =SUM(C41:C43) -> 65112.487
A45: 铸钢 | B45: ZG310-570 | C45: =G29 -> 1607.837 | D45: =SUM(C41:C45) -> 131832.81
A46: 涂装 | B46: 外涂 | C46: =SUM(O4:O5)/2+SUM(O22:O23)/2+O29 -> 143.97767
B47: 内涂 | C47: =SUM(O4:O5)/2+SUM(O22:O23)/2+SUM(O6:O21)+SUM(O24:O28) -> 647.18267

Sheet C5节段
A3: 位置 | B3: 编号 | C3: 规格(mm) | D3: 数量 | E3: 单件重(kg) | F3: 共重(kg) | G3: 全桥合计(共2段) | H3: 牌号 | J3: 短边 | K3: 厚度 | L3: 长边 | M3: 侧面S | N3: 涂装
A4: 副拱顶板 | B4: FT1 | C4: =CONCATENATE("□",J4,"×",K4,"×",L4) -> □1508×24×12945 | D4: 1 | E4: =IF(M4>0,(M4*K4/1000000000*7850),(J4*K4*L4/1000000000*7850)) -> 3677.7677 | F4: =D4*E4 -> 3677.7677 | G4: =F4*2 -> 7355.5354 | H4: Q355D | J4: 1508 | K4: 24 | L4: =12957-12 -> 12945 | N4: =IF(M4>0,(M4*2/1000000),(J4*L4*2/1000000)) -> 39.04212 | O4: =N4*D4*2 -> 78.08424
A5: 副拱底板 | B5: FD1 | C5: =CONCATENATE("□",J5,"×",K5,"×",L5) -> □1000×24×11570 | D5: 1 | E5: =IF(M5>0,(M5*K5/1000000000*7850),(J5*K5*L5/1000000000*7850)) -> 2179.788 | F5: =D5*E5 -> 2179.788 | G5: =F5*2 -> 4359.576 | J5: 1000 | K5: 24 | L5: 11570 | N5: =IF(M5>0,(M5*2/1000000),(J5*L5*2/1000000)) -> 23.14 | O5: =N5*D5*2 -> 46.28
A6: 副拱腹板 | B6: FF1 | C6: =CONCATENATE("□",J6,"×",K6,"×",L6) -> □1080×24×12945 | D6: 2 | E6: =IF(M6>0,(M6*K6/1000000000*7850),(J6*K6*L6/1000000000*7850)) -> 2633.945 | F6: =D6*E6 -> 5267.8901 | G6: =F6*2 -> 10535.78 | J6: 1080 | K6: 24 | L6: =L4 -> 12945 | N6: =IF(M6>0,(M6*2/1000000),(J6*L6*2/1000000)) -> 27.9612 | O6: =N6*D6*2 -> 111.8448
B7: FF2 | C7: =CONCATENATE("□",J7,"×",K7,"×",L7) -> □1333×24×1333 | D7: 2 | E7: =IF(M7>0,(M7*K7/1000000000*7850),(J7*K7*L7/1000000000*7850)) -> 52.525067 | F7: =D7*E7 -> 105.05013 | G7: =F7*2 -> 210.10027 | J7: 1333 | K7: 24 | L7: 1333 | M7: 278795.47 | N7: =IF(M7>0,(M7*2/1000000),(J7*L7*2/1000000)) -> 0.55759094 | O7: =N7*D7*2 -> 2.2303638
A8: 副拱横隔 | B8: HG1 | C8: =CONCATENATE("□",J8,"×",K8,"×",L8) -> □1000×12×1500 | D8: 4 | E8: =IF(M8>0,(M8*K8/1000000000*7850),(J8*K8*L8/1000000000*7850)) -> 89.037229 | F8: =D8*E8 -> 356.14892 | G8: =F8*2 -> 712.29783 | J8: 1000 | K8: 12 | L8: 1500 | M8: 945193.51 | N8: =IF(M8>0,(M8*2/1000000),(J8*L8*2/1000000)) -> 1.890387 | O8: =N8*D8*2 -> 15.123096
B9: HG2 | C9: =CONCATENATE("□",J9,"×",K9,"×",L9) -> □1000×24×1500 | D9: 2 | E9: =IF(M9>0,(M9*K9/1000000000*7850),(J9*K9*L9/1000000000*7850)) -> 178.07446 | F9: =D9*E9 -> 356.14892 | G9: =F9*2 -> 712.29783 | J9: 1000 | K9: 24 | L9: 1500 | M9: 945193.51 | N9: =IF(M9>0,(M9*2/1000000),(J9*L9*2/1000000)) -> 1.890387 | O9: =N9*D9*2 -> 7.5615481
B10: HG3 | C10: =CONCATENATE("□",J10,"×",K10,"×",L10) -> □1500×24×1695 | D10: 1 | E10: =IF(M10>0,(M10*K10/1000000000*7850),(J10*K10*L10/1000000000*7850)) -> 313.57427 | F10: =D10*E10 -> 313.57427 | G10: =F10*2 -> 627.14854 | J10: 1500 | K10: 24 | L10: 1695 | M10: 1664407 | N10: =IF(M10>0,(M10*2/1000000),(J10*L10*2/1000000)) -> 3.3288139 | O10: =N10*D10*2 -> 6.6576278
B11: HG4 | C11: =CONCATENATE("□",J11,"×",K11,"×",L11) -> □1500×24×1402 | D11: 1 | E11: =IF(M11>0,(M11*K11/1000000000*7850),(J11*K11*L11/1000000000*7850)) -> 220.01803 | F11: =D11*E11 -> 220.01803 | G11: =F11*2 -> 440.03607 | J11: 1500 | K11: 24 | L11: 1402 | M11: 1167824 | N11: =IF(M11>0,(M11*2/1000000),(J11*L11*2/1000000)) -> 2.3356479 | O11: =N11*D11*2 -> 4.6712958
B12: HG4a | C12: =CONCATENATE("□",J12,"×",K12,"×",L12) -> □400×24×488 | D12: 1 | E12: =IF(M12>0,(M12*K12/1000000000*7850),(J12*K12*L12/1000000000*7850)) -> 36.77568 | F12: =D12*E12 -> 36.77568 | G12: =F12*2 -> 73.55136 | J12: 400 | K12: 24 | L12: 488 | N12: =IF(M12>0,(M12*2/1000000),(J12*L12*2/1000000)) -> 0.3904 | O12: =N12*D12*2 -> 0.7808
B13: HG5 | C13: =CONCATENATE("□",J13,"×",K13,"×",L13) -> □1056×24×1561 | D13: 1 | E13: =IF(M13>0,(M13*K13/1000000000*7850),(J13*K13*L13/1000000000*7850)) -> 258.24782 | F13: =D13*E13 -> 258.24782 | G13: =F13*2 -> 516.49564 | J13: 1056 | K13: 24 | L13: 1561 | M13: 1370742.1 | N13: =IF(M13>0,(M13*2/1000000),(J13*L13*2/1000000)) -> 2.7414843 | O13: =N13*D13*2 -> 5.4829686
B14: HG5a | C14: =CONCATENATE("□",J14,"×",K14,"×",L14) -> □584×16×584 | D14: =D13 -> 1 | E14: =IF(M14>0,(M14*K14/1000000000*7850),(J14*K14*L14/1000000000*7850)) -> 33.643813 | F14: =D14*E14 -> 33.643813 | G14: =F14*2 -> 67.287627 | J14: 584 | K14: 16 | L14: 584 | M14: 267864.76 | N14: =IF(M14>0,(M14*2/1000000),(J14*L14*2/1000000)) -> 0.53572951 | O14: =N14*D14*2 -> 1.071459
B15: HG5b | C15: =CONCATENATE("□",J15,"×",K15,"×",L15) -> □150×8×150 | D15: =D13*4 -> 4 | E15: =IF(M15>0,(M15*K15/1000000000*7850),(J15*K15*L15/1000000000*7850)) -> 1.413 | F15: =D15*E15 -> 5.652 | G15: =F15*2 -> 11.304 | J15: 150 | K15: 8 | L15: 150 | N15: =IF(M15>0,(M15*2/1000000),(J15*L15*2/1000000)) -> 0.045 | O15: =N15*D15*2 -> 0.36
B16: HJ1 | C16: =CONCATENATE("□",J16,"×",K16,"×",L16) -> □110×10×1719 | D16: =SUM(D8:D10) -> 7 | E16: =IF(M16>0,(M16*K16/1000000000*7850),(J16*K16*L16/1000000000*7850)) -> 14.843565 | F16: =D16*E16 -> 103.90496 | G16: =F16*2 -> 207.80991 | J16: 110 | K16: 10 | L16: 1719 | N16: =IF(M16>0,(M16*2/1000000),(J16*L16*2/1000000)) -> 0.37818 | O16: =N16*D16*2 -> 5.29452
B17: HJ2 | C17: =CONCATENATE("□",J17,"×",K17,"×",L17) -> □300×12×448 | D17: 1 | E17: =IF(M17>0,(M17*K17/1000000000*7850),(J17*K17*L17/1000000000*7850)) -> 12.66048 | F17: =D17*E17 -> 12.66048 | G17: =F17*2 -> 25.32096 | J17: 300 | K17: 12 | L17: 448 | N17: =IF(M17>0,(M17*2/1000000),(J17*L17*2/1000000)) -> 0.2688 | O17: =N17*D17*2 -> 0.5376
B18: HJ2a | C18: =CONCATENATE("□",J18,"×",K18,"×",L18) -> □400×12×500 | D18: 1 | E18: =IF(M18>0,(M18*K18/1000000000*7850),(J18*K18*L18/1000000000*7850)) -> 18.84 | F18: =D18*E18 -> 18.84 | G18: =F18*2 -> 37.68 | J18: 400 | K18: 12 | L18: 500 | N18: =IF(M18>0,(M18*2/1000000),(J18*L18*2/1000000)) -> 0.4 | O18: =N18*D18*2 -> 0.8
B19: HJ3 | C19: =CONCATENATE("□",J19,"×",K19,"×",L19) -> □900×24×1058 | D19: 2 | E19: =IF(M19>0,(M19*K19/1000000000*7850),(J19*K19*L19/1000000000*7850)) -> 103.50425 | F19: =D19*E19 -> 207.00851 | G19: =F19*2 -> 414.01702 | J19: 900 | K19: 24 | L19: 1058 | M19: 549385.64 | N19: =IF(M19>0,(M19*2/1000000),(J19*L19*2/1000000)) -> 1.0987713 | O19: =N19*D19*2 -> 4.3950851
B20: HJ4 | C20: =CONCATENATE("□",J20,"×",K20,"×",L20) -> □200×24×900 | D20: 2 | E20: =IF(M20>0,(M20*K20/1000000000*7850),(J20*K20*L20/1000000000*7850)) -> 33.912 | F20: =D20*E20 -> 67.824 | G20: =F20*2 -> 135.648 | J20: 200 | K20: 24 | L20: 900 | N20: =IF(M20>0,(M20*2/1000000),(J20*L20*2/1000000)) -> 0.36 | O20: =N20*D20*2 -> 1.44
A21: 副拱加劲 | B21: FJ1 | C21: =CONCATENATE("□",J21,"×",K21,"×",L21,"(总长)") -> □140×12×103656(总长) | D21: 1 | E21: =IF(M21>0,(M21*K21/1000000000*7850),(J21*K21*L21/1000000000*7850)) -> 1367.0153 | F21: =D21*E21 -> 1367.0153 | G21: =F21*2 -> 2734.0307 | J21: 140 | K21: 12 | L21: =12957*8 -> 103656 | N21: =IF(M21>0,(M21*2/1000000),(J21*L21*2/1000000)) -> 29.02368 | O21: =N21*D21*2 -> 58.04736
A22: 连梁顶板 | B22: LT1 | C22: =CONCATENATE("□",J22,"×",K22,"×",L22) -> □1000×24×22352 | D22: 1 | E22: =IF(M22>0,(M22*K22/1000000000*7850),(J22*K22*L22/1000000000*7850)) -> 4211.1168 | F22: =D22*E22 -> 4211.1168 | G22: =F22*2 -> 8422.2336 | J22: 1000 | K22: 24 | L22: 22352 | N22: =IF(M22>0,(M22*2/1000000),(J22*L22*2/1000000)) -> 44.704 | O22: =N22*D22*2 -> 89.408
A23: 连梁底板 | B23: LD1 | C23: =CONCATENATE("□",J23,"×",K23,"×",L23) -> □1000×24×24405 | D23: 1 | E23: =IF(M23>0,(M23*K23/1000000000*7850),(J23*K23*L23/1000000000*7850)) -> 4597.902 | F23: =D23*E23 -> 4597.902 | G23: =F23*2 -> 9195.804 | J23: 1000 | K23: 24 | L23: 24405 | N23: =IF(M23>0,(M23*2/1000000),(J23*L23*2/1000000)) -> 48.81 | O23: =N23*D23*2 -> 97.62
A24: 连梁腹板 | B24: LF1 | C24: =CONCATENATE("□",J24,"×",K24,"×",L24) -> □1048×24×24405 | D24: 2 | E24: =IF(M24>0,(M24*K24/1000000000*7850),(J24*K24*L24/1000000000*7850)) -> 4404.4917 | F24: =D24*E24 -> 8808.9834 | G24: =F24*2 -> 17617.967 | J24: 1048 | K24: 24 | L24: 24405 | M24: 23378406 | N24: =IF(M24>0,(M24*2/1000000),(J24*L24*2/1000000)) -> 46.756812 | O24: =N24*D24*2 -> 187.02725
A25: 连梁横隔 | B25: LG1 | C25: =CONCATENATE("□",J25,"×",K25,"×",L25) -> □1000×12×1000 | D25: 7 | E25: =IF(M25>0,(M25*K25/1000000000*7850),(J25*K25*L25/1000000000*7850)) -> 70.812446 | F25: =D25*E25 -> 495.68712 | G25: =F25*2 -> 991.37424 | J25: 1000 | K25: 12 | L25: 1000 | M25: 751724.48 | N25: =IF(M25>0,(M25*2/1000000),(J25*L25*2/1000000)) -> 1.503449 | O25: =N25*D25*2 -> 21.048285
B26: LG2 | C26: =CONCATENATE("□",J26,"×",K26,"×",L26) -> □1000×24×1000 | D26: 2 | E26: =IF(M26>0,(M26*K26/1000000000*7850),(J26*K26*L26/1000000000*7850)) -> 141.62489 | F26: =D26*E26 -> 283.24978 | G26: =F26*2 -> 566.49957 | J26: 1000 | K26: 24 | L26: 1000 | M26: 751724.48 | N26: =IF(M26>0,(M26*2/1000000),(J26*L26*2/1000000)) -> 1.503449 | O26: =N26*D26*2 -> 6.0137958
B27: HJ5 | C27: =CONCATENATE("□",J27,"×",K27,"×",L27) -> □110×10×1491 | D27: 9 | E27: =IF(M27>0,(M27*K27/1000000000*7850),(J27*K27*L27/1000000000*7850)) -> 12.874785 | F27: =D27*E27 -> 115.87307 | G27: =F27*2 -> 231.74613 | J27: 110 | K27: 10 | L27: 1491 | N27: =IF(M27>0,(M27*2/1000000),(J27*L27*2/1000000)) -> 0.32802 | O27: =N27*D27*2 -> 5.90436
A28: 连梁加劲 | B28: LJ1 | C28: =CONCATENATE("□",J28,"×",K28,"×",L28,"(总长)") -> □140×12×194082(总长) | D28: 1 | E28: =IF(M28>0,(M28*K28/1000000000*7850),(J28*K28*L28/1000000000*7850)) -> 2559.5534 | F28: =D28*E28 -> 2559.5534 | G28: =F28*2 -> 5119.1068 | J28: 140 | K28: 12 | L28: =(23352+25410+48279)*2 -> 194082 | N28: =IF(M28>0,(M28*2/1000000),(J28*L28*2/1000000)) -> 54.34296 | O28: =N28*D28*2 -> 108.68592
A29: 调平钢板 | B29: Z1 | C29: =CONCATENATE("□",J29,"×",K29,"×",L29) -> □931×110×1000 | D29: 1 | E29: =IF(M29>0,(M29*K29/1000000000*7850),(J29*K29*L29/1000000000*7850)) -> 803.9185 | F29: =D29*E29 -> 803.9185 | G29: =F29*2 -> 1607.837 | H29: ZG310-570 | J29: 931 | K29: 110 | L29: 1000 | N29: =IF(M29>0,(M29*2/1000000),(J29*L29*2/1000000)) -> 1.862 | O29: =N29*D29*2 -> 3.724
B30: 合计（kg） | F30: =SUM(F4:F29) -> 36464.243 | G30: =F30*2 -> 72928.485
B31: 焊缝1.5%（kg） | F31: =F30*0.015 -> 546.96364 | G31: =F31*2 -> 1093.9273
B32: 总计（kg） | F32: =F30+F31 -> 37011.206 | G32: =F32*2 -> 74022.413
A33: M16螺栓(个) | F33: =4 -> 4 | G33: =F33*2 -> 8
A34: t=8 橡胶条(m) | F34: 1.9 | G34: =F34*2 -> 3.8
A39: Q355D | B39: 10 | C39: =SUMIF($K$4:$K$29,B39,$G$4:$G$29) -> 439.55604
B40: 12 | C40: =SUMIF($K$4:$K$29,B40,$G$4:$G$29) -> 9619.8105
B41: 24 | C41: =SUMIF($K$4:$K$29,B41,$G$4:$G$29) -> 61182.69
B42: 合计 | C42: =SUM(C39:C41) -> 71242.057
A43: 铸钢 | B43: ZG310-570 | C43: =G29 -> 1607.837 | D43: =SUM(C39:C43) -> 144091.95
A44: 涂装 | B44: 外涂 | C44: =SUM(O4:O5)/2+SUM(O22:O23)/2+O29 -> 159.42012
B45: 内涂 | C45: =SUM(O4:O5)/2+SUM(O22:O23)/2+SUM(O6:O21)+SUM(O25:O28) -> 523.64701

Sheet 拱肋吊点
A2: 单个吊点 | F2: 全桥合计(共38段) | G2: 牌号
A3: 编号 | B3: 规格(mm) | C3: 数量 | D3: 单件重(kg) | E3: 共重(kg) | I3: 短边 | J3: 厚度 | K3: 长边 | L3: 侧面S | M3: 涂装
A4: D1 | B4: =CONCATENATE("□",I4,"×",J4,"×",K4) -> □725×18×1100 | C4: 1 | D4: =IF(L4>0,(L4*J4/1000000000*7850),(I4*J4*K4/1000000000*7850)) -> 82.621088 | E4: =C4*D4 -> 82.621088 | F4: =E4*38 -> 3139.6014 | G4: Q355D | I4: 725 | J4: 18 | K4: 1100 | L4: 584721.08 | M4: =IF(L4>0,(L4*2/1000000),(I4*K4*2/1000000)) -> 1.1694422 | N4: =M4*C4*38 -> 44.438802
A5: D2 | B5: =CONCATENATE("□",I5,"×",J5,"×",K5) -> □400×50×1100 | C5: 2 | D5: =IF(L5>0,(L5*J5/1000000000*7850),(I5*J5*K5/1000000000*7850)) -> 172.7 | E5: =C5*D5 -> 345.4 | F5: =E5*38 -> 13125.2 | I5: 400 | J5: 50 | K5: 1100 | M5: =IF(L5>0,(L5*2/1000000),(I5*K5*2/1000000)) -> 0.88 | N5: =M5*C5*38 -> 66.88
A6: D3 | B6: =CONCATENATE("□",I6,"×",J6,"×",K6) -> □191×28×340 | C6: 4 | D6: =IF(L6>0,(L6*J6/1000000000*7850),(I6*J6*K6/1000000000*7850)) -> 13.012795 | E6: =C6*D6 -> 52.051178 | F6: =E6*38 -> 1977.9448 | I6: 191 | J6: 28 | K6: 340 | L6: 59202.887 | M6: =IF(L6>0,(L6*2/1000000),(I6*K6*2/1000000)) -> 0.11840577 | N6: =M6*C6*38 -> 17.997678
A7: D4 | B7: =CONCATENATE("□",I7,"×",J7,"×",K7) -> □191×28×240 | C7: 6 | D7: =IF(L7>0,(L7*J7/1000000000*7850),(I7*J7*K7/1000000000*7850)) -> 10.075632 | E7: =C7*D7 -> 60.453792 | F7: =E7*38 -> 2297.2441 | I7: 191 | J7: 28 | K7: 240 | M7: =IF(L7>0,(L7*2/1000000),(I7*K7*2/1000000)) -> 0.09168 | N7: =M7*C7*38 -> 20.90304
A8: D5 | B8: =CONCATENATE("□",I8,"×",J8,"×",K8) -> □190×28×400 | C8: 4 | D8: =IF(L8>0,(L8*J8/1000000000*7850),(I8*J8*K8/1000000000*7850)) -> 16.7048 | E8: =C8*D8 -> 66.8192 | F8: =E8*38 -> 2539.1296 | I8: 190 | J8: 28 | K8: 400 | M8: =IF(L8>0,(L8*2/1000000),(I8*K8*2/1000000)) -> 0.152 | N8: =M8*C8*38 -> 23.104
A9: D6 | B9: =CONCATENATE("□",I9,"×",J9,"×",K9) -> □120×18×120 | C9: 4 | D9: =IF(L9>0,(L9*J9/1000000000*7850),(I9*J9*K9/1000000000*7850)) -> 16.158216 | E9: =C9*D9 -> 64.632865 | F9: =E9*38 -> 2456.0489 | I9: 120 | J9: 18 | K9: 120 | L9: 114353.97 | M9: =IF(L9>0,(L9*2/1000000),(I9*K9*2/1000000)) -> 0.22870795 | N9: =M9*C9*38 -> 34.763608
A10: 合计（kg） | E10: =SUM(E4:E9) -> 671.97812 | F10: =E10*38 -> 25535.169
A11: 焊缝1.5%（kg） | E11: =E10*0.015 -> 10.079672 | F11: =E11*38 -> 383.02753
A12: 总计（kg） | E12: =E10+E11 -> 682.0578 | F12: =E12*38 -> 25918.196
A13: 螺栓 | B13: M30 | C13: 16 | F13: =C13*38 -> 608
A17: 单个吊点 | F17: 全桥合计(共8段) | G17: 牌号
A18: 编号 | B18: 规格(mm) | C18: 数量 | D18: 单件重(kg) | E18: 共重(kg)
A19: D1 | B19: =CONCATENATE("□",I19,"×",J19,"×",K19) -> □780×36×820 | C19: 2 | D19: =IF(L19>0,(L19*J19/1000000000*7850),(I19*J19*K19/1000000000*7850)) -> 141.97443 | E19: =C19*D19 -> 283.94886 | F19: =E19*8 -> 2271.5909 | G19: Q355D | I19: 780 | J19: 36 | K19: 820 | L19: 502386.53 | M19: =IF(L19>0,(L19*2/1000000),(I19*K19*2/1000000)) -> 1.0047731 | N19: =M19*C19*8 -> 16.076369
A20: D2 | B20: =CONCATENATE("□",I20,"×",J20,"×",K20) -> □550×50×1600 | C20: 1 | D20: =IF(L20>0,(L20*J20/1000000000*7850),(I20*J20*K20/1000000000*7850)) -> 345.4 | E20: =C20*D20 -> 345.4 | F20: =E20*8 -> 2763.2 | I20: 550 | J20: 50 | K20: 1600 | M20: =IF(L20>0,(L20*2/1000000),(I20*K20*2/1000000)) -> 1.76 | N20: =M20*C20*8 -> 14.08
A21: D2a | B21: =CONCATENATE("□",I21,"×",J21,"×",K21) -> □550×50×750 | C21: 2 | D21: =IF(L21>0,(L21*J21/1000000000*7850),(I21*J21*K21/1000000000*7850)) -> 161.90625 | E21: =C21*D21 -> 323.8125 | F21: =E21*8 -> 2590.5 | I21: 550 | J21: 50 | K21: 750 | M21: =IF(L21>0,(L21*2/1000000),(I21*K21*2/1000000)) -> 0.825 | N21: =M21*C21*8 -> 13.2
A22: D3 | B22: =CONCATENATE("□",I22,"×",J22,"×",K22) -> □257×28×458 | C22: 8 | D22: =IF(L22>0,(L22*J22/1000000000*7850),(I22*J22*K22/1000000000*7850)) -> 23.965648 | E22: =C22*D22 -> 191.72519 | F22: =E22*8 -> 1533.8015 | I22: 257 | J22: 28 | K22: 458 | L22: 109033.89 | M22: =IF(L22>0,(L22*2/1000000),(I22*K22*2/1000000)) -> 0.21806777 | N22: =M22*C22*8 -> 13.956338
A23: D4 | B23: =CONCATENATE("□",I23,"×",J23,"×",K23) -> □257×28×280 | C23: 4 | D23: =IF(L23>0,(L23*J23/1000000000*7850),(I23*J23*K23/1000000000*7850)) -> 15.816808 | E23: =C23*D23 -> 63.267232 | F23: =E23*8 -> 506.13786 | I23: 257 | J23: 28 | K23: 280 | M23: =IF(L23>0,(L23*2/1000000),(I23*K23*2/1000000)) -> 0.14392 | N23: =M23*C23*8 -> 4.60544
A24: D5 | B24: =CONCATENATE("□",I24,"×",J24,"×",K24) -> □190×28×550 | C24: 6 | D24: =IF(L24>0,(L24*J24/1000000000*7850),(I24*J24*K24/1000000000*7850)) -> 22.9691 | E24: =C24*D24 -> 137.8146 | F24: =E24*8 -> 1102.5168 | I24: 190 | J24: 28 | K24: 550 | M24: =IF(L24>0,(L24*2/1000000),(I24*K24*2/1000000)) -> 0.209 | N24: =M24*C24*8 -> 10.032
A25: D6 | B25: =CONCATENATE("□",I25,"×",J25,"×",K25) -> □180×36×180 | C25: 4 | D25: =IF(L25>0,(L25*J25/1000000000*7850),(I25*J25*K25/1000000000*7850)) -> 26.545641 | E25: =C25*D25 -> 106.18256 | F25: =E25*8 -> 849.46052 | I25: 180 | J25: 36 | K25: 180 | L25: 93933.62 | M25: =IF(L25>0,(L25*2/1000000),(I25*K25*2/1000000)) -> 0.18786724 | N25: =M25*C25*8 -> 6.0117517
A26: 合计（kg） | E26: =SUM(E19:E25) -> 1452.1509 | F26: =E26*8 -> 11617.208
A27: 焊缝1.5%（kg） | E27: =E26*0.015 -> 21.782264 | F27: =E27*8 -> 174.25811
A28: 总计（kg） | E28: =E26+E27 -> 1473.9332 | F28: =E28*8 -> 11791.466
A29: 螺栓 | B29: M30 | C29: 24 | F29: =C29*8 -> 192
A35: Q355D | B35: 18 | C35: =SUMIF($J$4:$J$25,B35,$F$4:$F$25) -> 5595.6502
B36: 28 | C36: =SUMIF($J$4:$J$25,B36,$F$4:$F$25) -> 9956.7746
B37: 36 | C37: =SUMIF($J$4:$J$25,B37,$F$4:$F$25) -> 3121.0514
B38: 50 | C38: =SUMIF($J$4:$J$25,B38,$F$4:$F$25) -> 18478.9
B39: 合计 | C39: =SUM(C35:C38) -> 37152.376
A40: M30螺栓 | C40: =F13+F29 -> 800
A41: 涂装 | B41: 外涂 | C41: =SUM(N4:N25) -> 286.04903

Sheet 装饰板
A5: 编号 | B5: 规格(mm) | C5: 数量 | D5: 单件重(kg) | E5: 共重(kg) | I5: 短边 | J5: 厚度 | K5: 长边 | L5: 侧面S | M5: 涂装
A6: Z1 | B6: =CONCATENATE("□",I6,"×",J6,"×",K6) -> □25134×8×86520 | C6: 2 | D6: =IF(L6>0,(L6*J6/1000000000*7850),(I6*J6*K6/1000000000*7850)) -> 27151.112 | E6: =C6*D6 -> 54302.224 | I6: 25134 | J6: 8 | K6: 86520 | L6: 4.3234255e+08 | M6: =IF(L6>0,(L6*2/1000000),(I6*K6*2/1000000)) -> 864.6851 | N6: =M6*C6 -> 1729.3702
A7: Z2 | B7: =CONCATENATE("□",I7,"×",J7,"×",K7) -> □26031×8×88503 | C7: 2 | D7: =IF(L7>0,(L7*J7/1000000000*7850),(I7*J7*K7/1000000000*7850)) -> 28504.818 | E7: =C7*D7 -> 57009.636 | I7: 26031 | J7: 8 | K7: 88503 | L7: 4.5389838e+08 | M7: =IF(L7>0,(L7*2/1000000),(I7*K7*2/1000000)) -> 907.79676 | N7: =M7*C7 -> 1815.5935
A8: A1 | B8: =CONCATENATE("□",I8,"×",J8,"×",K8) -> □100×12×195 | C8: =INT((175126.2538+179616.2918)/500)*2 -> 1418 | D8: =IF(L8>0,(L8*J8/1000000000*7850),(I8*J8*K8/1000000000*7850)) -> 1.8369 | E8: =C8*D8 -> 2604.7242 | I8: 100 | J8: 12 | K8: 195 | M8: =IF(L8>0,(L8*2/1000000),(I8*K8*2/1000000)) -> 0.039 | N8: =M8*C8 -> 55.302
A9: A2 | B9: =CONCATENATE("□",I9,"×",J9,"×",K9) -> □87×12×100 | C9: =C8 -> 1418 | D9: =IF(L9>0,(L9*J9/1000000000*7850),(I9*J9*K9/1000000000*7850)) -> 0.81954 | E9: =C9*D9 -> 1162.1077 | I9: 87 | J9: 12 | K9: 100 | M9: =IF(L9>0,(L9*2/1000000),(I9*K9*2/1000000)) -> 0.0174 | N9: =M9*C9 -> 24.6732
A10: A3 | B10: =CONCATENATE("□",I10,"×",J10,"×",K10) -> □25×12×38 | C10: =C9*4 -> 5672 | D10: =IF(L10>0,(L10*J10/1000000000*7850),(I10*J10*K10/1000000000*7850)) -> 0.08949 | E10: =C10*D10 -> 507.58728 | I10: 25 | J10: 12 | K10: 38 | M10: =IF(L10>0,(L10*2/1000000),(I10*K10*2/1000000)) -> 0.0019 | N10: =M10*C10 -> 10.7768
A11: 合计（kg） | E11: =SUM(E6:E10) -> 115586.28
A12: 焊缝1.5%（kg） | E12: =E11*0.015 -> 1733.7942
A13: 总计（kg） | E13: =E11+E12 -> 117320.07
A17: Q355D | B17: 8 | C17: =SUMIF($J$6:$J$10,B17,$E$6:$E$10) -> 111311.86
B18: 12 | C18: =SUMIF($J$6:$J$10,B18,$E$6:$E$10) -> 4274.4192
B19: 合计 | C19: =SUM(C17:C18) -> 115586.28
A20: 涂装 | B20: 外涂 | C20: =SUM(N6:N10) -> 3635.7157

Sheet 爬梯
A1: 爬梯编号 | B1: α° | C1: H（mm） | D1: L（mm） | E1: A（mm） | F1: B（mm） | G1: C（mm） | H1: 踏步数
A2: N1 | B2: 32.4 | C2: 1496.6 | D2: 2371.4 | E2: 2811.9 | F2: 2807.4 | G2: 2804.2 | H2: =INT(D2/300)+1 -> 8
A3: N2 | B3: 31.6 | C3: 2377.3 | D3: 1461.7 | E3: 2796 | F3: 2793 | G3: 2790.8 | H3: =INT(D3/300)+1 -> 5
A4: N3 | B4: 31 | C4: 2371.6 | D4: 1419.5 | E4: 2771.9 | F4: 2374.5 | G4: 2764 | H4: =INT(D4/300)+1 -> 5
A5: N4 | B5: 30.4 | C5: 2672.5 | D5: 1552.2 | E5: 2677.1 | F5: 2674.4 | G5: 3090.6 | H5: =INT(D5/300)+1 -> 6
A6: N5 | B6: 29.8 | C6: 552.4 | D6: 314.4 | E6: 929 | F6: 759 | G6: 635.6 | H6: =INT(D6/300)+1 -> 2
A7: N6 | B7: 29.5 | C7: 1819.5 | D7: 1021.9 | E7: 1801.5 | F7: 1966.1 | G7: 2086.8 | H7: =INT(D7/300)+1 -> 4
A8: N7 | B8: 28.9 | C8: 2178.8 | D8: 1192.9 | E8: 2489.5 | F8: 2486.3 | G8: 2484 | H8: =INT(D8/300)+1 -> 4
A9: N8 | B9: 28.3 | C9: 2182.9 | D9: 1162.4 | E9: 2478.7 | F9: 2475.5 | G9: 2473.2 | H9: =INT(D9/300)+1 -> 4
A10: N9 | B10: 27.7 | C10: 1127.8 | D10: 2179.2 | E10: 2459.4 | F10: 2456.1 | G10: 2453.7 | H10: =INT(D10/300)+1 -> 8
A11: N10 | B11: 26.8 | C11: 326.3 | D11: 643.4 | E11: 982 | F11: 832 | G11: 721.4 | H11: =INT(D11/300)+1 -> 3
A12: N11 | B12: 26.8 | C12: 1741.3 | D12: 869.8 | E12: 1680 | F12: 1825.9 | G12: 2303.7 | H12: =INT(D12/300)+1 -> 3
A13: N12 | B13: 26.2 | C13: 1270.9 | D13: 621.2 | E13: 2531 | F13: 2408.4 | G13: 2176.1 | H13: =INT(D13/300)+1 -> 3
... A50: N49 | B50: 1.5 | C50: 53.9 | D50: 2191.2 | E50: 2199 | F50: 2194.9 | G50: 2191.9 | H50: =INT(D50/300)+1 -> 8
A51: N50 | B51: 0.7 | C51: 15.9 | D51: 1193.7 | E51: =1186.15*2 -> 2372.3 | F51: =1186*2 -> 2372 | G51: =1187.2*2 -> 2374.4 | H51: =INT(D51/300)+1 -> 4
A53: M1 | B53: 23.3 | C53: 614.5 | D53: 1250.2 | E53: 1394.7 | F53: 1393.8 | G53: 1393 | H53: =INT(D53/300)+1 -> 5
A54: M2 | B54: 26.1 | C54: 632.3 | D54: 1299.3 | E54: 1446.6 | F54: 1445.7 | G54: 1445 | H54: =INT(D54/300)+1 -> 5
A55: M3 | B55: 25.7 | C55: 958.7 | D55: 1998.5 | E55: 2213 | F55: 2218 | G55: 2216.5 | H55: =INT(D55/300)+1 -> 7
A56: M4 | B56: 25.3 | C56: 942.5 | D56: 1998.5 | E56: 2213 | F56: 2211 | G56: 2209.6 | H56: =INT(D56/300)+1 -> 7
A57: M5 | B57: 25 | C57: 695.3 | D57: 1497.7 | E57: 1654.7 | F57: 1652.7 | G57: 1651.3 | H57: =INT(D57/300)+1 -> 5
A58: M6 | B58: 24.8 | C58: 1141 | D58: 2498.5 | E58: 2751.9 | F58: 2748.9 | G58: 2746.7 | H58: =INT(D58/300)+1 -> 9
A59: M7 | B59: 24.2 | C59: 1114.5 | D59: 2497.7 | E59: 2738.6 | F59: 2736.6 | G59: 2735.1 | H59: =INT(D59/300)+1 -> 9
A60: M8 | B60: 23.8 | C60: 1090.4 | D60: 2497.7 | E60: 2730.6 | F60: 2727.5 | G60: 2725.3 | H60: =INT(D60/300)+1 -> 9
A61: M9 | B61: 23.2 | C61: 1064.5 | D61: 2498.4 | E61: 2719.8 | F61: 2717.3 | G61: 2715.8 | H61: =INT(D61/300)+1 -> 9
A62: M10 | B62: 22.8 | C62: 1040 | D62: 2497.6 | E62: 2710.9 | F62: 2707.8 | G62: 2705.5 | H62: =INT(D62/300)+1 -> 9
A63: M11 | B63: 22.3 | C63: 1014 | D63: 2498 | E63: 2700 | F63: 2698 | G63: 2696.4 | H63: =INT(D63/300)+1 -> 9
A64: M12 | B64: 21.9 | C64: 990 | D64: 2498 | E64: 2691 | F64: 2688.9 | G64: 2687.4 | H64: =INT(D64/300)+1 -> 9
... A90: M38 | B90: 9.7 | C90: 321.3 | D90: 1918.7 | E90: 1949.5 | F90: 1947.2 | G90: 1945.4 | H90: =INT(D90/300)+1 -> 7
A95: 主拱
A96: 编号 | B96: 规格(mm) | C96: 数量 | D96: 单件重(kg) | E96: 共重(kg) | I96: 短边 | J96: 厚度 | K96: 长边 | L96: 侧面S | M96: 涂装
A97: 槽钢 | B97: =CONCATENATE(I97,"×",J97,"×",K97,"(均1986)") -> 70×10×180(均1986) | C97: =100*4 -> 400 | D97: =3165.0229/1000000*1.986*7850 -> 49.343024 | E97: =C97*D97 -> 19737.209 | I97: 70 | J97: 10 | K97: 180 | M97: =605.5952/1000*1.986 -> 1.2027121 | N97: =M97*C97 -> 481.08483
A98: 扶手钢管 | B98: φ40×4(均1978) | C98: =200*4 -> 800 | D98: =552.9203/1000000*1.978*7850 -> 8.5853594 | E98: =C98*D98 -> 6868.2875 | M98: =(125.66371+106.81415)/1000*1.978 -> 0.45984121 | N98: =M98*C98 -> 367.87297
A99: 菱形花纹踏板 | B99: =CONCATENATE("□",I99,"×",J99,"×",K99) -> □316×6×700 | C99: =SUM(H2:H51)*4 -> 1188 | D99: =IF(L99>0,(L99*J99/1000000000*7850),(I99*J99*K99/1000000000*7850)) -> 10.41852 | E99: =C99*D99 -> 12377.202 | I99: 316 | J99: 6 | K99: 700 | M99: =IF(L99>0,(L99*2/1000000),(I99*K99*2/1000000)) -> 0.4424 | N99: =M99*C99 -> 525.5712
A100: 合计（kg） | E100: =SUM(E97:E99) -> 38982.699
A101: 焊缝1.5%（kg） | E101: =E100*0.015 -> 584.74048
A102: 总计（kg） | E102: =E100+E101 -> 39567.439
A104: 副拱
A105: 编号 | B105: 规格(mm) | C105: 数量 | D105: 单件重(kg) | E105: 共重(kg) | I105: 短边 | J105: 厚度 | K105: 长边 | L105: 侧面S | M105: 涂装
A106: 槽钢 | B106: =CONCATENATE(I106,"×",J106,"×",K106,"(均2277)") -> 70×10×180(均2277) | C106: =38*2*4 -> 304 | D106: =3165.0229/1000000*2.277*7850 -> 56.573044 | E106: =C106*D106 -> 17198.205 | I106: 70 | J106: 10 | K106: 180 | M106: =605.5952/1000*1.986 -> 1.2027121 | N106: =M106*C106 -> 365.62447
A107: 扶手钢管 | B107: φ40×4(均2280) | C107: =38*4*4 -> 608 | D107: =552.9203/1000000*2.28*7850 -> 9.8961675 | E107: =C107*D107 -> 6016.8699 | M107: =(125.66371+106.81415)/1000*1.978 -> 0.45984121 | N107: =M107*C107 -> 279.58345
...

Sheet 拱肋数量汇总表
A6: 材料名称 | B6: 规格 | E6: 单位 | F6: 主拱肋 | G6: 副拱 | H6: 吊点 | I6: 装饰板 | J6: 横撑 | K6: 匹配件 | L6: 爬梯 | M6: 工地连接 | N6: 合计
A7: 钢材 | B7: Q355D | D7: t=8 | E7: kg | I7: =装饰板!C17 -> 111311.86 | N7: =SUM(F7:M7) -> 111311.86
D8: t=10 | E8: kg | G8: ='C1节段'!C43+'C2节段'!C39+'C3节段'!C19+'C4节段'!C41+'C5节段'!C39 -> 2426.7804 | N8: =SUM(F8:M8) -> 2426.7804
D9: t=12 | E9: kg | F9: 31443.8 | G9: ='C1节段'!C44+'C2节段'!C40+'C3节段'!C20+'C4节段'!C42+'C5节段'!C40 -> 63832.02 | I9: =装饰板!C18 -> 4274.4192 | J9: 8263.1 | K9: 2089 | N9: =SUM(F9:M9) -> 109902.34
D10: t=16 | E10: kg | F10: 66140.7 | G10: ='C1节段'!C45+'C2节段'!C41+'C3节段'!C21 -> 163083.59 | J10: 21858.9 | K10: 4642.2 | N10: =SUM(F10:M10) -> 255725.39
D11: t=18 | E11: kg | H11: =拱肋吊点!C35 -> 5595.6502 | N11: =SUM(F11:M11) -> 5595.6502
D12: t=20 | E12: kg | G12: ='C1节段'!C46+'C2节段'!C42 -> 4381.3857 | N12: =SUM(F12:M12) -> 4381.3857
D13: t=24 | E13: kg | F13: 303644.9 | G13: ='C1节段'!C47+'C4节段'!C43+'C5节段'!C41 -> 160201.88 | J13: 36165 | M13: 12154.1 | N13: =SUM(F13:M13) -> 512165.88
D14: t=28 | E14: kg | F14: 299071.3 | H14: =拱肋吊点!C36 -> 9956.7746 | J14: 23447.9 | M14: 2363.3 | N14: =SUM(F14:M14) -> 334839.27
D15: t=32 | E15: kg | F15: 199020.7 | G15: ='C1节段'!C48+'C2节段'!C43 -> 36466.633 | N15: =SUM(F15:M15) -> 235487.33
D16: t=36 | E16: kg | F16: 336022.3 | H16: =拱肋吊点!C37 -> 3121.0514 | N16: =SUM(F16:M16) -> 339143.35
D17: t=40 | E17: kg | F17: 266923.4 | N17: =SUM(F17:M17) -> 266923.4
D18: t=42 | E18: kg | K18: 6092.9 | N18: =SUM(F18:M18) -> 6092.9
D19: t=50 | E19: kg | F19: 136351.1 | H19: =拱肋吊点!C38 -> 18478.9 | N19: =SUM(F19:M19) -> 154830
D20: t=60 | E20: kg | F20: 38724.7 | N20: =SUM(F20:M20) -> 38724.7
B21: Q235B | D21: t=4 | E21: kg | L21: =爬梯!C114 -> 12885.157 | N21: =SUM(F21:M21) -> 12885.157
D22: t=6 | E22: kg | L22: =爬梯!C115 -> 22914.791 | N22: =SUM(F22:M22) -> 22914.791
D23: t=10 | E23: kg | L23: =爬梯!C116 -> 36935.415 | N23: =SUM(F23:M23) -> 36935.415
B24: 30Mn | D24: t=282 | E24: kg | G24: ='C1节段'!C50+'C2节段'!C45 -> 15443.305 | N24: =SUM(F24:M24) -> 15443.305
B25: S355N | D25: t=40 | E25: kg | G25: ='C1节段'!C51+'C2节段'!C46 -> 5609.1549 | N25: =SUM(F25:M25) -> 5609.1549
D26: t=50 | E26: kg | G26: ='C1节段'!C52+'C2节段'!C47 -> 3156.6723 | N26: =SUM(F26:M26) -> 3156.6723
B27: 40Cr | D27: D200 | E27: kg | G27: ='C1节段'!C53+'C2节段'!C48 -> 1104.8353 | N27: =SUM(F27:M27) -> 1104.8353
B28: ZG310-570 | D28: t=110 | E28: kg | G28: ='C4节段'!C45+'C5节段'!C43 -> 3215.674 | N28: =SUM(F28:M28) -> 3215.674
B29: 小计 | E29: kg | F29: =SUM(F7:F28) -> 1677342.9 | G29: =SUM(G7:G28) -> 458921.93 | H29: =SUM(H7:H28) -> 37152.376 | I29: =SUM(I7:I28) -> 115586.28 | J29: =SUM(J7:J28) -> 89734.9 | K29: =SUM(K7:K28) -> 12824.1 | L29: =SUM(L7:L28) -> 72735.363 | M29: =SUM(M7:M28) -> 14517.4 | N29: =SUM(F29:M29) -> 2478815.2
A30: 螺栓 | B30: M30 | E30: 套 | H30: =拱肋吊点!C40 -> 800 | N30: =SUM(F30:M30) -> 800
A31: 涂装 | B31: 外表面涂装 | E31: m2 | F31: 7807 | G31: ='C1节段'!C54+'C2节段'!C49+'C3节段'!C23+'C4节段'!C46+'C5节段'!C44 -> 5778.443 | H31: =拱肋吊点!C41 -> 286.04903 | I31: =装饰板!C20 -> 3635.7157 | J31: 472.7 | N31: =SUM(F31:M31) -> 17979.908
B32: 内表面涂装 | E32: m2 | F32: 4393.5 | G32: ='C1节段'!C55+'C2节段'!C50+'C3节段'!C24+'C4节段'!C47+'C5节段'!C45 -> 32210.001 | J32: 560.4 | L32: =爬梯!C118 -> 2467.1929 | N32: =SUM(F32:M32) -> 39631.094
