Workbook

Sheet Sheet1
A5: 材料名称 | B5: 规格 | E5: 单位 | F5: 上部结构 | G5: 下部结构 | H5: 拱肋 | I5: 桥面系 | J5: 合计
A6: 混凝土 | B6: C40 | E6: m3 | G6: =[1]主桥下部数量表!$L$5 -> 473.39648 | J6: =SUM(F6:I6) -> 473.39648
B7: C35 | E7: m3 | G7: =[1]主桥下部数量表!$L$6 -> 805.048 | J7: =SUM(F7:I7) -> 805.048
B8: C35水下 | E8: m3 | G8: =[1]主桥下部数量表!$L$7 -> 3513.1 | J8: =SUM(F8:I8) -> 3513.1
B9: C25封底混凝土 | E9: m3 | G9: =[1]主桥下部数量表!$L$8 -> 241.5144 | J9: =SUM(F9:I9) -> 241.5144
A10: 钢筋 | B10: HRB400 | D10: 32 | E10: kg | G10: =[1]主桥下部数量表!$L$14 -> 31996.38 | J10: =SUM(F10:I10) -> 31996.38
D11: 28 | E11: kg | G11: =[1]主桥下部数量表!$L$15 -> 91471.892 | J11: =SUM(F11:I11) -> 91471.892
D12: 25 | E12: kg | G12: =[1]主桥下部数量表!$L$16 -> 198927.7 | J12: =SUM(F12:I12) -> 198927.7
D13: 20 | E13: kg | G13: =[1]主桥下部数量表!$L$17 -> 6130.0262 | J13: =SUM(F13:I13) -> 6130.0262
D14: 16 | E14: kg | G14: =[1]主桥下部数量表!$L$18 -> 39222.618 | J14: =SUM(F14:I14) -> 39222.618
D15: 12 | E15: kg | G15: =[1]主桥下部数量表!$L$19 -> 2024.9757 | J15: =SUM(F15:I15) -> 2024.9757
B16: HPB300 | D16: 10 | E16: kg | G16: =[1]主桥下部数量表!$L$20 -> 45566.712 | J16: =SUM(F16:I16) -> 45566.712
A17: 12冷轧带肋钢筋网 | E17: kg | G17: =[1]主桥下部数量表!$L$22 -> 5715.8408 | J17: =SUM(F17:I17) -> 5715.8408
A18: 钢材 | B18: Q355D | D18: t=8 | E18: kg | H18: =[2]拱肋数量汇总表!$N$7 -> 111311.86 | J18: =SUM(F18:I18) -> 111311.86
D19: t=10 | E19: kg | F19: =[3]主梁工程数量表!$K$3 -> 31868.064 | H19: =[2]拱肋数量汇总表!$N$8 -> 2426.7804 | J19: =SUM(F19:I19) -> 34294.845
D20: t=12 | E20: kg | F20: =[3]主梁工程数量表!$K$4 -> 696185.45 | H20: =[2]拱肋数量汇总表!$N$9 -> 109902.34 | J20: =SUM(F20:I20) -> 806087.79
D21: t=14 | E21: kg | F21: =[3]主梁工程数量表!$K$5 -> 237040.76 | J21: =SUM(F21:I21) -> 237040.76
D22: t=16 | E22: kg | F22: =[3]主梁工程数量表!$K$6 -> 1231149.2 | H22: =[2]拱肋数量汇总表!$N$10 -> 255725.39 | J22: =SUM(F22:I22) -> 1486874.5
D23: t=18 | E23: kg | H23: =[2]拱肋数量汇总表!$N$11 -> 5595.6502 | J23: =SUM(F23:I23) -> 5595.6502
D24: t=20 | E24: kg | F24: =[3]主梁工程数量表!$K$7 -> 40713.102 | H24: =[2]拱肋数量汇总表!$N$12 -> 4381.3857 | J24: =SUM(F24:I24) -> 45094.488
D25: t=24 | E25: kg | F25: =[3]主梁工程数量表!$K$8 -> 136557.4 | H25: =[2]拱肋数量汇总表!$N$13 -> 512165.88 | J25: =SUM(F25:I25) -> 648723.27
D26: t=28 | E26: kg | F26: =[3]主梁工程数量表!$K$9 -> 382736.8 | H26: =[2]拱肋数量汇总表!$N$14 -> 334839.27 | J26: =SUM(F26:I26) -> 717576.08
D27: t=32 | E27: kg | F27: =[3]主梁工程数量表!$K$10 -> 123645.59 | H27: =[2]拱肋数量汇总表!$N$15 -> 235487.33 | J27: =SUM(F27:I27) -> 359132.92
D28: t=36 | E28: kg | F28: =[3]主梁工程数量表!$K$11 -> 178455.6 | H28: =[2]拱肋数量汇总表!$N$16 -> 339143.35 | J28: =SUM(F28:I28) -> 517598.96
D29: t=40 | E29: kg | F29: =[3]主梁工程数量表!$K$12 -> 180689.7 | H29: =[2]拱肋数量汇总表!$N$17 -> 266923.4 | J29: =SUM(F29:I29) -> 447613.1
D30: t=42 | E30: kg | F30: =[3]主梁工程数量表!$K$13 -> 10531.937 | H30: =[2]拱肋数量汇总表!$N$18 -> 6092.9 | J30: =SUM(F30:I30) -> 16624.837
D31: t=50 | E31: kg | F31: =[3]主梁工程数量表!$K$14 -> 56340.605 | H31: =[2]拱肋数量汇总表!$N$19 -> 154830 | J31: =SUM(F31:I31) -> 211170.61
D32: t=60 | E32: kg | F32: =[3]主梁工程数量表!$K$15 -> 5631.428 | H32: =[2]拱肋数量汇总表!$N$20 -> 38724.7 | J32: =SUM(F32:I32) -> 44356.128
D33: U型肋(t=8) | E33: kg | F33: =[3]主梁工程数量表!$K$16 -> 5907.1383 | J33: =SUM(F33:I33) -> 5907.1383
B34: Q355C | D34: t=5 | E34: kg | I34: =[4]桥面系工程数量汇总!$P$23 -> 264706.8 | J34: =SUM(F34:I34) -> 264706.8
D35: t=8 | E35: kg | I35: =[4]桥面系工程数量汇总!$P$24 -> 1656 | J35: =SUM(F35:I35) -> 1656
D36: t=10 | E36: kg | I36: =[4]桥面系工程数量汇总!$P$25 -> 2870.4 | J36: =SUM(F36:I36) -> 2870.4
D37: t=12 | E37: kg | I37: =[4]桥面系工程数量汇总!$P$26 -> 6900 | J37: =SUM(F37:I37) -> 6900
D38: t=14 | E38: kg | I38: =[4]桥面系工程数量汇总!$P$27 -> 1048.8 | J38: =SUM(F38:I38) -> 1048.8
D39: t=50 | E39: kg | I39: =[4]桥面系工程数量汇总!$P$28 -> 26233.8 | J39: =SUM(F39:I39) -> 26233.8
B40: Q235B | D40: t=4 | E40: kg | H40: =[2]拱肋数量汇总表!$N$21 -> 12885.157 | I40: =[4]桥面系工程数量汇总!$P$9 -> 41604.457 | J40: =SUM(F40:I40) -> 54489.614
D41: t=6 | E41: kg | H41: =[2]拱肋数量汇总表!$N$22 -> 22914.791 | I41: =[4]桥面系工程数量汇总!$P$10 -> 1366.2372 | J41: =SUM(F41:I41) -> 24281.028
D42: t=8 | E42: kg | I42: =[4]桥面系工程数量汇总!$P$11 -> 61387.2 | J42: =SUM(F42:I42) -> 61387.2
D43: t=10 | E43: kg | H43: =[2]拱肋数量汇总表!$N$23 -> 36935.415 | I43: =[4]桥面系工程数量汇总!$P$12 -> 59934.545 | J43: =SUM(F43:I43) -> 96869.959
D44: t=12 | E44: kg | I44: =[4]桥面系工程数量汇总!$P$13 -> 22288.5 | J44: =SUM(F44:I44) -> 22288.5
...
