Workbook

Sheet 排水
A2: 横向一组泄水孔数量 | G2: 全桥合计(共41组）
A3: 名称及编号 | C3: 规格(mm) | D3: 数量 | E3: 单件重(kg) | F3: 共重(kg) | I3: 涂装
A4: 横向排水管 | C4: φ150×8×6410 | D4: 2 | E4: =3568.8493/1000000*(6410/1000)*7850 -> 179.57914 | F4: =D4*E4 -> 359.15829 | G4: =F4*41 -> 14725.49 | H4: Q235B | I4: =(PI()*150+PI()*142)*6410/1000000 -> 5.8801818 | J4: =I4*D4*41 -> 482.17491
A5: 吊架1 | C5: □65×6×2366 | D5: 4 | E5: =2366*6*65/1000000000*7850 -> 7.243509 | F5: =D5*E5 -> 28.974036 | G5: =F5*41 -> 1187.9355 | I5: =0.065*2.366*2 -> 0.30758 | J5: =I5*D5*41 -> 50.44312
A6: 雨水篦子 | C6: D150×16 | D6: 2 | E6: =0.0177*0.0016*7850 -> 0.222312 | F6: =D6*E6 -> 0.444624 | G6: =F6*41 -> 18.229584 | I6: =PI()*150*2/1000000 -> 0.0009424778 | J6: =I6*D6*41 -> 0.077283179
A7: A1 | C7: □166×15×288 | D7: 2 | E7: =0.166*0.015*0.288*7850 -> 5.629392 | F7: =D7*E7 -> 11.258784 | G7: =F7*41 -> 461.61014 | I7: =0.166*0.288*2 -> 0.095616 | J7: =I7*D7*41 -> 7.840512
A8: A2 | C8: □206×50×328 | D8: 2 | E8: =33264/1000000*(50/1000)*7850 -> 13.05612 | F8: =D8*E8 -> 26.11224 | G8: =F8*41 -> 1070.6018 | I8: =0.206*0.328*2 -> 0.135136 | J8: =I8*D8*41 -> 11.081152
A9: 弯头1 | C9: φ150×150 | D9: 2 | G9: =D9*41 -> 82
A10: 三通1 | C10: φ150×150×150 | D10: 2 | G10: =D10*41 -> 82
A11: 三通2 | C11: φ150×377×377 | D11: 2 | G11: =D11*41 -> 82
A12: 聚酯螺旋排水管 | C12: D8×130 | D12: 2 | G12: =D12*41 -> 82
A19: 名称及编号 | C19: 规格(mm) | D19: 数量 | E19: 单件重(kg) | F19: 共重(kg)
A20: 纵向集水管 | C20: φ377×8×20376(全长) | D20: 2 | E20: =9273.9815/1000000*(20376/1000)*7850 -> 1483.3882 | F20: =D20*E20 -> 2966.7764 | G20: Q235B | I20: =(PI()*377+PI()*369)*20376/1000000 -> 47.753767 | J20: =I20*D20 -> 95.507533
A21: 吊架2 | C21: □65×6×1120 | D21: =13*4 -> 52 | E21: =1120*6*65/1000000000*7850 -> 3.42888 | F21: =D21*E21 -> 178.30176 | I21: =0.065*1.12*2 -> 0.1456 | J21: =I21*D21 -> 7.5712
A22: 弯头2 | C22: φ377×377 | D22: =2*4 -> 8
A23: 法兰伸缩器 | C23: YSSJA-2法兰限位伸缩器 | D23: 4
A27: φ150×8 | B27: =G4 -> 14725.49
A28: φ377×8 | B28: =F20 -> 2966.7764
A29: 6 | B29: =G5+F21 -> 1366.2372
A30: 15 | B30: =G7 -> 461.61014
A31: 16 | B31: =G6 -> 18.229584
A32: 50 | B32: =G8 -> 1070.6018
A33: 外涂 | B33: =SUM(J4:J21)*0.7 -> 458.287
A34: 内涂 | B34: =SUM(J4:J21)*0.3 -> 196.40871

Sheet 伸缩缝
A11: 伸缩缝 | B11: 车行 | C11: 240型 | D11: 49/2
B12: 人行 | C12: - | D12: 40.6/8
A13: 钢材(Q235B) | B13: N1 | C13: =CONCATENATE("□",580,"×",20) -> □580×20 | D13: =(6787.5/1000000)*40.6*7850 -> 2163.2441 | E13: =D13+D14 -> 4568.7079
B14: N2 | C14: =CONCATENATE("□",618,"×",20) -> □618×20 | D14: =(7547.5/1000000)*40.6*7850 -> 2405.4637
B15: N3 | C15: =CONCATENATE("□",138,"×",16,"×",144) -> □138×16×144 | D15: =162*15172/1000000*0.016*7850 -> 308.70772
B16: N4 | C16: M16螺栓(套) | D16: 162
A17: 氯丁橡胶止水带 | C17: 50×959 | D17: 40.6

Sheet 人行护栏
A3: 编号 | B3: 规格(mm) | C3: 数量 | D3: 单件重(kg) | E3: 共重(kg) | F3: 牌号 | H3: 短边 | I3: 厚度 | J3: 长边 | K3: 侧面S | L3: 涂装
A4: A1 | B4: =CONCATENATE("D",H4,"×",I4,"×",J4) -> D108×4×1200 | C4: 416 | D4: =2513.2741/1000000*1.2*7850 -> 23.675042 | E4: =C4*D4 -> 9848.8175 | F4: Q235B | H4: 108 | I4: 4 | J4: 1200 | L4: =339.292/1000*1.2 -> 0.4071504 | M4: =289.0265/1000*1.2 -> 0.3468318 | N4: =(L4+M4)*C4 -> 313.6566
A5: A2 | B5: =CONCATENATE("□",H5,"×",I5,"×",J5) -> □10×4×1004 | C5: =(18*101+5*2+2)*4 -> 7320 | D5: =IF(K5>0,(K5*I5/1000000000*7850),(H5*I5*J5/1000000000*7850)) -> 0.315256 | E5: =C5*D5 -> 2307.6739 | H5: 10 | I5: 4 | J5: 1004 | L5: =IF(K5>0,(K5*2/1000000),(H5*J5*2/1000000)) -> 0.02008 | N5: =(L5+M5)*C5 -> 146.9856
A6: A3 | B6: =CONCATENATE("□",H6,"×",I6,"×",J6,"(平均)") -> □10×4×1040(平均) | C6: =2*C5 -> 14640 | D6: =IF(K6>0,(K6*I6/1000000000*7850),(H6*I6*J6/1000000000*7850)) -> 0.32656 | E6: =C6*D6 -> 4780.8384 | H6: 10 | I6: 4 | J6: 1040 | L6: =IF(K6>0,(K6*2/1000000),(H6*J6*2/1000000)) -> 0.0208 | N6: =(L6+M6)*C6 -> 304.512
A7: A4 | B7: =CONCATENATE("□",H7,"×",I7,"×",J7,"(平均)") -> □10×4×59(平均) | C7: =C5*10 -> 73200 | D7: =IF(K7>0,(K7*I7/1000000000*7850),(H7*I7*J7/1000000000*7850)) -> 0.018526 | E7: =C7*D7 -> 1356.1032 | H7: 10 | I7: 4 | J7: 59 | L7: =IF(K7>0,(K7*2/1000000),(H7*J7*2/1000000)) -> 0.00118 | N7: =(L7+M7)*C7 -> 86.376
A8: B1 | B8: =CONCATENATE("D",H8,"×",I8,"×",J8) -> D108×4×7994 | C8: 50 | D8: =2513.2741/1000000*(J8/1000)*7850 -> 157.71524 | E8: =C8*D8 -> 7885.7619 | H8: 108 | I8: 4 | J8: =8000-6 -> 7994 | L8: =339.292/1000*8 -> 2.714336 | M8: =289.0265/1000*(J8/1000) -> 2.3104778 | N8: =(L8+M8)*C8 -> 251.24069
A9: B1a | B9: =CONCATENATE("□",H9,"×",I9,"×",J9) -> □108×4×3922 | C9: 100 | D9: =2513.2741/1000000*(J9/1000)*7850 -> 77.377929 | E9: =C9*D9 -> 7737.7929 | H9: 108 | I9: 4 | J9: =8000/2-3-75 -> 3922 | L9: =339.292/1000*3.992 -> 1.3544537 | M9: =289.0265/1000*(J9/1000) -> 1.1335619 | N9: =(L9+M9)*C9 -> 248.80156
A10: B1b | B10: =CONCATENATE("□",H10,"×",I10,"×",J10) -> □108×4×2007 | C10: 4 | D10: =2513.2741/1000000*(J10/1000)*7850 -> 39.596508 | E10: =C10*D10 -> 158.38603 | H10: 108 | I10: 4 | J10: 2007 | L10: =339.292/1000*1.987 -> 0.6741732 | M10: =289.0265/1000*(J10/1000) -> 0.58007619 | N10: =(L10+M10)*C10 -> 5.0169976 | T10: 参数 | V10: 变化点1 | W10: 变化点2 | X10: 变化点3 | Y10: 变化点4
A11: B1c | B11: =CONCATENATE("□",H11,"×",I11,"×",J11) -> □108×4×2017 | C11: 4 | D11: =2513.2741/1000000*(J11/1000)*7850 -> 39.7938 | E11: =C11*D11 -> 159.1752 | H11: 108 | I11: 4 | J11: 2017 | L11: =339.292/1000*1.977 -> 0.67078028 | M11: =289.0265/1000*(J11/1000) -> 0.58296645 | N11: =(L11+M11)*C11 -> 5.0149869 | T11: α | U11: ° | V11: 174.2 | W11: 174.2 | X11: 174.4 | Y11: 174.4
A12: B1d | B12: =CONCATENATE("□",H12,"×",I12,"×",J12) -> □96×4×96 | C12: 8 | D12: =1156.1061/1000000*(J12/1000)*7850 -> 0.87124156 | E12: =C12*D12 -> 6.9699325 | H12: 96 | I12: 4 | J12: 96 | L12: =339.292/1000*1.977 -> 0.67078028 | M12: =289.0265/1000*(J12/1000) -> 0.027746544 | N12: =(L12+M12)*C12 -> 5.5882146 | T12: L1 | U12: mm | V12: =6368-3-5 -> 6360 | W12: =1626-3-5 -> 1618 | X12: =5379-3-5 -> 5371 | Y12: =1759-3-5 -> 1751
A13: B2 | B13: =CONCATENATE("D",H13,"×",I13,"×",J13) -> D84×4×7994 | C13: 50 | D13: =1005.3096/1000000*(J13/1000)*7850 -> 63.086093 | E13: =C13*D13 -> 3154.3046 | H13: 84 | I13: 4 | J13: =J8 -> 7994 | L13: =263.8938/1000*(J13/1000) -> 2.109567 | M13: =238.761/1000*(J13/1000) -> 1.9086554 | N13: =(L13+M13)*C13 -> 200.91112 | T13: L2 | U13: mm | V13: =(8000-6-10)-V12 -> 1624 | W13: =(8000-6-10)-W12 -> 6366 | X13: =(8000-6-10)-X12 -> 2613 | Y13: =(8000-6-10)-Y12 -> 6233
A14: B2a | B14: =CONCATENATE("D",H14,"×",I14,"×",J14) -> D84×4×3922 | C14: 100 | D14: =1005.3096/1000000*(J14/1000)*7850 -> 30.95117 | E14: =C14*D14 -> 3095.117 | H14: 84 | I14: 4 | J14: =J9 -> 3922 | L14: =263.8938/1000*(J14/1000) -> 1.0349915 | M14: =238.761/1000*(J14/1000) -> 0.93642064 | N14: =(L14+M14)*C14 -> 197.14121
A15: B2b | B15: =CONCATENATE("D",H15,"×",I15,"×",J15) -> D84×4×2007 | C15: 4 | D15: =1005.3096/1000000*(J15/1000)*7850 -> 15.838602 | E15: =C15*D15 -> 63.35441 | H15: 84 | I15: 4 | J15: =J10 -> 2007 | L15: =263.8938/1000*(J15/1000) -> 0.52963486 | M15: =238.761/1000*(J15/1000) -> 0.47919333 | N15: =(L15+M15)*C15 -> 4.0353127
A16: B2c | B16: =CONCATENATE("D",H16,"×",I16,"×",J16) -> D84×4×2017 | C16: 4 | D16: =1005.3096/1000000*(J16/1000)*7850 -> 15.917519 | E16: =C16*D16 -> 63.670077 | H16: 84 | I16: 4 | J16: =J11 -> 2017 | L16: =263.8938/1000*(J16/1000) -> 0.53227379 | M16: =238.761/1000*(J16/1000) -> 0.48158094 | N16: =(L16+M16)*C16 -> 4.0554189
A17: B2d | B17: =CONCATENATE("D",H17,"×",I17,"×",J17) -> D72×4×72 | C17: 8 | D17: =854.5132/1000000*(J17/1000)*7850 -> 0.48297086 | E17: =C17*D17 -> 3.8637669 | H17: 72 | I17: 4 | J17: 72 | L17: =263.8938/1000*(J17/1000) -> 0.019000354 | M17: =238.761/1000*(J17/1000) -> 0.017190792 | N17: =(L17+M17)*C17 -> 0.28952916
A18: B3 | B18: =CONCATENATE("□",H18,"×",I18,"×",J18) -> □100×4×100 | C18: =SUM(C8:C11) -> 158 | D18: =7853.9816/1000000*0.004*7850 -> 0.24661502 | E18: =C18*D18 -> 38.965174 | H18: 100 | I18: 4 | J18: 100 | L18: =7853.9816/1000000 -> 0.0078539816 | M18: =7853.9816/1000000 -> 0.0078539816 | N18: =(L18+M18)*C18 -> 2.4818582
A19: B4 | B19: =CONCATENATE("□",H19,"×",I19,"×",J19) -> □76×4×76 | C19: =SUM(C13:C16) -> 158 | D19: =4536.4598/1000000*0.004*7850 -> 0.14244484 | E19: =C19*D19 -> 22.506284 | H19: 76 | I19: 4 | J19: 76 | L19: =4536.4598/1000000 -> 0.0045364598 | M19: =4536.4598/1000000 -> 0.0045364598 | N19: =(L19+M19)*C19 -> 1.4335213
A20: C1 | B20: =CONCATENATE("□",H20,"×",I20,"×",J20) -> □765×10×8000 | C20: 50 | D20: =7488.6083/1000000*(J20/1000)*7850 -> 470.2846 | E20: =C20*D20 -> 23514.23 | H20: 765 | I20: 10 | J20: 8000 | L20: =H20*J20/1000000 -> 6.12 | M20: =723*J20/1000000 -> 5.784 | N20: =(L20+M20)*C20 -> 595.2
A21: C1a | B21: =CONCATENATE("□",H21,"×",I21,"×",J21) -> □765×10×2010 | C21: 2 | D21: =7488.6083/1000000*(J21/1000)*7850 -> 118.15901 | E21: =C21*D21 -> 236.31801 | H21: 765 | I21: 10 | J21: =2130-120 -> 2010 | L21: =H21*J21/1000000 -> 1.53765 | M21: =723*J21/1000000 -> 1.45323 | N21: =(L21+M21)*C21 -> 5.98176
A22: C1b | B22: =CONCATENATE("□",H22,"×",I22,"×",J22) -> □765×10×2020 | C22: 2 | D22: =7488.6083/1000000*(J22/1000)*7850 -> 118.74686 | E22: =C22*D22 -> 237.49372 | H22: 765 | I22: 10 | J22: =2140-120 -> 2020 | L22: =H22*J22/1000000 -> 1.5453 | M22: =723*J22/1000000 -> 1.46046 | N22: =(L22+M22)*C22 -> 6.01152
A23: C2 | B23: =CONCATENATE("□",H23,"×",I23,"×",J23) -> □466×10×192 | C23: =5+13+1+65+14+5+1+2 -> 106 | D23: =IF(K23>0,(K23*I23/1000000000*7850),(H23*I23*J23/1000000000*7850)) -> 5.0245403 | E23: =C23*D23 -> 532.60127 | H23: 466 | I23: 10 | J23: 192 | K23: 64006.883 | L23: =IF(K23>0,(K23*2/1000000),(H23*J23*2/1000000)) -> 0.12801377 | N23: =(L23+M23)*C23 -> 13.569459
A24: D1 | B24: =CONCATENATE("□",H24,"×",I24,"×",J24) -> □528×10×8000 | C24: 50 | D24: =5128.3187/1000000*(J24/1000)*7850 -> 322.05841 | E24: =C24*D24 -> 16102.921 | H24: 528 | I24: 10 | J24: 8000 | L24: =H24*J24/1000000 -> 4.224 | M24: =497*J24/1000000 -> 3.976 | N24: =(L24+M24)*C24 -> 410
A25: D1a | B25: =CONCATENATE("□",H25,"×",I25,"×",J25) -> □528×10×2010 | C25: 2 | D25: =5128.3187/1000000*(J25/1000)*7850 -> 80.917177 | E25: =C25*D25 -> 161.83435 | H25: 528 | I25: 10 | J25: =2130-120 -> 2010 | L25: =IF(K25>0,(K25*2/1000000),(H25*J25*2/1000000)) -> 2.12256 | N25: =(L25+M25)*C25 -> 4.24512
A26: D1b | B26: =CONCATENATE("□",H26,"×",I26,"×",J26) -> □528×10×2020 | C26: 2 | D26: =5128.3187/1000000*(J26/1000)*7850 -> 81.31975 | E26: =C26*D26 -> 162.6395 | H26: 528 | I26: 10 | J26: =2140-120 -> 2020 | L26: =IF(K26>0,(K26*2/1000000),(H26*J26*2/1000000)) -> 2.13312 | N26: =(L26+M26)*C26 -> 4.26624
A27: D2 | B27: =CONCATENATE("□",H27,"×",I27,"×",J27) -> □140×10×230 | C27: =5+13+1+65+14+5+1+2 -> 106 | D27: =IF(K27>0,(K27*I27/1000000000*7850),(H27*I27*J27/1000000000*7850)) -> 1.9035818 | E27: =C27*D27 -> 201.77967 | H27: 140 | I27: 10 | J27: 230 | K27: 24249.45 | L27: =IF(K27>0,(K27*2/1000000),(H27*J27*2/1000000)) -> 0.048498899 | N27: =(L27+M27)*C27 -> 5.1408833
A28: E1 | B28: =CONCATENATE("□",H28,"×",I28,"×",J28) -> □340×10×8000 | C28: =C24 -> 50 | D28: =3216.2071/1000000*(J28/1000)*7850 -> 201.97781 | E28: =C28*D28 -> 10098.89 | H28: 340 | I28: 10 | J28: =J24 -> 8000 | L28: =IF(K28>0,(K28*2/1000000),(H28*J28*2/1000000)) -> 5.44 | N28: =(L28+M28)*C28 -> 272
A29: E1a | B29: =CONCATENATE("□",H29,"×",I29,"×",J29) -> □340×10×2010 | C29: =C25 -> 2 | D29: =3216.2071/1000000*(J29/1000)*7850 -> 50.746924 | E29: =C29*D29 -> 101.49385 | H29: 340 | I29: 10 | J29: =J25 -> 2010 | L29: =IF(K29>0,(K29*2/1000000),(H29*J29*2/1000000)) -> 1.3668 | N29: =(L29+M29)*C29 -> 2.7336
A30: E1a | B30: =CONCATENATE("□",H30,"×",I30,"×",J30) -> □340×10×2020 | C30: =C26 -> 2 | D30: =3216.2071/1000000*(J30/1000)*7850 -> 50.999396 | E30: =C30*D30 -> 101.99879 | H30: 340 | I30: 10 | J30: =J26 -> 2020 | L30: =IF(K30>0,(K30*2/1000000),(H30*J30*2/1000000)) -> 1.3736 | N30: =(L30+M30)*C30 -> 2.7472
A31: 泄水管 | B31: =CONCATENATE("D",H31,"×",I31,"×",J31) -> D50×4×250 | C31: =203/0.5*2 -> 812 | D31: =578.053*250/1000000000*7850 -> 1.134429 | E31: =C31*D31 -> 921.15636 | H31: 50 | I31: 4 | J31: 250 | L31: =IF(K31>0,(K31*2/1000000),(H31*J31*2/1000000)) -> 0.025 | N31: =(L31+M31)*C31 -> 20.3
A32: 合计（kg） | E32: =SUM(E4:E31) -> 93056.657
A33: 焊缝1.5%（kg） | E33: =E32*0.015 -> 1395.8499
A34: 总计（kg） | E34: =E32+E33 -> 94452.507
A35: M16螺栓（个） | E35: 32
A38: 4 | B38: =SUMIF($I$4:$I$31,A38,$E$4:$E$31) -> 41604.457
A39: 10 | B39: =SUMIF($I$4:$I$31,A39,$E$4:$E$31) -> 51452.2
A40: 外涂 | B40: =SUM(N4:N31)*0.7 -> 2183.8155
A41: 内涂 | B41: =SUM(N4:N31)*0.3 -> 935.92092

Sheet 路灯底座
A1: 10 | B1: =E7+E10 -> 552.74441
A2: 28 | B2: =E5+E6 -> 1171.534
A3: 40 | B3: =E8+E9 -> 408.2
A4: 编号 | B4: 规格(mm) | C4: 数量 | D4: 单件重(kg) | E4: 共重(kg) | G4: 牌号 | I4: 短边 | J4: 厚度 | K4: 长边 | L4: 侧面S | M4: 涂装
A5: D1 | B5: =CONCATENATE("□",I5,"×",J5,"×",K5) -> □250×28×250 | C5: 50 | D5: =IF(L5>0,(L5*J5/1000000000*7850),(I5*J5*K5/1000000000*7850)) -> 13.7375 | E5: =C5*D5 -> 686.875 | F5: =SUM(E5:E10) -> 2132.4784 | G5: Q235B | I5: 250 | J5: 28 | K5: 250 | M5: =IF(L5>0,(L5*2/1000000),(I5*K5*2/1000000)) -> 0.125 | N5: =M5*C5 -> 6.25
A6: D1a | B6: =CONCATENATE("□",I6,"×",J6,"×",K6) -> □210×28×210 | C6: 50 | D6: =IF(L6>0,(L6*J6/1000000000*7850),(I6*J6*K6/1000000000*7850)) -> 9.69318 | E6: =C6*D6 -> 484.659 | I6: 210 | J6: 28 | K6: 210 | M6: =IF(L6>0,(L6*2/1000000),(I6*K6*2/1000000)) -> 0.0882 | N6: =M6*C6 -> 4.41
A7: D1b | B7: =CONCATENATE("□",I7,"×",J7,"×",K7) -> □192×10×466 | C7: =C5*2 -> 100 | D7: =IF(L7>0,(L7*J7/1000000000*7850),(I7*J7*K7/1000000000*7850)) -> 5.0245403 | E7: =C7*D7 -> 502.45403 | I7: 192 | J7: 10 | K7: 466 | L7: 64006.883 | M7: =IF(L7>0,(L7*2/1000000),(I7*K7*2/1000000)) -> 0.12801377 | N7: =M7*C7 -> 12.801377
A8: D2 | B8: =CONCATENATE("□",I8,"×",J8,"×",K8) -> □380×40×380 | C8: 5 | D8: =IF(L8>0,(L8*J8/1000000000*7850),(I8*J8*K8/1000000000*7850)) -> 45.3416 | E8: =C8*D8 -> 226.708 | I8: 380 | J8: 40 | K8: 380 | M8: =IF(L8>0,(L8*2/1000000),(I8*K8*2/1000000)) -> 0.2888 | N8: =M8*C8 -> 1.444
A9: D2a | B9: =CONCATENATE("□",I9,"×",J9,"×",K9) -> □340×40×340 | C9: 5 | D9: =IF(L9>0,(L9*J9/1000000000*7850),(I9*J9*K9/1000000000*7850)) -> 36.2984 | E9: =C9*D9 -> 181.492 | I9: 340 | J9: 40 | K9: 340
A10: D2b | B10: =CONCATENATE("□",I10,"×",J10,"×",K10) -> □155×10×472 | C10: =C8*2 -> 10 | D10: =IF(L10>0,(L10*J10/1000000000*7850),(I10*J10*K10/1000000000*7850)) -> 5.0290381 | E10: =C10*D10 -> 50.290381 | I10: 155 | J10: 10 | K10: 472 | L10: 64064.179 | M10: =IF(L10>0,(L10*2/1000000),(I10*K10*2/1000000)) -> 0.12812836 | N10: =M10*C10 -> 1.2812836
A11: 螺栓 | B11: M16 | C11: =4*C5 -> 200 | D11: - | E11: - | F11: - | G11: -
B12: M22 | C12: =4*C8 -> 20 | D12: - | E12: - | F12: - | G12: -

Sheet 桥面系工程数量汇总
A8: 材料名称 | B8: 规格 | E8: 单位 | F8: 中央防撞护栏立柱 | G8: 边防撞护栏立柱 | H8: 横梁 | I8: 底座 | J8: 防撞护栏连接 | K8: 人行护栏 | L8: 路灯 | M8: 排水 | N8: 桥面铺装 | O8: 伸缩缝 | P8: 合计
A9: 钢材 | B9: Q235B | D9: t=4 | E9: kg | K9: =人行护栏!B38 -> 41604.457 | P9: =SUM(F9:O9) -> 41604.457
D10: t=6 | E10: kg | M10: =排水!B29 -> 1366.2372 | P10: =SUM(F10:O10) -> 1366.2372
D11: t=8 | E11: kg | H11: 61387.2 | P11: =SUM(F11:O11) -> 61387.2
D12: t=10 | E12: kg | J12: 7929.6 | K12: =人行护栏!B39 -> 51452.2 | L12: =路灯底座!B1 -> 552.74441 | P12: =SUM(F12:O12) -> 59934.545
D13: t=12 | E13: kg | I13: 22288.5 | P13: =SUM(F13:O13) -> 22288.5
D14: t=14 | E14: kg | I14: 52426 | P14: =SUM(F14:O14) -> 52426
D15: t=15 | E15: kg | M15: =排水!B30 -> 461.61014 | P15: =SUM(F15:O15) -> 461.61014
D16: t=16 | E16: kg | M16: =排水!B31 -> 18.229584 | O16: =伸缩缝!D15 -> 308.70772 | P16: =SUM(F16:O16) -> 326.9373
D17: t=20 | E17: kg | O17: =伸缩缝!E13 -> 4568.7079 | P17: =SUM(F17:O17) -> 4568.7079
D18: t=28 | E18: kg | L18: =路灯底座!B2 -> 1171.534 | P18: =SUM(F18:O18) -> 1171.534
D19: t=40 | E19: kg | L19: =路灯底座!B3 -> 408.2 | P19: =SUM(F19:O19) -> 408.2
D20: t=50 | E20: kg | M20: =排水!B32 -> 1070.6018 | P20: =SUM(F20:O20) -> 1070.6018
D21: φ150×8钢管 | E21: kg | M21: =排水!B27 -> 14725.49 | P21: =SUM(F21:O21) -> 14725.49
D22: φ377×8钢管 | E22: kg | M22: =排水!B28 -> 2966.7764 | P22: =SUM(F22:O22) -> 2966.7764
B23: 小计 | E23: kg | H23: =SUM(H9:H22) -> 61387.2 | I23: =SUM(I9:I22) -> 74714.5 | J23: =SUM(J9:J22) -> 7929.6 | K23: =SUM(K9:K22) -> 93056.657 | L23: =SUM(L9:L22) -> 2132.4784 | M23: =SUM(M9:M22) -> 20608.945 | O23: =SUM(O9:O22) -> 4877.4156 | P23: =SUM(F23:O23) -> 264706.8
B24: Q355C | D24: t=5 | F24: 552 | G24: 1104 | P24: =SUM(F24:O24) -> 1656
D25: t=8 | F25: 883.2 | G25: 1987.2 | P25: =SUM(F25:O25) -> 2870.4
D26: t=10 | F26: 3450 | G26: 3450 | P26: =SUM(F26:O26) -> 6900
D27: t=12 | F27: 524.4 | G27: 524.4 | P27: =SUM(F27:O27) -> 1048.8
D28: t=14 | F28: 8707.8 | G28: 17526 | P28: =SUM(F28:O28) -> 26233.8
D29: t=50 | F29: 8666.4 | G29: 17332.8 | P29: =SUM(F29:O29) -> 25999.2
B30: 小计 | F30: =SUM(F24:F29) -> 22783.8 | G30: =SUM(G24:G29) -> 41924.4 | P30: =SUM(F30:O30) -> 64708.2
A31: 螺栓 | B31: M30 | E31: 套 | I31: 2484 | P31: =SUM(F31:O31) -> 2484
B32: M22 | E32: 套 | L32: =路灯底座!C12 -> 20 | P32: =SUM(F32:O32) -> 20
B33: M16 | E33: 套 | L33: =路灯底座!C11 -> 200 | O33: =伸缩缝!D16 -> 162 | P33: =SUM(F33:O33) -> 362
B34: M14 | E34: 套 | J34: 4032 | P34: =SUM(F34:O34) -> 4032
B35: M12 | E35: 套 | F35: 3312 | G35: 3312 | P35: =SUM(F35:O35) -> 6624
A36: 垫圈 | B36: M14 | E36: 个 | J36: 4032 | P36: =SUM(F36:O36) -> 4032
B37: M12 | E37: 个 | F37: 6624 | G37: 6624 | P37: =SUM(F37:O37) -> 13248
A38: 螺母 | B38: M14 | E38: 个 | J38: 8064 | P38: =SUM(F38:O38) -> 8064
B39: M12 | E39: 个 | F39: 6624 | G39: 6624 | P39: =SUM(F39:O39) -> 13248
A40: 弯头 | B40: φ150×150 | E40: 个 | M40: =排水!G9 -> 82 | P40: =SUM(F40:O40) -> 82
B41: φ377×377 | E41: 个 | M41: =排水!D22 -> 8 | P41: =SUM(F41:O41) -> 8
A42: 三通 | B42: φ150×150×150 | E42: 个 | M42: =排水!G10 -> 82 | P42: =SUM(F42:O42) -> 82
B43: φ150×377×377 | E43: 个 | M43: =排水!G11 -> 82 | P43: =SUM(F43:O43) -> 82
A44: 聚酯螺旋排水管 | E44: m | M44: =0.13*排水!G12 -> 10.66 | P44: =SUM(F44:O44) -> 10.66
A45: 涂装 | B45: 外表面涂装 | E45: m2 | F45: 357.9 | G45: 625.8 | H45: 977.5 | I45: 477 | J45: 101 | K45: =人行护栏!B40 -> 2183.8155 | L45: =路灯底座!N5+路灯底座!N8 -> 7.694 | M45: =排水!B33 -> 458.287 | P45: =SUM(F45:O45) -> 5188.9965
B46: 内表面涂装 | E46: m2 | H46: 977.5 | I46: 950.2 | J46: 101 | K46: =人行护栏!B41 -> 935.92092 | M46: =排水!B34 -> 196.40871 | P46: =SUM(F46:O46) -> 3161.0296
A47: 铺装 | B47: 环氧沥青混合料EA10 | E47: m2 | N47: =23.5*203.76 -> 4788.36 | P47: =SUM(F47:O47) -> 4788.36
...
